Workbook

Sheet Sheet 1
A1: CODIGO_ARTICULO | B1: PROVEEDOR | C1: RUBRO | D1: FAMILIA | E1: DESCRIPCION | F1: MATERIAL | G1: COLOR | H1: BARRACAS | I1: OF FLORIDA | J1: FLORIDA | K1: SAN TELMO | L1: RECOLETA | M1: FRENCH | N1: SAN TELMO 2 | O1: GUEMES | P1: PRECIO | Q1: CONDICION
A2: MG100871101 | B2: BARONTINI | C2: MARRO GRANDE | D2: BANDOLERA | E2: BANDOLERA AMALIA | F2: MAGNUM | G2: NEGRO | H2: 0 | I2: 0 | J2: 0 | K2: 0 | L2: 0 | M2: 0 | N2: 0 | O2: 0 | P2: =VLOOKUP(E2,'lista de precios Sept 2025'!$B$1:$C$330,2,FALSE) -> 59990 | Q2: =VLOOKUP(E2,'lista de precios Sept 2025'!$B$1:$D$330,3,FALSE) -> LIQUIDACION
A3: MG100871120 | B3: BARONTINI | C3: MARRO GRANDE | D3: BANDOLERA | E3: BANDOLERA AMALIA | F3: MAGNUM | G3: CUOIO | H3: 0 | I3: 0 | J3: 0 | K3: 0 | L3: 0 | M3: 0 | N3: 0 | O3: 0 | P3: =VLOOKUP(E3,'lista de precios Sept 2025'!$B$1:$C$330,2,FALSE) -> 59990 | Q3: =VLOOKUP(E3,'lista de precios Sept 2025'!$B$1:$D$330,3,FALSE) -> LIQUIDACION
A4: MG100871153 | B4: BARONTINI | C4: MARRO GRANDE | D4: BANDOLERA | E4: BANDOLERA AMALIA | F4: MAGNUM | G4: HAVANA | H4: 0 | I4: 0 | J4: 0 | K4: 0 | L4: 0 | M4: 0 | N4: 0 | O4: 0 | P4: =VLOOKUP(E4,'lista de precios Sept 2025'!$B$1:$C$330,2,FALSE) -> 59990 | Q4: =VLOOKUP(E4,'lista de precios Sept 2025'!$B$1:$D$330,3,FALSE) -> LIQUIDACION
A5: MG100871160 | B5: BARONTINI | C5: MARRO GRANDE | D5: BANDOLERA | E5: BANDOLERA AMALIA | F5: MAGNUM | G5: ARMY | H5: 0 | I5: 0 | J5: 0 | K5: 0 | L5: 0 | M5: 0 | N5: 0 | O5: 0 | P5: =VLOOKUP(E5,'lista de precios Sept 2025'!$B$1:$C$330,2,FALSE) -> 59990 | Q5: =VLOOKUP(E5,'lista de precios Sept 2025'!$B$1:$D$330,3,FALSE) -> LIQUIDACION
A6: MG100871825 | B6: BARONTINI | C6: MARRO GRANDE | D6: BANDOLERA | E6: BANDOLERA AMALIA | F6: SENA | G6: WHISKY | H6: 0 | I6: 0 | J6: 0 | K6: 0 | L6: 0 | M6: 0 | N6: 0 | O6: 0 | P6: =VLOOKUP(E6,'lista de precios Sept 2025'!$B$1:$C$330,2,FALSE) -> 59990 | Q6: =VLOOKUP(E6,'lista de precios Sept 2025'!$B$1:$D$330,3,FALSE) -> LIQUIDACION
A7: MG100871827 | B7: BARONTINI | C7: MARRO GRANDE | D7: BANDOLERA | E7: BANDOLERA AMALIA | F7: SENA | G7: PIEDRA | H7: 0 | I7: 0 | J7: 0 | K7: 0 | L7: 0 | M7: 0 | N7: 0 | O7: 0 | P7: =VLOOKUP(E7,'lista de precios Sept 2025'!$B$1:$C$330,2,FALSE) -> 59990 | Q7: =VLOOKUP(E7,'lista de precios Sept 2025'!$B$1:$D$330,3,FALSE) -> LIQUIDACION
A8: MG100871828 | B8: BARONTINI | C8: MARRO GRANDE | D8: BANDOLERA | E8: BANDOLERA AMALIA | F8: SENA | G8: VISON | H8: 0 | I8: 0 | J8: 0 | K8: 0 | L8: 0 | M8: 0 | N8: 0 | O8: 0 | P8: =VLOOKUP(E8,'lista de precios Sept 2025'!$B$1:$C$330,2,FALSE) -> 59990 | Q8: =VLOOKUP(E8,'lista de precios Sept 2025'!$B$1:$D$330,3,FALSE) -> LIQUIDACION
A9: MG100872101 | B9: BARONTINI | C9: MARRO GRANDE | D9: BANDOLERA | E9: BANDOLERA AMALIA | F9: MACEIO | G9: NEGRO | H9: 0 | I9: 0 | J9: 0 | K9: 0 | L9: 0 | M9: 0 | N9: 0 | O9: 0 | P9: =VLOOKUP(E9,'lista de precios Sept 2025'!$B$1:$C$330,2,FALSE) -> 59990 | Q9: =VLOOKUP(E9,'lista de precios Sept 2025'!$B$1:$D$330,3,FALSE) -> LIQUIDACION
A10: MG100872201 | B10: BARONTINI | C10: MARRO GRANDE | D10: BANDOLERA | E10: BANDOLERA AMALIA | F10: SALLY | G10: NEGRO | H10: 0 | I10: 0 | J10: 0 | K10: 0 | L10: 0 | M10: 0 | N10: 0 | O10: 0 | P10: =VLOOKUP(E10,'lista de precios Sept 2025'!$B$1:$C$330,2,FALSE) -> 59990 | Q10: =VLOOKUP(E10,'lista de precios Sept 2025'!$B$1:$D$330,3,FALSE) -> LIQUIDACION
A11: MG010690101 | B11: FABRICA | C11: MARRO GRANDE | D11: BANDOLERA | E11: BANDOLERA ANTONIETA | F11: NAPADO | G11: NEGRO | H11: 8 | I11: 3 | J11: 1 | K11: 1 | L11: 1 | M11: 1 | N11: 0 | O11: 2 | P11: 139990 | Q11: CAMBIO
A12: MG010690102 | B12: FABRICA | C12: MARRO GRANDE | D12: BANDOLERA | E12: BANDOLERA ANTONIETA | F12: NAPADO | G12: SUELA | H12: 0 | I12: 0 | J12: 0 | K12: 0 | L12: 1 | M12: 0 | N12: 0 | O12: 0 | P12: 139990 | Q12: CAMBIO
A13: MG010690103 | B13: FABRICA | C13: MARRO GRANDE | D13: BANDOLERA | E13: BANDOLERA ANTONIETA | F13: NAPADO | G13: CARAMELO | H13: 7 | I13: 0 | J13: 4 | K13: 1 | L13: 2 | M13: 2 | N13: 0 | O13: 1 | P13: 139990 | Q13: CAMBIO
A14: MG010690107 | B14: FABRICA | C14: MARRO GRANDE | D14: BANDOLERA | E14: BANDOLERA ANTONIETA | F14: NAPADO | G14: ROJO | H14: 17 | I14: 0 | J14: 2 | K14: 2 | L14: 2 | M14: 2 | N14: 0 | O14: 0 | P14: 139990 | Q14: CAMBIO
A15: MG010690109 | B15: FABRICA | C15: MARRO GRANDE | D15: BANDOLERA | E15: BANDOLERA ANTONIETA | F15: NAPADO | G15: AZUL | H15: 1 | I15: 0 | J15: 1 | K15: 2 | L15: 2 | M15: 2 | N15: 0 | O15: 1 | P15: 139990 | Q15: CAMBIO
A16: MG010690110 | B16: FABRICA | C16: MARRO GRANDE | D16: BANDOLERA | E16: BANDOLERA ANTONIETA | F16: NAPADO | G16: VERDE | H16: 0 | I16: 0 | J16: 0 | K16: 0 | L16: 0 | M16: 0 | N16: 0 | O16: 0 | P16: 139990 | Q16: CAMBIO
A17: MG010690115 | B17: FABRICA | C17: MARRO GRANDE | D17: BANDOLERA | E17: BANDOLERA ANTONIETA | F17: NAPADO | G17: MALBEC | H17: 0 | I17: 0 | J17: 1 | K17: 1 | L17: 1 | M17: 1 | N17: 0 | O17: 1 | P17: 139990 | Q17: CAMBIO
A18: MG010690301 | B18: FABRICA | C18: MARRO GRANDE | D18: BANDOLERA | E18: BANDOLERA ANTONIETA | F18: BRIDGE | G18: NEGRO | H18: 4 | I18: 0 | J18: 2 | K18: 1 | L18: 1 | M18: 1 | N18: 0 | O18: 0 | P18: 139990 | Q18: CAMBIO
A19: MG010690303 | B19: FABRICA | C19: MARRO GRANDE | D19: BANDOLERA | E19: BANDOLERA ANTONIETA | F19: BRIDGE | G19: CARAMELO | H19: 0 | I19: 0 | J19: 0 | K19: 0 | L19: 1 | M19: 1 | N19: 0 | O19: 0 | P19: 139990 | Q19: CAMBIO
A20: MG010690315 | B20: FABRICA | C20: MARRO GRANDE | D20: BANDOLERA | E20: BANDOLERA ANTONIETA | F20: BRIDGE | G20: MALBEC | H20: 0 | I20: 0 | J20: 0 | K20: 0 | L20: 1 | M20: 1 | N20: 0 | O20: 0 | P20: 139990 | Q20: CAMBIO
A21: MG010690304 | B21: FABRICA | C21: MARRO GRANDE | D21: BANDOLERA | E21: BANDOLERA ANTONIETA | F21: BRIDGE | G21: TABACO | H21: 0 | I21: 0 | J21: 0 | K21: 0 | L21: 0 | M21: 0 | N21: 0 | O21: 0 | P21: 139990 | Q21: CAMBIO
A22: MG010690550 | B22: FABRICA | C22: MARRO GRANDE | D22: BANDOLERA | E22: BANDOLERA ANTONIETA | F22: GAMUZA | G22: VESUBIO | H22: 2 | I22: 15 | J22: 1 | K22: 2 | L22: 2 | M22: 2 | N22: 1 | O22: 0 | P22: 134990
A23: MG010690555 | B23: FABRICA | C23: MARRO GRANDE | D23: BANDOLERA | E23: BANDOLERA ANTONIETA | F23: GAMUZA | G23: AVELLANA | H23: 16 | I23: 3 | J23: 3 | K23: 2 | L23: 2 | M23: 1 | N23: 1 | O23: 0 | P23: 134990
A24: MG010690556 | B24: FABRICA | C24: MARRO GRANDE | D24: BANDOLERA | E24: BANDOLERA ANTONIETA | F24: GAMUZA | G24: OXIDO | H24: 16 | I24: 0 | J24: 2 | K24: 1 | L24: 3 | M24: 2 | N24: 3 | O24: 0 | P24: 134990
A25: MG010690558 | B25: FABRICA | C25: MARRO GRANDE | D25: BANDOLERA | E25: BANDOLERA ANTONIETA | F25: GAMUZA | G25: CAFE | H25: 6 | I25: 11 | J25: 1 | K25: 1 | L25: 1 | M25: 2 | N25: 1 | O25: 0 | P25: 134990
A26: MG100901301 | B26: BARONTINI | C26: MARRO GRANDE | D26: BANDOLERA | E26: BANDOLERA ASTRID | F26: NAPA LOLA SOFT | G26: NEGRO | H26: 0 | I26: 0 | J26: 0 | K26: 0 | L26: 0 | M26: 0 | N26: 0 | O26: 0 | P26: =VLOOKUP(E26,'lista de precios Sept 2025'!$B$1:$C$330,2,FALSE) -> 49990 | Q26: =VLOOKUP(E26,'lista de precios Sept 2025'!$B$1:$D$330,3,FALSE) -> LIQUIDACION
A27: MG100901353 | B27: BARONTINI | C27: MARRO GRANDE | D27: BANDOLERA | E27: BANDOLERA ASTRID | F27: NAPA LOLA SOFT | G27: HAVANA | H27: 0 | I27: 0 | J27: 0 | K27: 0 | L27: 0 | M27: 0 | N27: 0 | O27: 0 | P27: =VLOOKUP(E27,'lista de precios Sept 2025'!$B$1:$C$330,2,FALSE) -> 49990 | Q27: =VLOOKUP(E27,'lista de precios Sept 2025'!$B$1:$D$330,3,FALSE) -> LIQUIDACION
A28: MG100901361 | B28: BARONTINI | C28: MARRO GRANDE | D28: BANDOLERA | E28: BANDOLERA ASTRID | F28: NAPA LOLA SOFT | G28: CLAY | H28: 0 | I28: 0 | J28: 0 | K28: 0 | L28: 0 | M28: 0 | N28: 0 | O28: 0 | P28: =VLOOKUP(E28,'lista de precios Sept 2025'!$B$1:$C$330,2,FALSE) -> 49990 | Q28: =VLOOKUP(E28,'lista de precios Sept 2025'!$B$1:$D$330,3,FALSE) -> LIQUIDACION
A29: MG100901401 | B29: BARONTINI | C29: MARRO GRANDE | D29: BANDOLERA | E29: BANDOLERA ASTRID | F29: SAFARI | G29: NEGRO | H29: 0 | I29: 0 | J29: 0 | K29: 0 | L29: 0 | M29: 0 | N29: 0 | O29: 0 | P29: =VLOOKUP(E29,'lista de precios Sept 2025'!$B$1:$C$330,2,FALSE) -> 49990 | Q29: =VLOOKUP(E29,'lista de precios Sept 2025'!$B$1:$D$330,3,FALSE) -> LIQUIDACION
A30: MG100901501 | B30: BARONTINI | C30: MARRO GRANDE | D30: CARTERA | E30: BANDOLERA ASTRID | F30: TOLEDO | G30: NEGRO | H30: 0 | I30: 0 | J30: 0 | K30: 0 | L30: 0 | M30: 1 | N30: 0 | O30: 1 | P30: =VLOOKUP(E30,'lista de precios Sept 2025'!$B$1:$C$330,2,FALSE) -> 49990 | Q30: =VLOOKUP(E30,'lista de precios Sept 2025'!$B$1:$D$330,3,FALSE) -> LIQUIDACION
A31: MG100901553 | B31: BARONTINI | C31: MARRO GRANDE | D31: BANDOLERA | E31: BANDOLERA ASTRID | F31: TOLEDO | G31: HAVANA | H31: 0 | I31: 0 | J31: 0 | K31: 0 | L31: 0 | M31: 0 | N31: 0 | O31: 0 | P31: =VLOOKUP(E31,'lista de precios Sept 2025'!$B$1:$C$330,2,FALSE) -> 49990 | Q31: =VLOOKUP(E31,'lista de precios Sept 2025'!$B$1:$D$330,3,FALSE) -> LIQUIDACION
A32: MG100901561 | B32: BARONTINI | C32: MARRO GRANDE | D32: BANDOLERA | E32: BANDOLERA ASTRID | F32: TOLEDO | G32: CLAY | H32: 0 | I32: 0 | J32: 0 | K32: 0 | L32: 0 | M32: 0 | N32: 0 | O32: 0 | P32: =VLOOKUP(E32,'lista de precios Sept 2025'!$B$1:$C$330,2,FALSE) -> 49990 | Q32: =VLOOKUP(E32,'lista de precios Sept 2025'!$B$1:$D$330,3,FALSE) -> LIQUIDACION
A33: MG100901562 | B33: BARONTINI | C33: MARRO GRANDE | D33: BANDOLERA | E33: BANDOLERA ASTRID | F33: TOLEDO | G33: MANGO | H33: 0 | I33: 0 | J33: 2 | K33: 0 | L33: 0 | M33: 0 | N33: 0 | O33: 0 | P33: =VLOOKUP(E33,'lista de precios Sept 2025'!$B$1:$C$330,2,FALSE) -> 49990 | Q33: =VLOOKUP(E33,'lista de precios Sept 2025'!$B$1:$D$330,3,FALSE) -> LIQUIDACION
A34: MG100901816 | B34: BARONTINI | C34: MARRO GRANDE | D34: BANDOLERA | E34: BANDOLERA ASTRID | F34: SENA | G34: OLIVA | H34: 0 | I34: 0 | J34: 0 | K34: 0 | L34: 0 | M34: 0 | N34: 0 | O34: 0 | P34: =VLOOKUP(E34,'lista de precios Sept 2025'!$B$1:$C$330,2,FALSE) -> 49990 | Q34: =VLOOKUP(E34,'lista de precios Sept 2025'!$B$1:$D$330,3,FALSE) -> LIQUIDACION
A35: MG100901827 | B35: BARONTINI | C35: MARRO GRANDE | D35: BANDOLERA | E35: BANDOLERA ASTRID | F35: SENA | G35: PIEDRA | H35: 0 | I35: 0 | J35: 0 | K35: 0 | L35: 0 | M35: 0 | N35: 0 | O35: 0 | P35: =VLOOKUP(E35,'lista de precios Sept 2025'!$B$1:$C$330,2,FALSE) -> 49990 | Q35: =VLOOKUP(E35,'lista de precios Sept 2025'!$B$1:$D$330,3,FALSE) -> LIQUIDACION
A36: MG100901828 | B36: BARONTINI | C36: MARRO GRANDE | D36: BANDOLERA | E36: BANDOLERA ASTRID | F36: SENA | G36: VISON | H36: 0 | I36: 0 | J36: 0 | K36: 0 | L36: 0 | M36: 0 | N36: 0 | O36: 1 | P36: =VLOOKUP(E36,'lista de precios Sept 2025'!$B$1:$C$330,2,FALSE) -> 49990 | Q36: =VLOOKUP(E36,'lista de precios Sept 2025'!$B$1:$D$330,3,FALSE) -> LIQUIDACION
A37: MG100901831 | B37: BARONTINI | C37: MARRO GRANDE | D37: BANDOLERA | E37: BANDOLERA ASTRID | F37: SENA | G37: NUDE | H37: 0 | I37: 0 | J37: 0 | K37: 0 | L37: 0 | M37: 0 | N37: 0 | O37: 0 | P37: =VLOOKUP(E37,'lista de precios Sept 2025'!$B$1:$C$330,2,FALSE) -> 49990 | Q37: =VLOOKUP(E37,'lista de precios Sept 2025'!$B$1:$D$330,3,FALSE) -> LIQUIDACION
... A74: MG100892201 | B74: BARONTINI | C74: MARRO GRANDE | D74: BANDOLERA | E74: BANDOLERA MEGAN | F74: SALLY | G74: NEGRO | H74: 0 | I74: 0 | J74: 0 | K74: 0 | L74: 0 | M74: 0 | N74: 0 | O74: 3 | P74: =VLOOKUP(E74,'lista de precios Sept 2025'!$B$1:$C$330,2,FALSE) -> 49990 | Q74: =VLOOKUP(E74,'lista de precios Sept 2025'!$B$1:$D$330,3,FALSE) -> LIQUIDACION
A75: MG010310301 | B75: FABRICA | C75: MARRO GRANDE | D75: BANDOLERA | E75: BANDOLERA MINI | F75: BRIDGE | G75: NEGRO | H75: 0 | I75: 0 | J75: 0 | K75: 0 | L75: 0 | M75: 0 | N75: 0 | O75: 0
A76: MG010310303 | B76: FABRICA | C76: MARRO GRANDE | D76: BANDOLERA | E76: BANDOLERA MINI | F76: BRIDGE | G76: CARAMELO | H76: 0 | I76: 0 | J76: 0 | K76: 0 | L76: 0 | M76: 0 | N76: 0 | O76: 0
...

Sheet lista de precios Sept 2025
A1: Rubro | B1: Descripción | C1: Precio | D1: Comentarios
A2: ACCESORIOS | B2: BOINA CLYDE | C2: 59990
A3: ACCESORIOS | B3: BUFANDA ACRUX | C3: 79990
A4: ACCESORIOS | B4: BUFANDA ADHARA | C4: 79990
A5: ACCESORIOS | B5: BUFANDA CAPELLA | C5: 79990
A6: ACCESORIOS | B6: CORREA LOLI | C6: 29990
A7: ACCESORIOS | B7: CORREA LORE | C7: 26990
A8: ACCESORIOS | B8: ESPEJO RECTANGULAR | C8: 22990 | D8: CAMBIO
A9: ACCESORIOS | B9: GORRO ANTARES | C9: 24990
A10: ACCESORIOS | B10: GORRO ESPIGA | C10: 9990 | D10: LIQUIDACION
A11: ACCESORIOS | B11: GORRO FRED | C11: 33990
A12: ACCESORIOS | B12: GORRO NOA | C12: 24990
A13: ACCESORIOS | B13: GORRO PAÑO | C13: 49990
A14: ACCESORIOS | B14: GORRO SEA | C14: 36990
A15: ACCESORIOS | B15: GORRO SELA | C15: 24990
A16: ACCESORIOS | B16: GORRO SIRIUS | C16: 24990
A17: ACCESORIOS | B17: GORRO VEGA | C17: 24990
A18: ACCESORIOS | B18: GORRO VENTO | C18: 49990
A19: ACCESORIOS | B19: GUANTE DAMA | C19: 29990
A20: ACCESORIOS | B20: GUANTE HOMBRE | C20: 29990
A21: ACCESORIOS | B21: LLAVERO ABC | C21: 29990
A22: ACCESORIOS | B22: LLAVERO ALDANA | C22: 9990 | D22: LIQUIDACION
A23: ACCESORIOS | B23: LLAVERO CALADO FRASES | C23: 12990 | D23: LIQUIDACION
A24: ACCESORIOS | B24: LLAVERO CALADO INICIALES | C24: 12990 | D24: LIQUIDACION
A25: ACCESORIOS | B25: LLAVERO CALADO ZODIACO | C25: 12990 | D25: LIQUIDACION
A26: ACCESORIOS | B26: LLAVERO CALE | C26: 12990 | D26: LIQUIDACION
A27: ACCESORIOS | B27: LLAVERO COMBINADO | C27: 12990 | D27: LIQUIDACION
A28: ACCESORIOS | B28: LLAVERO ESPIGA | C28: 12990 | D28: LIQUIDACION
A29: ACCESORIOS | B29: LLAVERO INICIALES | C29: 12990
A30: ACCESORIOS | B30: LLAVERO JAIRO L216 | C30: 12990 | D30: LIQUIDACION
A31: ACCESORIOS | B31: LLAVERO KAREN | C31: 21990 | D31: CAMBIO
A32: ACCESORIOS | B32: LLAVERO MIRLO | C32: 9990 | D32: LIQUIDACION
A33: ACCESORIOS | B33: LLAVERO PANAMA | C33: 12990 | D33: LIQUIDACION
A34: ACCESORIOS | B34: LLAVERO SIMPLE | C34: 15990
A35: ACCESORIOS | B35: MATERA AVA | C35: 149990
A36: ACCESORIOS | B36: MATERA OLI | C36: 169990 | D36: CAMBIO
A37: ACCESORIOS | B37: MATERA OLI PELO | C37: 199990 | D37: CAMBIO
A38: ACCESORIOS | B38: MATERA RENATA | C38: 174990
A39: ACCESORIOS | B39: MATERA RENE FULL BLACK | C39: 169990 | D39: CAMBIO
A40: ACCESORIOS | B40: PILUSO HILDA | C40: 74990
...
