Workbook

Sheet Hoja1
A1: Legajo | B1: Apellido y Nombre | C1: Periodo | D1: Tienda asignada este mes | E1: Horas Totales | F1: Hs Normales (con vacaciones y feriados NO trabajados) | G1: Hs Feriados (Horas) | H1: Feriados No trabajados (DIAS) | I1: Licencias justificadas (en HORAS) | J1: Plus vacacional | K1: Cant dias vacaciones | L1: Premios | M1: Sueldo Neto | N1: Sueldo Bruto | O1: Contribuciones + ART | P1: Costo total | Q1: Observaciones
A2: 55 | B2: Carrizo Camila | C2: 44414 | D2: AS San Telmo | E2: 132 | F2: 126 | G2: 6 | H2: 1 | J2: NO | L2: 17916 | M2: 745721 | N2: 942309.32 | O2: 307038.17 | P2: 1249347.5 | R2: =P2/E2 -> 9464.7537
A3: 143 | B3: Molina Agustina | C3: 45184 | D3: AS San Telmo | E3: 124 | F3: 118 | G3: 6 | H3: 1 | J3: NO | L3: 16830 | M3: 688866 | N3: 870417.52 | O3: 283699.82 | P3: 1154117.3 | R3: =P3/E3 -> 9307.3979
A4: 151 | B4: Kiara Corbalan | C4: 45201 | D4: AS San Telmo | E4: 124 | F4: 118 | G4: 6 | H4: 1 | J4: NO | L4: 16830 | M4: 688866 | N4: 870417.52 | O4: 283699.82 | P4: 1154117.3 | R4: =P4/E4 -> 9307.3979
A5: 161 | B5: Martínez Brisa | C5: 45272 | D5: AS San Telmo | E5: 124 | F5: 118 | G5: 6 | H5: 1 | J5: NO | L5: 16830 | M5: 688866 | N5: 870417.52 | O5: 283699.82 | P5: 1154117.3 | R5: =P5/E5 -> 9307.3979
A6: 184 | B6: Villarruel Candela | C6: 45569 | D6: AS San Telmo | E6: 88 | H6: 2 | J6: NO | L6: 0 | M6: 462011 | N6: 582807.02 | O6: 189561.52 | P6: 772368.54 | R6: =P6/E6 -> 8776.9152
A7: 139 | B7: Viña Sofia | C7: 45139 | D7: Lucero Florida | E7: 127 | F7: 123 | G7: 4 | H7: 1 | J7: NO | L7: 35034 | M7: 711975 | N7: 899820.28 | O7: 293429.88 | P7: 1193250.2 | R7: =P7/E7 -> 9395.6706
A8: 170 | B8: Ruiz de la Torre Maitena | C8: 45345 | D8: Lucero Florida | E8: 125 | F8: 108 | G8: 5 | H8: 1 | I8: 12 | J8: NO | L8: 31172 | M8: 702267 | N8: 887570.87 | O8: 289479.86 | P8: 1177050.7 | R8: =P8/E8 -> 9416.4058
A9: 173 | B9: Imperiale Candela | C9: 45447 | D9: Lucero Florida | E9: 132 | F9: 126 | G9: 6 | H9: 1 | J9: NO | L9: 36413 | M9: 739658 | N9: 935028.96 | O9: 305067.38 | P9: 1240096.3 | R9: =P9/E9 -> 9394.6692
A10: 186 | B10: Balmaceda Luciana | C10: 45587 | D10: Lucero Florida | E10: 125 | F10: 120 | G10: 5 | H10: 1 | J10: NO | L10: 34482 | M10: 698137 | N10: 882412.97 | O10: 287870.99 | P10: 1170284 | R10: =P10/E10 -> 9362.2717
A11: 210 | B11: Dettoni Leguizamon Oriana | C11: 45759 | D11: Lucero Florida | E11: 126 | F11: 120 | G11: 6 | H11: 1 | J11: NO | L11: 0 | M11: 678241 | N11: 856603.76 | O11: 278830.29 | P11: 1135434.1 | R11: =P11/E11 -> 9011.3813
A12: 120 | B12: Bertolo Milagros | C12: 45020 | D12: Lucero French | E12: 124 | F12: 120 | G12: 4 | H12: 1 | J12: NO | L12: 27138 | M12: 696487 | N12: 880081.31 | O12: 286864.55 | P12: 1166945.9 | R12: =P12/E12 -> 9410.8537
A13: 174 | B13: Machuca Araceli | C13: 45477 | D13: Lucero French | E13: 120 | F13: 110 | G13: 6 | H13: 1 | I13: 4 | J13: NO | L13: 25388 | M13: 668709 | N13: 845127.07 | O13: 275690.54 | P13: 1120817.6 | R13: =P13/E13 -> 9340.1468
A14: 194 | B14: Scholler Chavez Ruth | C14: 45639 | D14: Lucero French | E14: 120 | F14: 114 | G14: 6 | H14: 1 | J14: NO | L14: 26263 | M14: 669444 | N14: 846075.35 | O14: 276017.62 | P14: 1122093 | R14: =P14/E14 -> 9350.7748
A15: 131 | B15: De Brito Rocio | C15: 45085 | D15: Lucero Güemes | E15: 130 | F15: 130 | H15: 2 | J15: NO | L15: 9245 | M15: 692511 | N15: 874289.91 | O15: 284207.92 | P15: 1158497.8 | R15: =P15/E15 -> 8911.5218
A16: 165 | B16: CORONEL Mailen | C16: 45311 | D16: Lucero Güemes | E16: 128 | F16: 120 | H16: 2 | I16: 8 | J16: NO | L16: 11605 | M16: 684127 | N16: 863748.83 | O16: 280847.24 | P16: 1144596.1 | R16: =P16/E16 -> 8942.1568
A17: 126 | B17: Barajas Barbara | C17: 45057 | D17: Lucero Recoleta | E17: 126 | F17: 122 | G17: 4 | H17: 1 | J17: NO | L17: 27576 | M17: 707350 | N17: 893818.36 | O17: 291325.13 | P17: 1185143.5 | R17: =P17/E17 -> 9405.9007
A18: 171 | B18: Gimenez Candela | C18: 45771 | D18: Lucero Recoleta | E18: 120 | F18: 112 | G18: 4 | H18: 1 | I18: 4 | J18: NO | L18: 25388 | M18: 667448 | N18: 843335.45 | O18: 274908.49 | P18: 1118243.9 | R18: =P18/E18 -> 9318.6995
A19: 189 | B19: Oliva Micaela | C19: 45597 | D19: Lucero Recoleta | E19: 125 | F19: 121 | G19: 4 | H19: 1 | J19: NO | L19: 28383 | M19: 689103 | N19: 870756.32 | O19: 283849.54 | P19: 1154605.9 | R19: =P19/E19 -> 9236.8469
A20: 103 | B20: Esposito Candela | C20: 44854 | D20: Lucero San Telmo | E20: 132 | F20: 123 | G20: 5 | H20: 1 | I20: 4 | J20: NO | L20: 32828 | M20: 747302 | N20: 944530.32 | O20: 307984.75 | P20: 1252515.1 | R20: =P20/E20 -> 9488.7505
A21: 138 | B21: Lara Robbio | C21: 45139 | D21: Lucero San Telmo | E21: 123 | F21: 114 | G21: 5 | H21: 1 | I21: 4 | J21: NO | L21: 30520 | M21: 691330 | N21: 873735.31 | O21: 284982.4 | P21: 1158717.7 | R21: =P21/E21 -> 9420.4692
A22: 192 | B22: Sarapura Rebecca | C22: 45597 | D22: Lucero San Telmo | E22: 122 | F22: 101 | G22: 5 | H22: 1 | I22: 16 | J22: NO | L22: 27186 | M22: 676588 | N22: 855019.22 | O22: 278830.04 | P22: 1133849.3 | R22: =P22/E22 -> 9293.8464
A23: 206 | B23: Morena Martinez | C23: 45713 | D23: Lucero San Telmo | E23: 124 | F23: 119 | G23: 5 | H23: 1 | J23: NO | L23: 4518 | M23: 667839 | N23: 843456.02 | O23: 274567.53 | P23: 1118023.6 | R23: =P23/E23 -> 9016.319
A24: 190 | B24: Mohamad Daila | C24: 45597 | D24: Lucero San Telmo 2 | E24: 132 | F24: 127 | G24: 5 | H24: 1 | J24: NO | L24: 13198 | M24: 716255 | N24: 904831.42 | O24: 294649.16 | P24: 1199480.6 | R24: =P24/E24 -> 9086.9741
A25: 205 | B25: Florencia Aguero | C25: 45713 | D25: Lucero San Telmo 2 | E25: 58 | F25: 58 | J25: NO | L25: 0 | M25: 560658 | N25: 681305.96 | O25: 207086.12 | P25: 888392.08 | Q25: BAJA | R25: =P25/E25 -> 15317.105
A26: 213 | B26: Gonzalez Valentina | C26: 45789 | D26: Lucero San Telmo 2 | E26: 93 | F26: 89 | G26: 4 | H26: 1 | J26: NO | L26: 0 | M26: 498151 | N26: 628753.8 | O26: 204730.14 | P26: 833483.94 | Q26: ALTA | R26: =P26/E26 -> 8962.1929

Sheet Hoja2
A1: FLORIDA
Q2: Presupuesto mensual: | S2: 4000000
A3: JULIO
D4: Martes | F4: Miércoles | H4: Jueves | J4: Viernes | L4: Sábado | N4: Domingo | Q4: Legajo | R4: Nombre | S4: Valor hora | T4: Horas | U4: Horas proporcional | V4: Costo
D5: 1 | F5: 2 | H5: 3 | J5: 4 | L5: 5 | N5: 6 | Q5: 139 | R5: Sofía | S5: =Hoja1!R7 -> 9395.6706 | T5: =SUM(COUNTIF($B$6:$O$67,R5)+5) -> 7 | V5: =S5*T5 -> 65769.694
A6: 10 | D6: Sofía | Q6: 170 | R6: Maitena | S6: =Hoja1!R8 -> 9416.4058 | T6: =COUNTIF($B$6:$O$67, R6) -> 5 | V6: =S6*T6 -> 47082.029
A7: 11 | D7: Sofía | Q7: 173 | R7: Candela | S7: =Hoja1!R9 -> 9394.6692 | T7: =COUNTIF($B$6:$O$67, R7) -> 4 | V7: =S7*T7 -> 37578.677
A8: 12 | D8: Maitena | Q8: 186 | R8: Luciana | S8: =Hoja1!R10 -> 9362.2717 | T8: =COUNTIF($B$6:$O$67, R8) -> 0 | V8: =S8*T8 -> 0
A9: 13 | D9: Maitena | E9: Candela | F9: Maitena | Q9: 210 | R9: Oriana | S9: =Hoja1!R11 -> 9011.3813 | T9: =COUNTIF($B$6:$O$67, R9) -> 0 | V9: =S9*T9 -> 0
A10: 14 | D10: Maitena | E10: Candela | Q10: Costo total | V10: =SUM(V5:V9) -> 150430.4
A11: 15 | D11: Maitena | E11: Candela | Q11: Porcentaje del prespuesto | V11: =V10/S2 -> 0.0376076
A12: 16 | E12: Candela | Q12: Proporcional al mes | W12: calcular cuánto sería el mes entero con estos valores considerando los días en los que hay datos
A13: 17
A14: 18
A15: 19
B17: Lunes | D17: Martes | F17: Miércoles | G17: Jueves | H17: Jueves | I17: Viernes | J17: Viernes | K17: Viernes | L17: Sábado | N17: Domingo
B18: 7 | D18: 8 | F18: 9 | G18: 10 | H18: 10 | I18: 11 | J18: 11 | K18: 11 | L18: 12 | N18: 13
A19: 10
A20: 11
A21: 12
A22: 13
A23: 14
A24: 15
A25: 16
A26: 17
A27: 18
A28: 19
B30: Lunes | D30: Martes | F30: Miércoles | H30: Jueves | J30: Viernes | L30: Sábado | N30: Domingo
B31: 14 | D31: 15 | F31: 16 | H31: 17 | J31: 18 | L31: 19 | N31: 20
A32: 10
A33: 11
A34: 12
A35: 13
A36: 14
A37: 15
A38: 16
A39: 17
A40: 18
A41: 19
B43: Lunes | D43: Martes | F43: Miércoles | H43: Jueves | J43: Viernes | L43: Sábado | N43: Domingo
...

Sheet Hoja3
D4: Martes | F4: Miércoles | H4: Jueves | J4: Viernes | L4: Sábado | N4: Domingo | Q4: Legajo | R4: Nombre | S4: Valor hora | T4: Horas | U4: Horas proporcional | V4: Costo
D5: 1 | F5: 2 | H5: 3 | J5: 4 | L5: 5 | N5: 6 | Q5: 100 | R5: Vendedora A | S5: =Hoja1!R7 -> 9395.6706 | T5: =IF(OR(D7="F", D7 = "f"),5,E7-D7)+IF(OR(F7="F", F7 = "f"),5,G7-F7)+IF(OR(H7="F", H7 = "f"),5,I7-H7)+IF(OR(J7="F", J7 = "f"),5,K7-J7) -> 19 | V5: =S5*T5 -> 178517.74
D6: Entrada | E6: Salida | F6: Entrada | G6: Salida | H6: Entrada | I6: Salida | J6: Entrada | K6: Salida | L6: Entrada | M6: Salida | N6: Entrada | O6: Salida | Q6: 101 | R6: Vendedora B | S6: =Hoja1!R8 -> 9416.4058 | T6: =IF(OR(D8="F", D8 = "f"),5,E8-D8) -> 5 | V6: =S6*T6 -> 47082.029
A7: Vendedora A | D7: F | F7: 15 | G7: 20 | H7: 16 | I7: 20 | J7: F | L7: 14 | M7: 20 | N7: 15 | O7: 20 | Q7: 102 | R7: Vendedora C | S7: =Hoja1!R9 -> 9394.6692 | T7: =IF(OR(D9="F", D9 = "f"),5,E9-D9) -> 5 | V7: =S7*T7 -> 46973.346
A8: Vendedora B | D8: 10 | E8: 15 | F8: 15 | G8: 20 | H8: F | J8: 10 | K8: 14 | L8: F | N8: 15 | O8: 20 | Q8: 103 | R8: Vendedora D | S8: =Hoja1!R10 -> 9362.2717 | T8: =IF(OR(D10="F", D10 = "f"),5,E10-D10) -> 6 | V8: =S8*T8 -> 56173.63
A9: Vendedora C | D9: 15 | E9: 20 | F9: F | H9: F | J9: 14 | K9: 20 | L9: 10 | M9: 15 | N9: 10 | O9: 15 | Q9: 104 | R9: Vendedora E | S9: =Hoja1!R11 -> 9011.3813 | T9: =IF(OR(D11="F", D11 = "f"),5,E11-D11) -> 5 | V9: =S9*T9 -> 45056.907
A10: Vendedora D | D10: 14 | E10: 20 | F10: 10 | G10: 15 | H10: 10 | I10: 14 | J10: 10 | K10: 14 | L10: 14 | M10: 20 | N10: F | Q10: Costo total | V10: =SUM(V5:V9) -> 373803.65
A11: Vendedora E | D11: 10 | E11: 15 | F11: 10 | G11: 15 | H11: 14 | I11: 20 | J11: 14 | K11: 20 | L11: F | N11: 10 | O11: 15 | Q11: Porcentaje del prespuesto | V11: =V10/S2 -> #DIV/0!
Q12: Proporcional al mes | W12: calcular cuánto sería el mes entero con estos valores considerando los días en los que hay datos
B13: Lunes | D13: Martes | F13: Miércoles | G13: Jueves | H13: Jueves | I13: Viernes | J13: Viernes | K13: Viernes | L13: Sábado | N13: Domingo
B14: 7 | D14: 8 | F14: 9 | G14: 10 | H14: 10 | I14: 11 | J14: 11 | K14: 11 | L14: 12 | N14: 13
B15: Entrada | C15: Salida | D15: Entrada | E15: Salida | F15: Entrada | G15: Salida | H15: Entrada | I15: Salida | J15: Entrada | K15: Salida | L15: Entrada | M15: Salida | N15: Entrada | O15: Salida
A16: Vendedora A
A17: Vendedora B
A18: Vendedora C
A19: Vendedora D
A20: Vendedora E
B22: Lunes | D22: Martes | F22: Miércoles | H22: Jueves | J22: Viernes | L22: Sábado | N22: Domingo
B23: 14 | D23: 15 | F23: 16 | H23: 17 | J23: 18 | L23: 19 | N23: 20
B24: Entrada | C24: Salida | D24: Entrada | E24: Salida | F24: Entrada | G24: Salida | H24: Entrada | I24: Salida | J24: Entrada | K24: Salida | L24: Entrada | M24: Salida | N24: Entrada | O24: Salida
A25: Vendedora A
A26: Vendedora B
A27: Vendedora C
A28: Vendedora D
A29: Vendedora E
B31: Lunes | D31: Martes | F31: Miércoles | H31: Jueves | J31: Viernes | L31: Sábado | N31: Domingo
B32: 21 | D32: 22 | F32: 23 | H32: 24 | J32: 25 | L32: 26 | N32: 27
B33: Entrada | C33: Salida | D33: Entrada | E33: Salida | F33: Entrada | G33: Salida | H33: Entrada | I33: Salida | J33: Entrada | K33: Salida | L33: Entrada | M33: Salida | N33: Entrada | O33: Salida
A34: Vendedora A
A35: Vendedora B
A36: Vendedora C
A37: Vendedora D
A38: Vendedora E
B40: Lunes | D40: Martes | F40: Miércoles | H40: Jueves
B41: 28 | D41: 29 | F41: 30 | H41: 31
B42: Entrada | C42: Salida | D42: Entrada | E42: Salida | F42: Entrada | G42: Salida | H42: Entrada | I42: Salida
A43: Vendedora A
A44: Vendedora B | B44: f
A45: Vendedora C | B45: F
A46: Vendedora D
...

Sheet Hoja4
A1: 10
A2: 11
A3: 12
A4: 13
A5: 14
A6: 15
A7: 16
A8: 17
A9: 18
A10: 19
A11: 20
A12: F
