Workbook

Sheet Resumen zona
A1: NOVIEMBRE 2025
A3: HORAS POR VENDEDORA Y TIENDA | K3: HORAS TOTALES POR TIENDA (normales y feriados trabajados)
A4: Vendedoras | B4: Hora normales | E4: Feriados trabajados | H4: Horas totales trabajadas | I4: Feriados no trabajados | K4: Tienda | L4: Total horas | M4: Máximo
B5: Florida | C5: Güemes | D5: Recoleta | E5: Florida | F5: Güemes | G5: Recoleta | K5: Florida | L5: =SUM(B6:B16)+SUM(E6:E16) -> 535 | M5: 600
A6: Sofía | B6: =SUMPRODUCT((TablaFloridaNov[Vendedora 1]=A6)+(TablaFloridaNov[Vendedora 2]=A6)+(TablaFloridaNov[Vendedora 3]=A6),--(TablaFloridaNov[Día]<>$K$11)) -> 0 | C6: =SUMPRODUCT((TablaGuemesNov[Vendedora 1]=A6)+(TablaGuemesNov[Vendedora 2]=A6)+(TablaGuemesNov[Vendedora 3]=A6),--(TablaGuemesNov[Día]<>$K$11)) -> 143 | D6: =SUMPRODUCT((TablaRecoletaNov[Vendedora 1]=A6)+(TablaRecoletaNov[Vendedora 2]=A6)+(TablaRecoletaNov[Vendedora 3]=A6),--(TablaRecoletaNov[Día]<>$K$11)) -> 0 | E6: =SUMPRODUCT((TablaFloridaNov[Vendedora 1]=A6)+(TablaFloridaNov[Vendedora 2]=A6)+(TablaFloridaNov[Vendedora 3]=A6),--(TablaFloridaNov[Día]=$K$11)) -> 0 | F6: =SUMPRODUCT((TablaGuemesNov[Vendedora 1]=A6)+(TablaGuemesNov[Vendedora 2]=A6)+(TablaGuemesNov[Vendedora 3]=A6),--(TablaGuemesNov[Día]=$K$11)) -> 9 | G6: =SUMPRODUCT((TablaRecoletaNov[Vendedora 1]=A6)+(TablaRecoletaNov[Vendedora 2]=A6)+(TablaRecoletaNov[Vendedora 3]=A6),--(TablaRecoletaNov[Día]=$K$11)) -> 0 | H6: =SUM(B6:G6) -> 152 | K6: Güemes | L6: =SUM(C6:C16)+SUM(F6:F16) -> 152 | M6: 300
A7: Giselle | B7: =SUMPRODUCT((TablaFloridaNov[Vendedora 1]=A7)+(TablaFloridaNov[Vendedora 2]=A7)+(TablaFloridaNov[Vendedora 3]=A7),--(TablaFloridaNov[Día]<>$K$11)) -> 0 | C7: =SUMPRODUCT((TablaGuemesNov[Vendedora 1]=A7)+(TablaGuemesNov[Vendedora 2]=A7)+(TablaGuemesNov[Vendedora 3]=A7),--(TablaGuemesNov[Día]<>$K$11)) -> 0 | D7: =SUMPRODUCT((TablaRecoletaNov[Vendedora 1]=A7)+(TablaRecoletaNov[Vendedora 2]=A7)+(TablaRecoletaNov[Vendedora 3]=A7),--(TablaRecoletaNov[Día]<>$K$11)) -> 0 | E7: =SUMPRODUCT((TablaFloridaNov[Vendedora 1]=A7)+(TablaFloridaNov[Vendedora 2]=A7)+(TablaFloridaNov[Vendedora 3]=A7),--(TablaFloridaNov[Día]=$K$11)) -> 0 | F7: =SUMPRODUCT((TablaGuemesNov[Vendedora 1]=A7)+(TablaGuemesNov[Vendedora 2]=A7)+(TablaGuemesNov[Vendedora 3]=A7),--(TablaGuemesNov[Día]=$K$11)) -> 0 | G7: =SUMPRODUCT((TablaRecoletaNov[Vendedora 1]=A7)+(TablaRecoletaNov[Vendedora 2]=A7)+(TablaRecoletaNov[Vendedora 3]=A7),--(TablaRecoletaNov[Día]=$K$11)) -> 0 | H7: =SUM(B7:G7) -> 0 | K7: Recoleta | L7: =SUM(D6:D16)+SUM(G6:G16) -> 157 | M7: 450
A8: Maitena | B8: =SUMPRODUCT((TablaFloridaNov[Vendedora 1]=A8)+(TablaFloridaNov[Vendedora 2]=A8)+(TablaFloridaNov[Vendedora 3]=A8),--(TablaFloridaNov[Día]<>$K$11)) -> 493 | C8: =SUMPRODUCT((TablaGuemesNov[Vendedora 1]=A8)+(TablaGuemesNov[Vendedora 2]=A8)+(TablaGuemesNov[Vendedora 3]=A8),--(TablaGuemesNov[Día]<>$K$11)) -> 0 | D8: =SUMPRODUCT((TablaRecoletaNov[Vendedora 1]=A8)+(TablaRecoletaNov[Vendedora 2]=A8)+(TablaRecoletaNov[Vendedora 3]=A8),--(TablaRecoletaNov[Día]<>$K$11)) -> 11 | E8: =SUMPRODUCT((TablaFloridaNov[Vendedora 1]=A8)+(TablaFloridaNov[Vendedora 2]=A8)+(TablaFloridaNov[Vendedora 3]=A8),--(TablaFloridaNov[Día]=$K$11)) -> 8 | F8: =SUMPRODUCT((TablaGuemesNov[Vendedora 1]=A8)+(TablaGuemesNov[Vendedora 2]=A8)+(TablaGuemesNov[Vendedora 3]=A8),--(TablaGuemesNov[Día]=$K$11)) -> 0 | G8: =SUMPRODUCT((TablaRecoletaNov[Vendedora 1]=A8)+(TablaRecoletaNov[Vendedora 2]=A8)+(TablaRecoletaNov[Vendedora 3]=A8),--(TablaRecoletaNov[Día]=$K$11)) -> 0 | H8: =SUM(B8:G8) -> 512
A9: Candela I. | B9: =SUMPRODUCT((TablaFloridaNov[Vendedora 1]=A9)+(TablaFloridaNov[Vendedora 2]=A9)+(TablaFloridaNov[Vendedora 3]=A9),--(TablaFloridaNov[Día]<>$K$11)) -> 12 | C9: =SUMPRODUCT((TablaGuemesNov[Vendedora 1]=A9)+(TablaGuemesNov[Vendedora 2]=A9)+(TablaGuemesNov[Vendedora 3]=A9),--(TablaGuemesNov[Día]<>$K$11)) -> 0 | D9: =SUMPRODUCT((TablaRecoletaNov[Vendedora 1]=A9)+(TablaRecoletaNov[Vendedora 2]=A9)+(TablaRecoletaNov[Vendedora 3]=A9),--(TablaRecoletaNov[Día]<>$K$11)) -> 0 | E9: =SUMPRODUCT((TablaFloridaNov[Vendedora 1]=A9)+(TablaFloridaNov[Vendedora 2]=A9)+(TablaFloridaNov[Vendedora 3]=A9),--(TablaFloridaNov[Día]=$K$11)) -> 0 | F9: =SUMPRODUCT((TablaGuemesNov[Vendedora 1]=A9)+(TablaGuemesNov[Vendedora 2]=A9)+(TablaGuemesNov[Vendedora 3]=A9),--(TablaGuemesNov[Día]=$K$11)) -> 0 | G9: =SUMPRODUCT((TablaRecoletaNov[Vendedora 1]=A9)+(TablaRecoletaNov[Vendedora 2]=A9)+(TablaRecoletaNov[Vendedora 3]=A9),--(TablaRecoletaNov[Día]=$K$11)) -> 0 | H9: =SUM(B9:G9) -> 12
A10: Luciana | B10: =SUMPRODUCT((TablaFloridaNov[Vendedora 1]=A10)+(TablaFloridaNov[Vendedora 2]=A10)+(TablaFloridaNov[Vendedora 3]=A10),--(TablaFloridaNov[Día]<>$K$11)) -> 0 | C10: =SUMPRODUCT((TablaGuemesNov[Vendedora 1]=A10)+(TablaGuemesNov[Vendedora 2]=A10)+(TablaGuemesNov[Vendedora 3]=A10),--(TablaGuemesNov[Día]<>$K$11)) -> 0 | D10: =SUMPRODUCT((TablaRecoletaNov[Vendedora 1]=A10)+(TablaRecoletaNov[Vendedora 2]=A10)+(TablaRecoletaNov[Vendedora 3]=A10),--(TablaRecoletaNov[Día]<>$K$11)) -> 0 | E10: =SUMPRODUCT((TablaFloridaNov[Vendedora 1]=A10)+(TablaFloridaNov[Vendedora 2]=A10)+(TablaFloridaNov[Vendedora 3]=A10),--(TablaFloridaNov[Día]=$K$11)) -> 0 | F10: =SUMPRODUCT((TablaGuemesNov[Vendedora 1]=A10)+(TablaGuemesNov[Vendedora 2]=A10)+(TablaGuemesNov[Vendedora 3]=A10),--(TablaGuemesNov[Día]=$K$11)) -> 0 | G10: =SUMPRODUCT((TablaRecoletaNov[Vendedora 1]=A10)+(TablaRecoletaNov[Vendedora 2]=A10)+(TablaRecoletaNov[Vendedora 3]=A10),--(TablaRecoletaNov[Día]=$K$11)) -> 0 | H10: =SUM(B10:G10) -> 0 | K10: FERIADOS
A11: Bárbara | B11: =SUMPRODUCT((TablaFloridaNov[Vendedora 1]=A11)+(TablaFloridaNov[Vendedora 2]=A11)+(TablaFloridaNov[Vendedora 3]=A11),--(TablaFloridaNov[Día]<>$K$11)) -> 0 | C11: =SUMPRODUCT((TablaGuemesNov[Vendedora 1]=A11)+(TablaGuemesNov[Vendedora 2]=A11)+(TablaGuemesNov[Vendedora 3]=A11),--(TablaGuemesNov[Día]<>$K$11)) -> 0 | D11: =SUMPRODUCT((TablaRecoletaNov[Vendedora 1]=A11)+(TablaRecoletaNov[Vendedora 2]=A11)+(TablaRecoletaNov[Vendedora 3]=A11),--(TablaRecoletaNov[Día]<>$K$11)) -> 0 | E11: =SUMPRODUCT((TablaFloridaNov[Vendedora 1]=A11)+(TablaFloridaNov[Vendedora 2]=A11)+(TablaFloridaNov[Vendedora 3]=A11),--(TablaFloridaNov[Día]=$K$11)) -> 0 | F11: =SUMPRODUCT((TablaGuemesNov[Vendedora 1]=A11)+(TablaGuemesNov[Vendedora 2]=A11)+(TablaGuemesNov[Vendedora 3]=A11),--(TablaGuemesNov[Día]=$K$11)) -> 0 | G11: =SUMPRODUCT((TablaRecoletaNov[Vendedora 1]=A11)+(TablaRecoletaNov[Vendedora 2]=A11)+(TablaRecoletaNov[Vendedora 3]=A11),--(TablaRecoletaNov[Día]=$K$11)) -> 0 | H11: =SUM(B11:G11) -> 0 | K11: 45985
A12: Rocío | B12: =SUMPRODUCT((TablaFloridaNov[Vendedora 1]=A12)+(TablaFloridaNov[Vendedora 2]=A12)+(TablaFloridaNov[Vendedora 3]=A12),--(TablaFloridaNov[Día]<>$K$11)) -> 5 | C12: =SUMPRODUCT((TablaGuemesNov[Vendedora 1]=A12)+(TablaGuemesNov[Vendedora 2]=A12)+(TablaGuemesNov[Vendedora 3]=A12),--(TablaGuemesNov[Día]<>$K$11)) -> 0 | D12: =SUMPRODUCT((TablaRecoletaNov[Vendedora 1]=A12)+(TablaRecoletaNov[Vendedora 2]=A12)+(TablaRecoletaNov[Vendedora 3]=A12),--(TablaRecoletaNov[Día]<>$K$11)) -> 63 | E12: =SUMPRODUCT((TablaFloridaNov[Vendedora 1]=A12)+(TablaFloridaNov[Vendedora 2]=A12)+(TablaFloridaNov[Vendedora 3]=A12),--(TablaFloridaNov[Día]=$K$11)) -> 0 | F12: =SUMPRODUCT((TablaGuemesNov[Vendedora 1]=A12)+(TablaGuemesNov[Vendedora 2]=A12)+(TablaGuemesNov[Vendedora 3]=A12),--(TablaGuemesNov[Día]=$K$11)) -> 0 | G12: =SUMPRODUCT((TablaRecoletaNov[Vendedora 1]=A12)+(TablaRecoletaNov[Vendedora 2]=A12)+(TablaRecoletaNov[Vendedora 3]=A12),--(TablaRecoletaNov[Día]=$K$11)) -> 11 | H12: =SUM(B12:G12) -> 79
A13: Mailén | B13: =SUMPRODUCT((TablaFloridaNov[Vendedora 1]=A13)+(TablaFloridaNov[Vendedora 2]=A13)+(TablaFloridaNov[Vendedora 3]=A13),--(TablaFloridaNov[Día]<>$K$11)) -> 12 | C13: =SUMPRODUCT((TablaGuemesNov[Vendedora 1]=A13)+(TablaGuemesNov[Vendedora 2]=A13)+(TablaGuemesNov[Vendedora 3]=A13),--(TablaGuemesNov[Día]<>$K$11)) -> 0 | D13: =SUMPRODUCT((TablaRecoletaNov[Vendedora 1]=A13)+(TablaRecoletaNov[Vendedora 2]=A13)+(TablaRecoletaNov[Vendedora 3]=A13),--(TablaRecoletaNov[Día]<>$K$11)) -> 0 | E13: =SUMPRODUCT((TablaFloridaNov[Vendedora 1]=A13)+(TablaFloridaNov[Vendedora 2]=A13)+(TablaFloridaNov[Vendedora 3]=A13),--(TablaFloridaNov[Día]=$K$11)) -> 0 | F13: =SUMPRODUCT((TablaGuemesNov[Vendedora 1]=A13)+(TablaGuemesNov[Vendedora 2]=A13)+(TablaGuemesNov[Vendedora 3]=A13),--(TablaGuemesNov[Día]=$K$11)) -> 0 | G13: =SUMPRODUCT((TablaRecoletaNov[Vendedora 1]=A13)+(TablaRecoletaNov[Vendedora 2]=A13)+(TablaRecoletaNov[Vendedora 3]=A13),--(TablaRecoletaNov[Día]=$K$11)) -> 0 | H13: =SUM(B13:G13) -> 12
A14: Candela G. | B14: =SUMPRODUCT((TablaFloridaNov[Vendedora 1]=A14)+(TablaFloridaNov[Vendedora 2]=A14)+(TablaFloridaNov[Vendedora 3]=A14),--(TablaFloridaNov[Día]<>$K$11)) -> 0 | C14: =SUMPRODUCT((TablaGuemesNov[Vendedora 1]=A14)+(TablaGuemesNov[Vendedora 2]=A14)+(TablaGuemesNov[Vendedora 3]=A14),--(TablaGuemesNov[Día]<>$K$11)) -> 0 | D14: =SUMPRODUCT((TablaRecoletaNov[Vendedora 1]=A14)+(TablaRecoletaNov[Vendedora 2]=A14)+(TablaRecoletaNov[Vendedora 3]=A14),--(TablaRecoletaNov[Día]<>$K$11)) -> 0 | E14: =SUMPRODUCT((TablaFloridaNov[Vendedora 1]=A14)+(TablaFloridaNov[Vendedora 2]=A14)+(TablaFloridaNov[Vendedora 3]=A14),--(TablaFloridaNov[Día]=$K$11)) -> 0 | F14: =SUMPRODUCT((TablaGuemesNov[Vendedora 1]=A14)+(TablaGuemesNov[Vendedora 2]=A14)+(TablaGuemesNov[Vendedora 3]=A14),--(TablaGuemesNov[Día]=$K$11)) -> 0 | G14: =SUMPRODUCT((TablaRecoletaNov[Vendedora 1]=A14)+(TablaRecoletaNov[Vendedora 2]=A14)+(TablaRecoletaNov[Vendedora 3]=A14),--(TablaRecoletaNov[Día]=$K$11)) -> 0 | H14: =SUM(B14:G14) -> 0
A15: Micaela | B15: =SUMPRODUCT((TablaFloridaNov[Vendedora 1]=A15)+(TablaFloridaNov[Vendedora 2]=A15)+(TablaFloridaNov[Vendedora 3]=A15),--(TablaFloridaNov[Día]<>$K$11)) -> 0 | C15: =SUMPRODUCT((TablaGuemesNov[Vendedora 1]=A15)+(TablaGuemesNov[Vendedora 2]=A15)+(TablaGuemesNov[Vendedora 3]=A15),--(TablaGuemesNov[Día]<>$K$11)) -> 0 | D15: =SUMPRODUCT((TablaRecoletaNov[Vendedora 1]=A15)+(TablaRecoletaNov[Vendedora 2]=A15)+(TablaRecoletaNov[Vendedora 3]=A15),--(TablaRecoletaNov[Día]<>$K$11)) -> 72 | E15: =SUMPRODUCT((TablaFloridaNov[Vendedora 1]=A15)+(TablaFloridaNov[Vendedora 2]=A15)+(TablaFloridaNov[Vendedora 3]=A15),--(TablaFloridaNov[Día]=$K$11)) -> 5 | F15: =SUMPRODUCT((TablaGuemesNov[Vendedora 1]=A15)+(TablaGuemesNov[Vendedora 2]=A15)+(TablaGuemesNov[Vendedora 3]=A15),--(TablaGuemesNov[Día]=$K$11)) -> 0 | G15: =SUMPRODUCT((TablaRecoletaNov[Vendedora 1]=A15)+(TablaRecoletaNov[Vendedora 2]=A15)+(TablaRecoletaNov[Vendedora 3]=A15),--(TablaRecoletaNov[Día]=$K$11)) -> 0 | H15: =SUM(B15:G15) -> 77
A16: [Nueva] | B16: =SUMPRODUCT((TablaFloridaNov[Vendedora 1]=A16)+(TablaFloridaNov[Vendedora 2]=A16)+(TablaFloridaNov[Vendedora 3]=A16),--(TablaFloridaNov[Día]<>$K$11)) -> 0 | C16: =SUMPRODUCT((TablaGuemesNov[Vendedora 1]=A16)+(TablaGuemesNov[Vendedora 2]=A16)+(TablaGuemesNov[Vendedora 3]=A16),--(TablaGuemesNov[Día]<>$K$11)) -> 0 | D16: =SUMPRODUCT((TablaRecoletaNov[Vendedora 1]=A16)+(TablaRecoletaNov[Vendedora 2]=A16)+(TablaRecoletaNov[Vendedora 3]=A16),--(TablaRecoletaNov[Día]<>$K$11)) -> 0 | E16: =SUMPRODUCT((TablaFloridaNov[Vendedora 1]=A16)+(TablaFloridaNov[Vendedora 2]=A16)+(TablaFloridaNov[Vendedora 3]=A16),--(TablaFloridaNov[Día]=$K$11)) -> 0 | F16: =SUMPRODUCT((TablaGuemesNov[Vendedora 1]=A16)+(TablaGuemesNov[Vendedora 2]=A16)+(TablaGuemesNov[Vendedora 3]=A16),--(TablaGuemesNov[Día]=$K$11)) -> 0 | G16: =SUMPRODUCT((TablaRecoletaNov[Vendedora 1]=A16)+(TablaRecoletaNov[Vendedora 2]=A16)+(TablaRecoletaNov[Vendedora 3]=A16),--(TablaRecoletaNov[Día]=$K$11)) -> 0 | H16: =SUM(B16:G16) -> 0
A20: DICIEMBRE 2025
A22: HORAS POR VENDEDORA Y TIENDA | K22: HORAS TOTALES POR TIENDA (normales y feriados trabajados)
A23: Vendedoras | B23: Hora normales | E23: Feriados trabajados | H23: Horas totales trabajadas | I23: Feriados no trabajados | K23: Tienda | L23: Total horas | M23: Máximo
B24: Florida | C24: Güemes | D24: Recoleta | E24: Florida | F24: Güemes | G24: Recoleta | K24: Florida | L24: =SUM(B25:B35)+SUM(E25:E35) -> 535 | M24: 600
A25: Sofía | B25: =SUMPRODUCT((TablaFloridaNov[Vendedora 1]=A25)+(TablaFloridaNov[Vendedora 2]=A25)+(TablaFloridaNov[Vendedora 3]=A25),--(TablaFloridaNov[Día]<>$K$11)) -> 0 | C25: =SUMPRODUCT((TablaGuemesNov[Vendedora 1]=A25)+(TablaGuemesNov[Vendedora 2]=A25)+(TablaGuemesNov[Vendedora 3]=A25),--(TablaGuemesNov[Día]<>$K$11)) -> 143 | D25: =SUMPRODUCT((TablaRecoletaNov[Vendedora 1]=A25)+(TablaRecoletaNov[Vendedora 2]=A25)+(TablaRecoletaNov[Vendedora 3]=A25),--(TablaRecoletaNov[Día]<>$K$11)) -> 0 | E25: =SUMPRODUCT((TablaFloridaNov[Vendedora 1]=A25)+(TablaFloridaNov[Vendedora 2]=A25)+(TablaFloridaNov[Vendedora 3]=A25),--(TablaFloridaNov[Día]=$K$11)) -> 0 | F25: =SUMPRODUCT((TablaGuemesNov[Vendedora 1]=A25)+(TablaGuemesNov[Vendedora 2]=A25)+(TablaGuemesNov[Vendedora 3]=A25),--(TablaGuemesNov[Día]=$K$11)) -> 9 | G25: =SUMPRODUCT((TablaRecoletaNov[Vendedora 1]=A25)+(TablaRecoletaNov[Vendedora 2]=A25)+(TablaRecoletaNov[Vendedora 3]=A25),--(TablaRecoletaNov[Día]=$K$11)) -> 0 | H25: =SUM(B25:G25) -> 152 | K25: Güemes | L25: =SUM(C25:C35)+SUM(F25:F35) -> 152 | M25: 300
A26: Giselle | B26: =SUMPRODUCT((TablaFloridaNov[Vendedora 1]=A26)+(TablaFloridaNov[Vendedora 2]=A26)+(TablaFloridaNov[Vendedora 3]=A26),--(TablaFloridaNov[Día]<>$K$11)) -> 0 | C26: =SUMPRODUCT((TablaGuemesNov[Vendedora 1]=A26)+(TablaGuemesNov[Vendedora 2]=A26)+(TablaGuemesNov[Vendedora 3]=A26),--(TablaGuemesNov[Día]<>$K$11)) -> 0 | D26: =SUMPRODUCT((TablaRecoletaNov[Vendedora 1]=A26)+(TablaRecoletaNov[Vendedora 2]=A26)+(TablaRecoletaNov[Vendedora 3]=A26),--(TablaRecoletaNov[Día]<>$K$11)) -> 0 | E26: =SUMPRODUCT((TablaFloridaNov[Vendedora 1]=A26)+(TablaFloridaNov[Vendedora 2]=A26)+(TablaFloridaNov[Vendedora 3]=A26),--(TablaFloridaNov[Día]=$K$11)) -> 0 | F26: =SUMPRODUCT((TablaGuemesNov[Vendedora 1]=A26)+(TablaGuemesNov[Vendedora 2]=A26)+(TablaGuemesNov[Vendedora 3]=A26),--(TablaGuemesNov[Día]=$K$11)) -> 0 | G26: =SUMPRODUCT((TablaRecoletaNov[Vendedora 1]=A26)+(TablaRecoletaNov[Vendedora 2]=A26)+(TablaRecoletaNov[Vendedora 3]=A26),--(TablaRecoletaNov[Día]=$K$11)) -> 0 | H26: =SUM(B26:G26) -> 0 | K26: Recoleta | L26: =SUM(D25:D35)+SUM(G25:G35) -> 157 | M26: 450
A27: Maitena | B27: =SUMPRODUCT((TablaFloridaNov[Vendedora 1]=A27)+(TablaFloridaNov[Vendedora 2]=A27)+(TablaFloridaNov[Vendedora 3]=A27),--(TablaFloridaNov[Día]<>$K$11)) -> 493 | C27: =SUMPRODUCT((TablaGuemesNov[Vendedora 1]=A27)+(TablaGuemesNov[Vendedora 2]=A27)+(TablaGuemesNov[Vendedora 3]=A27),--(TablaGuemesNov[Día]<>$K$11)) -> 0 | D27: =SUMPRODUCT((TablaRecoletaNov[Vendedora 1]=A27)+(TablaRecoletaNov[Vendedora 2]=A27)+(TablaRecoletaNov[Vendedora 3]=A27),--(TablaRecoletaNov[Día]<>$K$11)) -> 11 | E27: =SUMPRODUCT((TablaFloridaNov[Vendedora 1]=A27)+(TablaFloridaNov[Vendedora 2]=A27)+(TablaFloridaNov[Vendedora 3]=A27),--(TablaFloridaNov[Día]=$K$11)) -> 8 | F27: =SUMPRODUCT((TablaGuemesNov[Vendedora 1]=A27)+(TablaGuemesNov[Vendedora 2]=A27)+(TablaGuemesNov[Vendedora 3]=A27),--(TablaGuemesNov[Día]=$K$11)) -> 0 | G27: =SUMPRODUCT((TablaRecoletaNov[Vendedora 1]=A27)+(TablaRecoletaNov[Vendedora 2]=A27)+(TablaRecoletaNov[Vendedora 3]=A27),--(TablaRecoletaNov[Día]=$K$11)) -> 0 | H27: =SUM(B27:G27) -> 512
A28: Candela I. | B28: =SUMPRODUCT((TablaFloridaNov[Vendedora 1]=A28)+(TablaFloridaNov[Vendedora 2]=A28)+(TablaFloridaNov[Vendedora 3]=A28),--(TablaFloridaNov[Día]<>$K$11)) -> 12 | C28: =SUMPRODUCT((TablaGuemesNov[Vendedora 1]=A28)+(TablaGuemesNov[Vendedora 2]=A28)+(TablaGuemesNov[Vendedora 3]=A28),--(TablaGuemesNov[Día]<>$K$11)) -> 0 | D28: =SUMPRODUCT((TablaRecoletaNov[Vendedora 1]=A28)+(TablaRecoletaNov[Vendedora 2]=A28)+(TablaRecoletaNov[Vendedora 3]=A28),--(TablaRecoletaNov[Día]<>$K$11)) -> 0 | E28: =SUMPRODUCT((TablaFloridaNov[Vendedora 1]=A28)+(TablaFloridaNov[Vendedora 2]=A28)+(TablaFloridaNov[Vendedora 3]=A28),--(TablaFloridaNov[Día]=$K$11)) -> 0 | F28: =SUMPRODUCT((TablaGuemesNov[Vendedora 1]=A28)+(TablaGuemesNov[Vendedora 2]=A28)+(TablaGuemesNov[Vendedora 3]=A28),--(TablaGuemesNov[Día]=$K$11)) -> 0 | G28: =SUMPRODUCT((TablaRecoletaNov[Vendedora 1]=A28)+(TablaRecoletaNov[Vendedora 2]=A28)+(TablaRecoletaNov[Vendedora 3]=A28),--(TablaRecoletaNov[Día]=$K$11)) -> 0 | H28: =SUM(B28:G28) -> 12
A29: Luciana | B29: =SUMPRODUCT((TablaFloridaNov[Vendedora 1]=A29)+(TablaFloridaNov[Vendedora 2]=A29)+(TablaFloridaNov[Vendedora 3]=A29),--(TablaFloridaNov[Día]<>$K$11)) -> 0 | C29: =SUMPRODUCT((TablaGuemesNov[Vendedora 1]=A29)+(TablaGuemesNov[Vendedora 2]=A29)+(TablaGuemesNov[Vendedora 3]=A29),--(TablaGuemesNov[Día]<>$K$11)) -> 0 | D29: =SUMPRODUCT((TablaRecoletaNov[Vendedora 1]=A29)+(TablaRecoletaNov[Vendedora 2]=A29)+(TablaRecoletaNov[Vendedora 3]=A29),--(TablaRecoletaNov[Día]<>$K$11)) -> 0 | E29: =SUMPRODUCT((TablaFloridaNov[Vendedora 1]=A29)+(TablaFloridaNov[Vendedora 2]=A29)+(TablaFloridaNov[Vendedora 3]=A29),--(TablaFloridaNov[Día]=$K$11)) -> 0 | F29: =SUMPRODUCT((TablaGuemesNov[Vendedora 1]=A29)+(TablaGuemesNov[Vendedora 2]=A29)+(TablaGuemesNov[Vendedora 3]=A29),--(TablaGuemesNov[Día]=$K$11)) -> 0 | G29: =SUMPRODUCT((TablaRecoletaNov[Vendedora 1]=A29)+(TablaRecoletaNov[Vendedora 2]=A29)+(TablaRecoletaNov[Vendedora 3]=A29),--(TablaRecoletaNov[Día]=$K$11)) -> 0 | H29: =SUM(B29:G29) -> 0 | K29: FERIADOS
A30: Bárbara | B30: =SUMPRODUCT((TablaFloridaNov[Vendedora 1]=A30)+(TablaFloridaNov[Vendedora 2]=A30)+(TablaFloridaNov[Vendedora 3]=A30),--(TablaFloridaNov[Día]<>$K$11)) -> 0 | C30: =SUMPRODUCT((TablaGuemesNov[Vendedora 1]=A30)+(TablaGuemesNov[Vendedora 2]=A30)+(TablaGuemesNov[Vendedora 3]=A30),--(TablaGuemesNov[Día]<>$K$11)) -> 0 | D30: =SUMPRODUCT((TablaRecoletaNov[Vendedora 1]=A30)+(TablaRecoletaNov[Vendedora 2]=A30)+(TablaRecoletaNov[Vendedora 3]=A30),--(TablaRecoletaNov[Día]<>$K$11)) -> 0 | E30: =SUMPRODUCT((TablaFloridaNov[Vendedora 1]=A30)+(TablaFloridaNov[Vendedora 2]=A30)+(TablaFloridaNov[Vendedora 3]=A30),--(TablaFloridaNov[Día]=$K$11)) -> 0 | F30: =SUMPRODUCT((TablaGuemesNov[Vendedora 1]=A30)+(TablaGuemesNov[Vendedora 2]=A30)+(TablaGuemesNov[Vendedora 3]=A30),--(TablaGuemesNov[Día]=$K$11)) -> 0 | G30: =SUMPRODUCT((TablaRecoletaNov[Vendedora 1]=A30)+(TablaRecoletaNov[Vendedora 2]=A30)+(TablaRecoletaNov[Vendedora 3]=A30),--(TablaRecoletaNov[Día]=$K$11)) -> 0 | H30: =SUM(B30:G30) -> 0 | K30: 45999
A31: Rocío | B31: =SUMPRODUCT((TablaFloridaNov[Vendedora 1]=A31)+(TablaFloridaNov[Vendedora 2]=A31)+(TablaFloridaNov[Vendedora 3]=A31),--(TablaFloridaNov[Día]<>$K$11)) -> 5 | C31: =SUMPRODUCT((TablaGuemesNov[Vendedora 1]=A31)+(TablaGuemesNov[Vendedora 2]=A31)+(TablaGuemesNov[Vendedora 3]=A31),--(TablaGuemesNov[Día]<>$K$11)) -> 0 | D31: =SUMPRODUCT((TablaRecoletaNov[Vendedora 1]=A31)+(TablaRecoletaNov[Vendedora 2]=A31)+(TablaRecoletaNov[Vendedora 3]=A31),--(TablaRecoletaNov[Día]<>$K$11)) -> 63 | E31: =SUMPRODUCT((TablaFloridaNov[Vendedora 1]=A31)+(TablaFloridaNov[Vendedora 2]=A31)+(TablaFloridaNov[Vendedora 3]=A31),--(TablaFloridaNov[Día]=$K$11)) -> 0 | F31: =SUMPRODUCT((TablaGuemesNov[Vendedora 1]=A31)+(TablaGuemesNov[Vendedora 2]=A31)+(TablaGuemesNov[Vendedora 3]=A31),--(TablaGuemesNov[Día]=$K$11)) -> 0 | G31: =SUMPRODUCT((TablaRecoletaNov[Vendedora 1]=A31)+(TablaRecoletaNov[Vendedora 2]=A31)+(TablaRecoletaNov[Vendedora 3]=A31),--(TablaRecoletaNov[Día]=$K$11)) -> 11 | H31: =SUM(B31:G31) -> 79
A32: Mailén | B32: =SUMPRODUCT((TablaFloridaNov[Vendedora 1]=A32)+(TablaFloridaNov[Vendedora 2]=A32)+(TablaFloridaNov[Vendedora 3]=A32),--(TablaFloridaNov[Día]<>$K$11)) -> 12 | C32: =SUMPRODUCT((TablaGuemesNov[Vendedora 1]=A32)+(TablaGuemesNov[Vendedora 2]=A32)+(TablaGuemesNov[Vendedora 3]=A32),--(TablaGuemesNov[Día]<>$K$11)) -> 0 | D32: =SUMPRODUCT((TablaRecoletaNov[Vendedora 1]=A32)+(TablaRecoletaNov[Vendedora 2]=A32)+(TablaRecoletaNov[Vendedora 3]=A32),--(TablaRecoletaNov[Día]<>$K$11)) -> 0 | E32: =SUMPRODUCT((TablaFloridaNov[Vendedora 1]=A32)+(TablaFloridaNov[Vendedora 2]=A32)+(TablaFloridaNov[Vendedora 3]=A32),--(TablaFloridaNov[Día]=$K$11)) -> 0 | F32: =SUMPRODUCT((TablaGuemesNov[Vendedora 1]=A32)+(TablaGuemesNov[Vendedora 2]=A32)+(TablaGuemesNov[Vendedora 3]=A32),--(TablaGuemesNov[Día]=$K$11)) -> 0 | G32: =SUMPRODUCT((TablaRecoletaNov[Vendedora 1]=A32)+(TablaRecoletaNov[Vendedora 2]=A32)+(TablaRecoletaNov[Vendedora 3]=A32),--(TablaRecoletaNov[Día]=$K$11)) -> 0 | H32: =SUM(B32:G32) -> 12
A33: Candela G. | B33: =SUMPRODUCT((TablaFloridaNov[Vendedora 1]=A33)+(TablaFloridaNov[Vendedora 2]=A33)+(TablaFloridaNov[Vendedora 3]=A33),--(TablaFloridaNov[Día]<>$K$11)) -> 0 | C33: =SUMPRODUCT((TablaGuemesNov[Vendedora 1]=A33)+(TablaGuemesNov[Vendedora 2]=A33)+(TablaGuemesNov[Vendedora 3]=A33),--(TablaGuemesNov[Día]<>$K$11)) -> 0 | D33: =SUMPRODUCT((TablaRecoletaNov[Vendedora 1]=A33)+(TablaRecoletaNov[Vendedora 2]=A33)+(TablaRecoletaNov[Vendedora 3]=A33),--(TablaRecoletaNov[Día]<>$K$11)) -> 0 | E33: =SUMPRODUCT((TablaFloridaNov[Vendedora 1]=A33)+(TablaFloridaNov[Vendedora 2]=A33)+(TablaFloridaNov[Vendedora 3]=A33),--(TablaFloridaNov[Día]=$K$11)) -> 0 | F33: =SUMPRODUCT((TablaGuemesNov[Vendedora 1]=A33)+(TablaGuemesNov[Vendedora 2]=A33)+(TablaGuemesNov[Vendedora 3]=A33),--(TablaGuemesNov[Día]=$K$11)) -> 0 | G33: =SUMPRODUCT((TablaRecoletaNov[Vendedora 1]=A33)+(TablaRecoletaNov[Vendedora 2]=A33)+(TablaRecoletaNov[Vendedora 3]=A33),--(TablaRecoletaNov[Día]=$K$11)) -> 0 | H33: =SUM(B33:G33) -> 0
A34: Micaela | B34: =SUMPRODUCT((TablaFloridaNov[Vendedora 1]=A34)+(TablaFloridaNov[Vendedora 2]=A34)+(TablaFloridaNov[Vendedora 3]=A34),--(TablaFloridaNov[Día]<>$K$11)) -> 0 | C34: =SUMPRODUCT((TablaGuemesNov[Vendedora 1]=A34)+(TablaGuemesNov[Vendedora 2]=A34)+(TablaGuemesNov[Vendedora 3]=A34),--(TablaGuemesNov[Día]<>$K$11)) -> 0 | D34: =SUMPRODUCT((TablaRecoletaNov[Vendedora 1]=A34)+(TablaRecoletaNov[Vendedora 2]=A34)+(TablaRecoletaNov[Vendedora 3]=A34),--(TablaRecoletaNov[Día]<>$K$11)) -> 72 | E34: =SUMPRODUCT((TablaFloridaNov[Vendedora 1]=A34)+(TablaFloridaNov[Vendedora 2]=A34)+(TablaFloridaNov[Vendedora 3]=A34),--(TablaFloridaNov[Día]=$K$11)) -> 5 | F34: =SUMPRODUCT((TablaGuemesNov[Vendedora 1]=A34)+(TablaGuemesNov[Vendedora 2]=A34)+(TablaGuemesNov[Vendedora 3]=A34),--(TablaGuemesNov[Día]=$K$11)) -> 0 | G34: =SUMPRODUCT((TablaRecoletaNov[Vendedora 1]=A34)+(TablaRecoletaNov[Vendedora 2]=A34)+(TablaRecoletaNov[Vendedora 3]=A34),--(TablaRecoletaNov[Día]=$K$11)) -> 0 | H34: =SUM(B34:G34) -> 77
A35: [Nueva] | B35: =SUMPRODUCT((TablaFloridaNov[Vendedora 1]=A35)+(TablaFloridaNov[Vendedora 2]=A35)+(TablaFloridaNov[Vendedora 3]=A35),--(TablaFloridaNov[Día]<>$K$11)) -> 0 | C35: =SUMPRODUCT((TablaGuemesNov[Vendedora 1]=A35)+(TablaGuemesNov[Vendedora 2]=A35)+(TablaGuemesNov[Vendedora 3]=A35),--(TablaGuemesNov[Día]<>$K$11)) -> 0 | D35: =SUMPRODUCT((TablaRecoletaNov[Vendedora 1]=A35)+(TablaRecoletaNov[Vendedora 2]=A35)+(TablaRecoletaNov[Vendedora 3]=A35),--(TablaRecoletaNov[Día]<>$K$11)) -> 0 | E35: =SUMPRODUCT((TablaFloridaNov[Vendedora 1]=A35)+(TablaFloridaNov[Vendedora 2]=A35)+(TablaFloridaNov[Vendedora 3]=A35),--(TablaFloridaNov[Día]=$K$11)) -> 0 | F35: =SUMPRODUCT((TablaGuemesNov[Vendedora 1]=A35)+(TablaGuemesNov[Vendedora 2]=A35)+(TablaGuemesNov[Vendedora 3]=A35),--(TablaGuemesNov[Día]=$K$11)) -> 0 | G35: =SUMPRODUCT((TablaRecoletaNov[Vendedora 1]=A35)+(TablaRecoletaNov[Vendedora 2]=A35)+(TablaRecoletaNov[Vendedora 3]=A35),--(TablaRecoletaNov[Día]=$K$11)) -> 0 | H35: =SUM(B35:G35) -> 0

Sheet Florida
A1: FLORIDA | I1: FLORIDA
A2: NOVIEMBRE | I2: DICIEMBRE
A4: Personal Mínimo Requerido por turno: | D4: 2 | I4: Personal Mínimo Requerido por turno: | L4: 2
A6: Resumen de horas por vendedora | I6: Resumen de horas por vendedora
A7: Vendedoras | B7: Horas normales trabajadas | C7: Horas feriados trabajados | D7: Horas totales trabajadas | F7: HORAS EN FLORIDA | I7: Vendedoras | J7: Horas normales trabajadas | K7: Horas feriados trabajados | L7: Horas totales trabajadas | N7: HORAS EN FLORIDA
A8: ='Resumen zona'!A6 -> Sofía | B8: =SUMPRODUCT((TablaFloridaNov[Vendedora 1]=A8)+(TablaFloridaNov[Vendedora 2]=A8)+(TablaFloridaNov[Vendedora 3]=A8),--(TablaFloridaNov[Día]<>$F$14)) + SUMPRODUCT((TablaGuemesNov[Vendedora 1]=A8)+(TablaGuemesNov[Vendedora 2]=A8)+(TablaGuemesNov[Vendedora 3]=A8),--(TablaGuemesNov[Día]<>$F$14)) + SUMPRODUCT((TablaRecoletaNov[Vendedora 1]=A8)+(TablaRecoletaNov[Vendedora 2]=A8)+(TablaRecoletaNov[Vendedora 3]=A8),--(TablaRecoletaNov[Día]<>$F$14)) -> 143 | C8: =SUMPRODUCT((TablaFloridaNov[Vendedora 1]=A8)+(TablaFloridaNov[Vendedora 2]=A8)+(TablaFloridaNov[Vendedora 3]=A8),--(TablaFloridaNov[Día]=$F$14)) + SUMPRODUCT((TablaGuemesNov[Vendedora 1]=A8)+(TablaGuemesNov[Vendedora 2]=A8)+(TablaGuemesNov[Vendedora 3]=A8),--(TablaGuemesNov[Día]=$F$14)) + SUMPRODUCT((TablaRecoletaNov[Vendedora 1]=A8)+(TablaRecoletaNov[Vendedora 2]=A8)+(TablaRecoletaNov[Vendedora 3]=A8),--(TablaRecoletaNov[Día]=$F$14)) -> 9 | D8: =SUM(B8:C8) -> 152 | F8: Máximas | I8: ='Resumen zona'!A25 -> Sofía | J8: =SUMPRODUCT((TablaFloridaDic[Vendedora 1]=I8)+(TablaFloridaDic[Vendedora 2]=I8)+(TablaFloridaDic[Vendedora 3]=I8),--(TablaFloridaDic[Día]<>$N$14)) + SUMPRODUCT((TablaGuemesDic[Vendedora 1]=I8)+(TablaGuemesDic[Vendedora 2]=I8)+(TablaGuemesDic[Vendedora 3]=I8),--(TablaGuemesDic[Día]<>$N$14)) + SUMPRODUCT((TablaRecoletaDic[Vendedora 1]=I8)+(TablaRecoletaDic[Vendedora 2]=I8)+(TablaRecoletaDic[Vendedora 3]=I8),--(TablaRecoletaDic[Día]<>$N$14)) -> 29 | K8: =SUMPRODUCT((TablaFloridaDic[Vendedora 1]=I8)+(TablaFloridaDic[Vendedora 2]=I8)+(TablaFloridaDic[Vendedora 3]=I8),--(TablaFloridaDic[Día]=$N$14)) + SUMPRODUCT((TablaGuemesDic[Vendedora 1]=I8)+(TablaGuemesDic[Vendedora 2]=I8)+(TablaGuemesDic[Vendedora 3]=I8),--(TablaGuemesDic[Día]=$N$14)) + SUMPRODUCT((TablaRecoletaDic[Vendedora 1]=I8)+(TablaRecoletaDic[Vendedora 2]=I8)+(TablaRecoletaDic[Vendedora 3]=I8),--(TablaRecoletaDic[Día]=$N$14)) -> 0 | L8: =J8+K8 -> 29 | N8: Máximas
A9: ='Resumen zona'!A7 -> Giselle | B9: =SUMPRODUCT((TablaFloridaNov[Vendedora 1]=A9)+(TablaFloridaNov[Vendedora 2]=A9)+(TablaFloridaNov[Vendedora 3]=A9),--(TablaFloridaNov[Día]<>$F$14)) + SUMPRODUCT((TablaGuemesNov[Vendedora 1]=A9)+(TablaGuemesNov[Vendedora 2]=A9)+(TablaGuemesNov[Vendedora 3]=A9),--(TablaGuemesNov[Día]<>$F$14)) + SUMPRODUCT((TablaRecoletaNov[Vendedora 1]=A9)+(TablaRecoletaNov[Vendedora 2]=A9)+(TablaRecoletaNov[Vendedora 3]=A9),--(TablaRecoletaNov[Día]<>$F$14)) -> 0 | C9: =SUMPRODUCT((TablaFloridaNov[Vendedora 1]=A9)+(TablaFloridaNov[Vendedora 2]=A9)+(TablaFloridaNov[Vendedora 3]=A9),--(TablaFloridaNov[Día]=$F$14)) + SUMPRODUCT((TablaGuemesNov[Vendedora 1]=A9)+(TablaGuemesNov[Vendedora 2]=A9)+(TablaGuemesNov[Vendedora 3]=A9),--(TablaGuemesNov[Día]=$F$14)) + SUMPRODUCT((TablaRecoletaNov[Vendedora 1]=A9)+(TablaRecoletaNov[Vendedora 2]=A9)+(TablaRecoletaNov[Vendedora 3]=A9),--(TablaRecoletaNov[Día]=$F$14)) -> 0 | D9: =SUM(B9:C9) -> 0 | F9: ='Resumen zona'!M5 -> 600 | I9: ='Resumen zona'!A26 -> Giselle | J9: =SUMPRODUCT((TablaFloridaDic[Vendedora 1]=I9)+(TablaFloridaDic[Vendedora 2]=I9)+(TablaFloridaDic[Vendedora 3]=I9),--(TablaFloridaDic[Día]<>$N$14)) + SUMPRODUCT((TablaGuemesDic[Vendedora 1]=I9)+(TablaGuemesDic[Vendedora 2]=I9)+(TablaGuemesDic[Vendedora 3]=I9),--(TablaGuemesDic[Día]<>$N$14)) + SUMPRODUCT((TablaRecoletaDic[Vendedora 1]=I9)+(TablaRecoletaDic[Vendedora 2]=I9)+(TablaRecoletaDic[Vendedora 3]=I9),--(TablaRecoletaDic[Día]<>$N$14)) -> 0 | K9: =SUMPRODUCT((TablaFloridaDic[Vendedora 1]=I9)+(TablaFloridaDic[Vendedora 2]=I9)+(TablaFloridaDic[Vendedora 3]=I9),--(TablaFloridaDic[Día]=$N$14)) + SUMPRODUCT((TablaGuemesDic[Vendedora 1]=I9)+(TablaGuemesDic[Vendedora 2]=I9)+(TablaGuemesDic[Vendedora 3]=I9),--(TablaGuemesDic[Día]=$N$14)) + SUMPRODUCT((TablaRecoletaDic[Vendedora 1]=I9)+(TablaRecoletaDic[Vendedora 2]=I9)+(TablaRecoletaDic[Vendedora 3]=I9),--(TablaRecoletaDic[Día]=$N$14)) -> 0 | L9: =J9+K9 -> 0 | N9: ='Resumen zona'!M24 -> 600
A10: ='Resumen zona'!A8 -> Maitena | B10: =SUMPRODUCT((TablaFloridaNov[Vendedora 1]=A10)+(TablaFloridaNov[Vendedora 2]=A10)+(TablaFloridaNov[Vendedora 3]=A10),--(TablaFloridaNov[Día]<>$F$14)) + SUMPRODUCT((TablaGuemesNov[Vendedora 1]=A10)+(TablaGuemesNov[Vendedora 2]=A10)+(TablaGuemesNov[Vendedora 3]=A10),--(TablaGuemesNov[Día]<>$F$14)) + SUMPRODUCT((TablaRecoletaNov[Vendedora 1]=A10)+(TablaRecoletaNov[Vendedora 2]=A10)+(TablaRecoletaNov[Vendedora 3]=A10),--(TablaRecoletaNov[Día]<>$F$14)) -> 504 | C10: =SUMPRODUCT((TablaFloridaNov[Vendedora 1]=A10)+(TablaFloridaNov[Vendedora 2]=A10)+(TablaFloridaNov[Vendedora 3]=A10),--(TablaFloridaNov[Día]=$F$14)) + SUMPRODUCT((TablaGuemesNov[Vendedora 1]=A10)+(TablaGuemesNov[Vendedora 2]=A10)+(TablaGuemesNov[Vendedora 3]=A10),--(TablaGuemesNov[Día]=$F$14)) + SUMPRODUCT((TablaRecoletaNov[Vendedora 1]=A10)+(TablaRecoletaNov[Vendedora 2]=A10)+(TablaRecoletaNov[Vendedora 3]=A10),--(TablaRecoletaNov[Día]=$F$14)) -> 8 | D10: =SUM(B10:C10) -> 512 | F10: Ocupadas | I10: ='Resumen zona'!A27 -> Maitena | J10: =SUMPRODUCT((TablaFloridaDic[Vendedora 1]=I10)+(TablaFloridaDic[Vendedora 2]=I10)+(TablaFloridaDic[Vendedora 3]=I10),--(TablaFloridaDic[Día]<>$N$14)) + SUMPRODUCT((TablaGuemesDic[Vendedora 1]=I10)+(TablaGuemesDic[Vendedora 2]=I10)+(TablaGuemesDic[Vendedora 3]=I10),--(TablaGuemesDic[Día]<>$N$14)) + SUMPRODUCT((TablaRecoletaDic[Vendedora 1]=I10)+(TablaRecoletaDic[Vendedora 2]=I10)+(TablaRecoletaDic[Vendedora 3]=I10),--(TablaRecoletaDic[Día]<>$N$14)) -> 981 | K10: =SUMPRODUCT((TablaFloridaDic[Vendedora 1]=I10)+(TablaFloridaDic[Vendedora 2]=I10)+(TablaFloridaDic[Vendedora 3]=I10),--(TablaFloridaDic[Día]=$N$14)) + SUMPRODUCT((TablaGuemesDic[Vendedora 1]=I10)+(TablaGuemesDic[Vendedora 2]=I10)+(TablaGuemesDic[Vendedora 3]=I10),--(TablaGuemesDic[Día]=$N$14)) + SUMPRODUCT((TablaRecoletaDic[Vendedora 1]=I10)+(TablaRecoletaDic[Vendedora 2]=I10)+(TablaRecoletaDic[Vendedora 3]=I10),--(TablaRecoletaDic[Día]=$N$14)) -> 34 | L10: =J10+K10 -> 1015 | N10: Ocupadas
A11: ='Resumen zona'!A9 -> Candela I. | B11: =SUMPRODUCT((TablaFloridaNov[Vendedora 1]=A11)+(TablaFloridaNov[Vendedora 2]=A11)+(TablaFloridaNov[Vendedora 3]=A11),--(TablaFloridaNov[Día]<>$F$14)) + SUMPRODUCT((TablaGuemesNov[Vendedora 1]=A11)+(TablaGuemesNov[Vendedora 2]=A11)+(TablaGuemesNov[Vendedora 3]=A11),--(TablaGuemesNov[Día]<>$F$14)) + SUMPRODUCT((TablaRecoletaNov[Vendedora 1]=A11)+(TablaRecoletaNov[Vendedora 2]=A11)+(TablaRecoletaNov[Vendedora 3]=A11),--(TablaRecoletaNov[Día]<>$F$14)) -> 12 | C11: =SUMPRODUCT((TablaFloridaNov[Vendedora 1]=A11)+(TablaFloridaNov[Vendedora 2]=A11)+(TablaFloridaNov[Vendedora 3]=A11),--(TablaFloridaNov[Día]=$F$14)) + SUMPRODUCT((TablaGuemesNov[Vendedora 1]=A11)+(TablaGuemesNov[Vendedora 2]=A11)+(TablaGuemesNov[Vendedora 3]=A11),--(TablaGuemesNov[Día]=$F$14)) + SUMPRODUCT((TablaRecoletaNov[Vendedora 1]=A11)+(TablaRecoletaNov[Vendedora 2]=A11)+(TablaRecoletaNov[Vendedora 3]=A11),--(TablaRecoletaNov[Día]=$F$14)) -> 0 | D11: =SUM(B11:C11) -> 12 | F11: =SUM(D8:D18) -> 844 | I11: ='Resumen zona'!A28 -> Candela I. | J11: =SUMPRODUCT((TablaFloridaDic[Vendedora 1]=I11)+(TablaFloridaDic[Vendedora 2]=I11)+(TablaFloridaDic[Vendedora 3]=I11),--(TablaFloridaDic[Día]<>$N$14)) + SUMPRODUCT((TablaGuemesDic[Vendedora 1]=I11)+(TablaGuemesDic[Vendedora 2]=I11)+(TablaGuemesDic[Vendedora 3]=I11),--(TablaGuemesDic[Día]<>$N$14)) + SUMPRODUCT((TablaRecoletaDic[Vendedora 1]=I11)+(TablaRecoletaDic[Vendedora 2]=I11)+(TablaRecoletaDic[Vendedora 3]=I11),--(TablaRecoletaDic[Día]<>$N$14)) -> 0 | K11: =SUMPRODUCT((TablaFloridaDic[Vendedora 1]=I11)+(TablaFloridaDic[Vendedora 2]=I11)+(TablaFloridaDic[Vendedora 3]=I11),--(TablaFloridaDic[Día]=$N$14)) + SUMPRODUCT((TablaGuemesDic[Vendedora 1]=I11)+(TablaGuemesDic[Vendedora 2]=I11)+(TablaGuemesDic[Vendedora 3]=I11),--(TablaGuemesDic[Día]=$N$14)) + SUMPRODUCT((TablaRecoletaDic[Vendedora 1]=I11)+(TablaRecoletaDic[Vendedora 2]=I11)+(TablaRecoletaDic[Vendedora 3]=I11),--(TablaRecoletaDic[Día]=$N$14)) -> 0 | L11: =J11+K11 -> 0 | N11: =SUM(L8:L18) -> 1079
A12: ='Resumen zona'!A10 -> Luciana | B12: =SUMPRODUCT((TablaFloridaNov[Vendedora 1]=A12)+(TablaFloridaNov[Vendedora 2]=A12)+(TablaFloridaNov[Vendedora 3]=A12),--(TablaFloridaNov[Día]<>$F$14)) + SUMPRODUCT((TablaGuemesNov[Vendedora 1]=A12)+(TablaGuemesNov[Vendedora 2]=A12)+(TablaGuemesNov[Vendedora 3]=A12),--(TablaGuemesNov[Día]<>$F$14)) + SUMPRODUCT((TablaRecoletaNov[Vendedora 1]=A12)+(TablaRecoletaNov[Vendedora 2]=A12)+(TablaRecoletaNov[Vendedora 3]=A12),--(TablaRecoletaNov[Día]<>$F$14)) -> 0 | C12: =SUMPRODUCT((TablaFloridaNov[Vendedora 1]=A12)+(TablaFloridaNov[Vendedora 2]=A12)+(TablaFloridaNov[Vendedora 3]=A12),--(TablaFloridaNov[Día]=$F$14)) + SUMPRODUCT((TablaGuemesNov[Vendedora 1]=A12)+(TablaGuemesNov[Vendedora 2]=A12)+(TablaGuemesNov[Vendedora 3]=A12),--(TablaGuemesNov[Día]=$F$14)) + SUMPRODUCT((TablaRecoletaNov[Vendedora 1]=A12)+(TablaRecoletaNov[Vendedora 2]=A12)+(TablaRecoletaNov[Vendedora 3]=A12),--(TablaRecoletaNov[Día]=$F$14)) -> 0 | D12: =SUM(B12:C12) -> 0 | I12: ='Resumen zona'!A29 -> Luciana | J12: =SUMPRODUCT((TablaFloridaDic[Vendedora 1]=I12)+(TablaFloridaDic[Vendedora 2]=I12)+(TablaFloridaDic[Vendedora 3]=I12),--(TablaFloridaDic[Día]<>$N$14)) + SUMPRODUCT((TablaGuemesDic[Vendedora 1]=I12)+(TablaGuemesDic[Vendedora 2]=I12)+(TablaGuemesDic[Vendedora 3]=I12),--(TablaGuemesDic[Día]<>$N$14)) + SUMPRODUCT((TablaRecoletaDic[Vendedora 1]=I12)+(TablaRecoletaDic[Vendedora 2]=I12)+(TablaRecoletaDic[Vendedora 3]=I12),--(TablaRecoletaDic[Día]<>$N$14)) -> 0 | K12: =SUMPRODUCT((TablaFloridaDic[Vendedora 1]=I12)+(TablaFloridaDic[Vendedora 2]=I12)+(TablaFloridaDic[Vendedora 3]=I12),--(TablaFloridaDic[Día]=$N$14)) + SUMPRODUCT((TablaGuemesDic[Vendedora 1]=I12)+(TablaGuemesDic[Vendedora 2]=I12)+(TablaGuemesDic[Vendedora 3]=I12),--(TablaGuemesDic[Día]=$N$14)) + SUMPRODUCT((TablaRecoletaDic[Vendedora 1]=I12)+(TablaRecoletaDic[Vendedora 2]=I12)+(TablaRecoletaDic[Vendedora 3]=I12),--(TablaRecoletaDic[Día]=$N$14)) -> 0 | L12: =J12+K12 -> 0
A13: ='Resumen zona'!A11 -> Bárbara | B13: =SUMPRODUCT((TablaFloridaNov[Vendedora 1]=A13)+(TablaFloridaNov[Vendedora 2]=A13)+(TablaFloridaNov[Vendedora 3]=A13),--(TablaFloridaNov[Día]<>$F$14)) + SUMPRODUCT((TablaGuemesNov[Vendedora 1]=A13)+(TablaGuemesNov[Vendedora 2]=A13)+(TablaGuemesNov[Vendedora 3]=A13),--(TablaGuemesNov[Día]<>$F$14)) + SUMPRODUCT((TablaRecoletaNov[Vendedora 1]=A13)+(TablaRecoletaNov[Vendedora 2]=A13)+(TablaRecoletaNov[Vendedora 3]=A13),--(TablaRecoletaNov[Día]<>$F$14)) -> 0 | C13: =SUMPRODUCT((TablaFloridaNov[Vendedora 1]=A13)+(TablaFloridaNov[Vendedora 2]=A13)+(TablaFloridaNov[Vendedora 3]=A13),--(TablaFloridaNov[Día]=$F$14)) + SUMPRODUCT((TablaGuemesNov[Vendedora 1]=A13)+(TablaGuemesNov[Vendedora 2]=A13)+(TablaGuemesNov[Vendedora 3]=A13),--(TablaGuemesNov[Día]=$F$14)) + SUMPRODUCT((TablaRecoletaNov[Vendedora 1]=A13)+(TablaRecoletaNov[Vendedora 2]=A13)+(TablaRecoletaNov[Vendedora 3]=A13),--(TablaRecoletaNov[Día]=$F$14)) -> 0 | D13: =SUM(B13:C13) -> 0 | F13: FERIADOS | I13: ='Resumen zona'!A30 -> Bárbara | J13: =SUMPRODUCT((TablaFloridaDic[Vendedora 1]=I13)+(TablaFloridaDic[Vendedora 2]=I13)+(TablaFloridaDic[Vendedora 3]=I13),--(TablaFloridaDic[Día]<>$N$14)) + SUMPRODUCT((TablaGuemesDic[Vendedora 1]=I13)+(TablaGuemesDic[Vendedora 2]=I13)+(TablaGuemesDic[Vendedora 3]=I13),--(TablaGuemesDic[Día]<>$N$14)) + SUMPRODUCT((TablaRecoletaDic[Vendedora 1]=I13)+(TablaRecoletaDic[Vendedora 2]=I13)+(TablaRecoletaDic[Vendedora 3]=I13),--(TablaRecoletaDic[Día]<>$N$14)) -> 0 | K13: =SUMPRODUCT((TablaFloridaDic[Vendedora 1]=I13)+(TablaFloridaDic[Vendedora 2]=I13)+(TablaFloridaDic[Vendedora 3]=I13),--(TablaFloridaDic[Día]=$N$14)) + SUMPRODUCT((TablaGuemesDic[Vendedora 1]=I13)+(TablaGuemesDic[Vendedora 2]=I13)+(TablaGuemesDic[Vendedora 3]=I13),--(TablaGuemesDic[Día]=$N$14)) + SUMPRODUCT((TablaRecoletaDic[Vendedora 1]=I13)+(TablaRecoletaDic[Vendedora 2]=I13)+(TablaRecoletaDic[Vendedora 3]=I13),--(TablaRecoletaDic[Día]=$N$14)) -> 0 | L13: =J13+K13 -> 0 | N13: FERIADOS
A14: ='Resumen zona'!A12 -> Rocío | B14: =SUMPRODUCT((TablaFloridaNov[Vendedora 1]=A14)+(TablaFloridaNov[Vendedora 2]=A14)+(TablaFloridaNov[Vendedora 3]=A14),--(TablaFloridaNov[Día]<>$F$14)) + SUMPRODUCT((TablaGuemesNov[Vendedora 1]=A14)+(TablaGuemesNov[Vendedora 2]=A14)+(TablaGuemesNov[Vendedora 3]=A14),--(TablaGuemesNov[Día]<>$F$14)) + SUMPRODUCT((TablaRecoletaNov[Vendedora 1]=A14)+(TablaRecoletaNov[Vendedora 2]=A14)+(TablaRecoletaNov[Vendedora 3]=A14),--(TablaRecoletaNov[Día]<>$F$14)) -> 68 | C14: =SUMPRODUCT((TablaFloridaNov[Vendedora 1]=A14)+(TablaFloridaNov[Vendedora 2]=A14)+(TablaFloridaNov[Vendedora 3]=A14),--(TablaFloridaNov[Día]=$F$14)) + SUMPRODUCT((TablaGuemesNov[Vendedora 1]=A14)+(TablaGuemesNov[Vendedora 2]=A14)+(TablaGuemesNov[Vendedora 3]=A14),--(TablaGuemesNov[Día]=$F$14)) + SUMPRODUCT((TablaRecoletaNov[Vendedora 1]=A14)+(TablaRecoletaNov[Vendedora 2]=A14)+(TablaRecoletaNov[Vendedora 3]=A14),--(TablaRecoletaNov[Día]=$F$14)) -> 11 | D14: =SUM(B14:C14) -> 79 | F14: ='Resumen zona'!K11 -> 45985 | I14: ='Resumen zona'!A31 -> Rocío | J14: =SUMPRODUCT((TablaFloridaDic[Vendedora 1]=I14)+(TablaFloridaDic[Vendedora 2]=I14)+(TablaFloridaDic[Vendedora 3]=I14),--(TablaFloridaDic[Día]<>$N$14)) + SUMPRODUCT((TablaGuemesDic[Vendedora 1]=I14)+(TablaGuemesDic[Vendedora 2]=I14)+(TablaGuemesDic[Vendedora 3]=I14),--(TablaGuemesDic[Día]<>$N$14)) + SUMPRODUCT((TablaRecoletaDic[Vendedora 1]=I14)+(TablaRecoletaDic[Vendedora 2]=I14)+(TablaRecoletaDic[Vendedora 3]=I14),--(TablaRecoletaDic[Día]<>$N$14)) -> 19 | K14: =SUMPRODUCT((TablaFloridaDic[Vendedora 1]=I14)+(TablaFloridaDic[Vendedora 2]=I14)+(TablaFloridaDic[Vendedora 3]=I14),--(TablaFloridaDic[Día]=$N$14)) + SUMPRODUCT((TablaGuemesDic[Vendedora 1]=I14)+(TablaGuemesDic[Vendedora 2]=I14)+(TablaGuemesDic[Vendedora 3]=I14),--(TablaGuemesDic[Día]=$N$14)) + SUMPRODUCT((TablaRecoletaDic[Vendedora 1]=I14)+(TablaRecoletaDic[Vendedora 2]=I14)+(TablaRecoletaDic[Vendedora 3]=I14),--(TablaRecoletaDic[Día]=$N$14)) -> 4 | L14: =J14+K14 -> 23 | N14: ='Resumen zona'!K30 -> 45999
A15: ='Resumen zona'!A13 -> Mailén | B15: =SUMPRODUCT((TablaFloridaNov[Vendedora 1]=A15)+(TablaFloridaNov[Vendedora 2]=A15)+(TablaFloridaNov[Vendedora 3]=A15),--(TablaFloridaNov[Día]<>$F$14)) + SUMPRODUCT((TablaGuemesNov[Vendedora 1]=A15)+(TablaGuemesNov[Vendedora 2]=A15)+(TablaGuemesNov[Vendedora 3]=A15),--(TablaGuemesNov[Día]<>$F$14)) + SUMPRODUCT((TablaRecoletaNov[Vendedora 1]=A15)+(TablaRecoletaNov[Vendedora 2]=A15)+(TablaRecoletaNov[Vendedora 3]=A15),--(TablaRecoletaNov[Día]<>$F$14)) -> 12 | C15: =SUMPRODUCT((TablaFloridaNov[Vendedora 1]=A15)+(TablaFloridaNov[Vendedora 2]=A15)+(TablaFloridaNov[Vendedora 3]=A15),--(TablaFloridaNov[Día]=$F$14)) + SUMPRODUCT((TablaGuemesNov[Vendedora 1]=A15)+(TablaGuemesNov[Vendedora 2]=A15)+(TablaGuemesNov[Vendedora 3]=A15),--(TablaGuemesNov[Día]=$F$14)) + SUMPRODUCT((TablaRecoletaNov[Vendedora 1]=A15)+(TablaRecoletaNov[Vendedora 2]=A15)+(TablaRecoletaNov[Vendedora 3]=A15),--(TablaRecoletaNov[Día]=$F$14)) -> 0 | D15: =SUM(B15:C15) -> 12 | I15: ='Resumen zona'!A32 -> Mailén | J15: =SUMPRODUCT((TablaFloridaDic[Vendedora 1]=I15)+(TablaFloridaDic[Vendedora 2]=I15)+(TablaFloridaDic[Vendedora 3]=I15),--(TablaFloridaDic[Día]<>$N$14)) + SUMPRODUCT((TablaGuemesDic[Vendedora 1]=I15)+(TablaGuemesDic[Vendedora 2]=I15)+(TablaGuemesDic[Vendedora 3]=I15),--(TablaGuemesDic[Día]<>$N$14)) + SUMPRODUCT((TablaRecoletaDic[Vendedora 1]=I15)+(TablaRecoletaDic[Vendedora 2]=I15)+(TablaRecoletaDic[Vendedora 3]=I15),--(TablaRecoletaDic[Día]<>$N$14)) -> 3 | K15: =SUMPRODUCT((TablaFloridaDic[Vendedora 1]=I15)+(TablaFloridaDic[Vendedora 2]=I15)+(TablaFloridaDic[Vendedora 3]=I15),--(TablaFloridaDic[Día]=$N$14)) + SUMPRODUCT((TablaGuemesDic[Vendedora 1]=I15)+(TablaGuemesDic[Vendedora 2]=I15)+(TablaGuemesDic[Vendedora 3]=I15),--(TablaGuemesDic[Día]=$N$14)) + SUMPRODUCT((TablaRecoletaDic[Vendedora 1]=I15)+(TablaRecoletaDic[Vendedora 2]=I15)+(TablaRecoletaDic[Vendedora 3]=I15),--(TablaRecoletaDic[Día]=$N$14)) -> 0 | L15: =J15+K15 -> 3
A16: ='Resumen zona'!A14 -> Candela G. | B16: =SUMPRODUCT((TablaFloridaNov[Vendedora 1]=A16)+(TablaFloridaNov[Vendedora 2]=A16)+(TablaFloridaNov[Vendedora 3]=A16),--(TablaFloridaNov[Día]<>$F$14)) + SUMPRODUCT((TablaGuemesNov[Vendedora 1]=A16)+(TablaGuemesNov[Vendedora 2]=A16)+(TablaGuemesNov[Vendedora 3]=A16),--(TablaGuemesNov[Día]<>$F$14)) + SUMPRODUCT((TablaRecoletaNov[Vendedora 1]=A16)+(TablaRecoletaNov[Vendedora 2]=A16)+(TablaRecoletaNov[Vendedora 3]=A16),--(TablaRecoletaNov[Día]<>$F$14)) -> 0 | C16: =SUMPRODUCT((TablaFloridaNov[Vendedora 1]=A16)+(TablaFloridaNov[Vendedora 2]=A16)+(TablaFloridaNov[Vendedora 3]=A16),--(TablaFloridaNov[Día]=$F$14)) + SUMPRODUCT((TablaGuemesNov[Vendedora 1]=A16)+(TablaGuemesNov[Vendedora 2]=A16)+(TablaGuemesNov[Vendedora 3]=A16),--(TablaGuemesNov[Día]=$F$14)) + SUMPRODUCT((TablaRecoletaNov[Vendedora 1]=A16)+(TablaRecoletaNov[Vendedora 2]=A16)+(TablaRecoletaNov[Vendedora 3]=A16),--(TablaRecoletaNov[Día]=$F$14)) -> 0 | D16: =SUM(B16:C16) -> 0 | I16: ='Resumen zona'!A33 -> Candela G. | J16: =SUMPRODUCT((TablaFloridaDic[Vendedora 1]=I16)+(TablaFloridaDic[Vendedora 2]=I16)+(TablaFloridaDic[Vendedora 3]=I16),--(TablaFloridaDic[Día]<>$N$14)) + SUMPRODUCT((TablaGuemesDic[Vendedora 1]=I16)+(TablaGuemesDic[Vendedora 2]=I16)+(TablaGuemesDic[Vendedora 3]=I16),--(TablaGuemesDic[Día]<>$N$14)) + SUMPRODUCT((TablaRecoletaDic[Vendedora 1]=I16)+(TablaRecoletaDic[Vendedora 2]=I16)+(TablaRecoletaDic[Vendedora 3]=I16),--(TablaRecoletaDic[Día]<>$N$14)) -> 4 | K16: =SUMPRODUCT((TablaFloridaDic[Vendedora 1]=I16)+(TablaFloridaDic[Vendedora 2]=I16)+(TablaFloridaDic[Vendedora 3]=I16),--(TablaFloridaDic[Día]=$N$14)) + SUMPRODUCT((TablaGuemesDic[Vendedora 1]=I16)+(TablaGuemesDic[Vendedora 2]=I16)+(TablaGuemesDic[Vendedora 3]=I16),--(TablaGuemesDic[Día]=$N$14)) + SUMPRODUCT((TablaRecoletaDic[Vendedora 1]=I16)+(TablaRecoletaDic[Vendedora 2]=I16)+(TablaRecoletaDic[Vendedora 3]=I16),--(TablaRecoletaDic[Día]=$N$14)) -> 0 | L16: =J16+K16 -> 4
A17: ='Resumen zona'!A15 -> Micaela | B17: =SUMPRODUCT((TablaFloridaNov[Vendedora 1]=A17)+(TablaFloridaNov[Vendedora 2]=A17)+(TablaFloridaNov[Vendedora 3]=A17),--(TablaFloridaNov[Día]<>$F$14)) + SUMPRODUCT((TablaGuemesNov[Vendedora 1]=A17)+(TablaGuemesNov[Vendedora 2]=A17)+(TablaGuemesNov[Vendedora 3]=A17),--(TablaGuemesNov[Día]<>$F$14)) + SUMPRODUCT((TablaRecoletaNov[Vendedora 1]=A17)+(TablaRecoletaNov[Vendedora 2]=A17)+(TablaRecoletaNov[Vendedora 3]=A17),--(TablaRecoletaNov[Día]<>$F$14)) -> 72 | C17: =SUMPRODUCT((TablaFloridaNov[Vendedora 1]=A17)+(TablaFloridaNov[Vendedora 2]=A17)+(TablaFloridaNov[Vendedora 3]=A17),--(TablaFloridaNov[Día]=$F$14)) + SUMPRODUCT((TablaGuemesNov[Vendedora 1]=A17)+(TablaGuemesNov[Vendedora 2]=A17)+(TablaGuemesNov[Vendedora 3]=A17),--(TablaGuemesNov[Día]=$F$14)) + SUMPRODUCT((TablaRecoletaNov[Vendedora 1]=A17)+(TablaRecoletaNov[Vendedora 2]=A17)+(TablaRecoletaNov[Vendedora 3]=A17),--(TablaRecoletaNov[Día]=$F$14)) -> 5 | D17: =SUM(B17:C17) -> 77 | I17: ='Resumen zona'!A34 -> Micaela | J17: =SUMPRODUCT((TablaFloridaDic[Vendedora 1]=I17)+(TablaFloridaDic[Vendedora 2]=I17)+(TablaFloridaDic[Vendedora 3]=I17),--(TablaFloridaDic[Día]<>$N$14)) + SUMPRODUCT((TablaGuemesDic[Vendedora 1]=I17)+(TablaGuemesDic[Vendedora 2]=I17)+(TablaGuemesDic[Vendedora 3]=I17),--(TablaGuemesDic[Día]<>$N$14)) + SUMPRODUCT((TablaRecoletaDic[Vendedora 1]=I17)+(TablaRecoletaDic[Vendedora 2]=I17)+(TablaRecoletaDic[Vendedora 3]=I17),--(TablaRecoletaDic[Día]<>$N$14)) -> 5 | K17: =SUMPRODUCT((TablaFloridaDic[Vendedora 1]=I17)+(TablaFloridaDic[Vendedora 2]=I17)+(TablaFloridaDic[Vendedora 3]=I17),--(TablaFloridaDic[Día]=$N$14)) + SUMPRODUCT((TablaGuemesDic[Vendedora 1]=I17)+(TablaGuemesDic[Vendedora 2]=I17)+(TablaGuemesDic[Vendedora 3]=I17),--(TablaGuemesDic[Día]=$N$14)) + SUMPRODUCT((TablaRecoletaDic[Vendedora 1]=I17)+(TablaRecoletaDic[Vendedora 2]=I17)+(TablaRecoletaDic[Vendedora 3]=I17),--(TablaRecoletaDic[Día]=$N$14)) -> 0 | L17: =J17+K17 -> 5
A18: ='Resumen zona'!A16 -> [Nueva] | B18: =SUMPRODUCT((TablaFloridaNov[Vendedora 1]=A18)+(TablaFloridaNov[Vendedora 2]=A18)+(TablaFloridaNov[Vendedora 3]=A18),--(TablaFloridaNov[Día]<>$F$14)) + SUMPRODUCT((TablaGuemesNov[Vendedora 1]=A18)+(TablaGuemesNov[Vendedora 2]=A18)+(TablaGuemesNov[Vendedora 3]=A18),--(TablaGuemesNov[Día]<>$F$14)) + SUMPRODUCT((TablaRecoletaNov[Vendedora 1]=A18)+(TablaRecoletaNov[Vendedora 2]=A18)+(TablaRecoletaNov[Vendedora 3]=A18),--(TablaRecoletaNov[Día]<>$F$14)) -> 0 | C18: =SUMPRODUCT((TablaFloridaNov[Vendedora 1]=A18)+(TablaFloridaNov[Vendedora 2]=A18)+(TablaFloridaNov[Vendedora 3]=A18),--(TablaFloridaNov[Día]=$F$14)) + SUMPRODUCT((TablaGuemesNov[Vendedora 1]=A18)+(TablaGuemesNov[Vendedora 2]=A18)+(TablaGuemesNov[Vendedora 3]=A18),--(TablaGuemesNov[Día]=$F$14)) + SUMPRODUCT((TablaRecoletaNov[Vendedora 1]=A18)+(TablaRecoletaNov[Vendedora 2]=A18)+(TablaRecoletaNov[Vendedora 3]=A18),--(TablaRecoletaNov[Día]=$F$14)) -> 0 | D18: =SUM(B18:C18) -> 0 | I18: ='Resumen zona'!A35 -> [Nueva] | J18: =SUMPRODUCT((TablaFloridaDic[Vendedora 1]=I18)+(TablaFloridaDic[Vendedora 2]=I18)+(TablaFloridaDic[Vendedora 3]=I18),--(TablaFloridaDic[Día]<>$N$14)) + SUMPRODUCT((TablaGuemesDic[Vendedora 1]=I18)+(TablaGuemesDic[Vendedora 2]=I18)+(TablaGuemesDic[Vendedora 3]=I18),--(TablaGuemesDic[Día]<>$N$14)) + SUMPRODUCT((TablaRecoletaDic[Vendedora 1]=I18)+(TablaRecoletaDic[Vendedora 2]=I18)+(TablaRecoletaDic[Vendedora 3]=I18),--(TablaRecoletaDic[Día]<>$N$14)) -> 0 | K18: =SUMPRODUCT((TablaFloridaDic[Vendedora 1]=I18)+(TablaFloridaDic[Vendedora 2]=I18)+(TablaFloridaDic[Vendedora 3]=I18),--(TablaFloridaDic[Día]=$N$14)) + SUMPRODUCT((TablaGuemesDic[Vendedora 1]=I18)+(TablaGuemesDic[Vendedora 2]=I18)+(TablaGuemesDic[Vendedora 3]=I18),--(TablaGuemesDic[Día]=$N$14)) + SUMPRODUCT((TablaRecoletaDic[Vendedora 1]=I18)+(TablaRecoletaDic[Vendedora 2]=I18)+(TablaRecoletaDic[Vendedora 3]=I18),--(TablaRecoletaDic[Día]=$N$14)) -> 0 | L18: =J18+K18 -> 0
A21: Día | B21: Día de semana | C21: Hora | D21: Vendedora 1 | E21: Vendedora 2 | F21: Vendedora 3 | G21: Estado de la hora | I21: Día | J21: Día de semana | K21: Hora | L21: Vendedora 1 | M21: Vendedora 2 | N21: Vendedora 3 | O21: Estado de la hora
A22: 45962 | B22: =TEXT(A22,"ddd") -> sáb | C22: 0.45833333 | D22: Maitena | E22: Mailén | G22: =IF(COUNTIF(D22:F22,"?*")=$D$4,"✅ CUBIERTO", IF(COUNTIF(D22:F22,"?*")>$D$4,"⚠ EXCESO",IF(COUNTIF(D22:F22,"?*")>0,"⚠ FALTANTE", "❌ SIN COMPLETAR"))) -> ✅ CUBIERTO | I22: 45992 | J22: =TEXT(I22,"ddd") -> lun | K22: 0.45833333 | L22: Maitena | M22: Candela G. | O22: =IF(COUNTIF(L22:N22,"?*")>=$L$4, "✅ CUBIERTO", IF(COUNTIF(L22:N22,"?*")>0, "⚠ FALTANTE", "❌ SIN COMPLETAR")) -> ✅ CUBIERTO
A23: 45962 | B23: =TEXT(A23,"ddd") -> sáb | C23: 0.5 | D23: Maitena | E23: Mailén | G23: =IF(COUNTIF(D23:F23,"?*")=$D$4,"✅ CUBIERTO", IF(COUNTIF(D23:F23,"?*")>$D$4,"⚠ EXCESO",IF(COUNTIF(D23:F23,"?*")>0,"⚠ FALTANTE", "❌ SIN COMPLETAR"))) -> ✅ CUBIERTO | I23: 45992 | J23: =TEXT(I23,"ddd") -> lun | K23: 0.5 | L23: Maitena | M23: Candela G. | O23: =IF(COUNTIF(L23:N23,"?*")>=$L$4, "✅ CUBIERTO", IF(COUNTIF(L23:N23,"?*")>0, "⚠ FALTANTE", "❌ SIN COMPLETAR")) -> ✅ CUBIERTO
A24: 45962 | B24: =TEXT(A24,"ddd") -> sáb | C24: 0.54166667 | D24: Maitena | E24: Mailén | G24: =IF(COUNTIF(D24:F24,"?*")=$D$4,"✅ CUBIERTO", IF(COUNTIF(D24:F24,"?*")>$D$4,"⚠ EXCESO",IF(COUNTIF(D24:F24,"?*")>0,"⚠ FALTANTE", "❌ SIN COMPLETAR"))) -> ✅ CUBIERTO | I24: 45992 | J24: =TEXT(I24,"ddd") -> lun | K24: 0.54166667 | L24: Maitena | M24: Candela G. | O24: =IF(COUNTIF(L24:N24,"?*")>=$L$4, "✅ CUBIERTO", IF(COUNTIF(L24:N24,"?*")>0, "⚠ FALTANTE", "❌ SIN COMPLETAR")) -> ✅ CUBIERTO
A25: 45962 | B25: =TEXT(A25,"ddd") -> sáb | C25: 0.58333333 | D25: Maitena | E25: Mailén | G25: =IF(COUNTIF(D25:F25,"?*")=$D$4,"✅ CUBIERTO", IF(COUNTIF(D25:F25,"?*")>$D$4,"⚠ EXCESO",IF(COUNTIF(D25:F25,"?*")>0,"⚠ FALTANTE", "❌ SIN COMPLETAR"))) -> ✅ CUBIERTO | I25: 45992 | J25: =TEXT(I25,"ddd") -> lun | K25: 0.58333333 | L25: Maitena | M25: Candela G. | O25: =IF(COUNTIF(L25:N25,"?*")>=$L$4, "✅ CUBIERTO", IF(COUNTIF(L25:N25,"?*")>0, "⚠ FALTANTE", "❌ SIN COMPLETAR")) -> ✅ CUBIERTO
A26: 45962 | B26: =TEXT(A26,"ddd") -> sáb | C26: 0.625 | D26: Maitena | E26: Mailén | G26: =IF(COUNTIF(D26:F26,"?*")=$D$4,"✅ CUBIERTO", IF(COUNTIF(D26:F26,"?*")>$D$4,"⚠ EXCESO",IF(COUNTIF(D26:F26,"?*")>0,"⚠ FALTANTE", "❌ SIN COMPLETAR"))) -> ✅ CUBIERTO | I26: 45992 | J26: =TEXT(I26,"ddd") -> lun | K26: 0.625 | L26: Micaela | M26: Rocío | O26: =IF(COUNTIF(L26:N26,"?*")>=$L$4, "✅ CUBIERTO", IF(COUNTIF(L26:N26,"?*")>0, "⚠ FALTANTE", "❌ SIN COMPLETAR")) -> ✅ CUBIERTO
A27: 45962 | B27: =TEXT(A27,"ddd") -> sáb | C27: 0.66666667 | D27: Maitena | E27: Mailén | G27: =IF(COUNTIF(D27:F27,"?*")=$D$4,"✅ CUBIERTO", IF(COUNTIF(D27:F27,"?*")>$D$4,"⚠ EXCESO",IF(COUNTIF(D27:F27,"?*")>0,"⚠ FALTANTE", "❌ SIN COMPLETAR"))) -> ✅ CUBIERTO | I27: 45992 | J27: =TEXT(I27,"ddd") -> lun | K27: 0.66666667 | L27: Micaela | M27: Rocío | O27: =IF(COUNTIF(L27:N27,"?*")>=$L$4, "✅ CUBIERTO", IF(COUNTIF(L27:N27,"?*")>0, "⚠ FALTANTE", "❌ SIN COMPLETAR")) -> ✅ CUBIERTO
A28: 45962 | B28: =TEXT(A28,"ddd") -> sáb | C28: 0.70833333 | D28: Maitena | E28: Mailén | G28: =IF(COUNTIF(D28:F28,"?*")=$D$4,"✅ CUBIERTO", IF(COUNTIF(D28:F28,"?*")>$D$4,"⚠ EXCESO",IF(COUNTIF(D28:F28,"?*")>0,"⚠ FALTANTE", "❌ SIN COMPLETAR"))) -> ✅ CUBIERTO | I28: 45992 | J28: =TEXT(I28,"ddd") -> lun | K28: 0.70833333 | L28: Micaela | M28: Rocío | O28: =IF(COUNTIF(L28:N28,"?*")>=$L$4, "✅ CUBIERTO", IF(COUNTIF(L28:N28,"?*")>0, "⚠ FALTANTE", "❌ SIN COMPLETAR")) -> ✅ CUBIERTO
A29: 45962 | B29: =TEXT(A29,"ddd") -> sáb | C29: 0.75 | D29: Maitena | E29: Mailén | G29: =IF(COUNTIF(D29:F29,"?*")=$D$4,"✅ CUBIERTO", IF(COUNTIF(D29:F29,"?*")>$D$4,"⚠ EXCESO",IF(COUNTIF(D29:F29,"?*")>0,"⚠ FALTANTE", "❌ SIN COMPLETAR"))) -> ✅ CUBIERTO | I29: 45992 | J29: =TEXT(I29,"ddd") -> lun | K29: 0.75 | L29: Micaela | M29: Rocío | O29: =IF(COUNTIF(L29:N29,"?*")>=$L$4, "✅ CUBIERTO", IF(COUNTIF(L29:N29,"?*")>0, "⚠ FALTANTE", "❌ SIN COMPLETAR")) -> ✅ CUBIERTO
A30: 45962 | B30: =TEXT(A30,"ddd") -> sáb | C30: 0.79166667 | D30: Maitena | E30: Mailén | G30: =IF(COUNTIF(D30:F30,"?*")=$D$4,"✅ CUBIERTO", IF(COUNTIF(D30:F30,"?*")>$D$4,"⚠ EXCESO",IF(COUNTIF(D30:F30,"?*")>0,"⚠ FALTANTE", "❌ SIN COMPLETAR"))) -> ✅ CUBIERTO | I30: 45992 | J30: =TEXT(I30,"ddd") -> lun | K30: 0.79166667 | L30: Micaela | M30: Rocío | O30: =IF(COUNTIF(L30:N30,"?*")>=$L$4, "✅ CUBIERTO", IF(COUNTIF(L30:N30,"?*")>0, "⚠ FALTANTE", "❌ SIN COMPLETAR")) -> ✅ CUBIERTO
A31: 45963 | B31: =TEXT(A31,"ddd") -> dom | C31: 0.45833333 | D31: Maitena | E31: Mailén | G31: =IF(COUNTIF(D31:F31,"?*")=$D$4,"✅ CUBIERTO", IF(COUNTIF(D31:F31,"?*")>$D$4,"⚠ EXCESO",IF(COUNTIF(D31:F31,"?*")>0,"⚠ FALTANTE", "❌ SIN COMPLETAR"))) -> ✅ CUBIERTO | I31: 45993 | J31: =TEXT(I31,"ddd") -> mar | K31: 0.45833333 | L31: Maitena | M31: Maitena | O31: =IF(COUNTIF(L31:N31,"?*")>=$L$4, "✅ CUBIERTO", IF(COUNTIF(L31:N31,"?*")>0, "⚠ FALTANTE", "❌ SIN COMPLETAR")) -> ✅ CUBIERTO
A32: 45963 | B32: =TEXT(A32,"ddd") -> dom | C32: 0.5 | D32: Maitena | E32: Mailén | G32: =IF(COUNTIF(D32:F32,"?*")=$D$4,"✅ CUBIERTO", IF(COUNTIF(D32:F32,"?*")>$D$4,"⚠ EXCESO",IF(COUNTIF(D32:F32,"?*")>0,"⚠ FALTANTE", "❌ SIN COMPLETAR"))) -> ✅ CUBIERTO | I32: 45993 | J32: =TEXT(I32,"ddd") -> mar | K32: 0.5 | L32: Maitena | M32: Maitena | O32: =IF(COUNTIF(L32:N32,"?*")>=$L$4, "✅ CUBIERTO", IF(COUNTIF(L32:N32,"?*")>0, "⚠ FALTANTE", "❌ SIN COMPLETAR")) -> ✅ CUBIERTO
A33: 45963 | B33: =TEXT(A33,"ddd") -> dom | C33: 0.54166667 | D33: Maitena | E33: Mailén | G33: =IF(COUNTIF(D33:F33,"?*")=$D$4,"✅ CUBIERTO", IF(COUNTIF(D33:F33,"?*")>$D$4,"⚠ EXCESO",IF(COUNTIF(D33:F33,"?*")>0,"⚠ FALTANTE", "❌ SIN COMPLETAR"))) -> ✅ CUBIERTO | I33: 45993 | J33: =TEXT(I33,"ddd") -> mar | K33: 0.54166667 | L33: Maitena | M33: Maitena | O33: =IF(COUNTIF(L33:N33,"?*")>=$L$4, "✅ CUBIERTO", IF(COUNTIF(L33:N33,"?*")>0, "⚠ FALTANTE", "❌ SIN COMPLETAR")) -> ✅ CUBIERTO
... A237: 45985 | B237: =TEXT(A237,"ddd") -> lun | C237: 0.79166667 | D237: Candela | E237: Micaela | G237: =IF(COUNTIF(D237:F237,"?*")=$D$4,"✅ CUBIERTO", IF(COUNTIF(D237:F237,"?*")>$D$4,"⚠ EXCESO",IF(COUNTIF(D237:F237,"?*")>0,"⚠ FALTANTE", "❌ SIN COMPLETAR"))) -> ✅ CUBIERTO | I237: 46015 | J237: =TEXT(I237,"ddd") -> mié | K237: 0.79166667 | L237: Maitena | M237: Maitena | O237: =IF(COUNTIF(L237:N237,"?*")>=$L$4, "✅ CUBIERTO", IF(COUNTIF(L237:N237,"?*")>0, "⚠ FALTANTE", "❌ SIN COMPLETAR")) -> ✅ CUBIERTO
A238: 45986 | B238: =TEXT(A238,"ddd") -> mar | C238: 0.45833333 | D238: Maitena | E238: Maitena | G238: =IF(COUNTIF(D238:F238,"?*")=$D$4,"✅ CUBIERTO", IF(COUNTIF(D238:F238,"?*")>$D$4,"⚠ EXCESO",IF(COUNTIF(D238:F238,"?*")>0,"⚠ FALTANTE", "❌ SIN COMPLETAR"))) -> ✅ CUBIERTO | I238: 46016 | J238: =TEXT(I238,"ddd") -> jue | K238: 0.45833333 | O238: FERIADO
A239: 45986 | B239: =TEXT(A239,"ddd") -> mar | C239: 0.5 | D239: Maitena | E239: Maitena | G239: =IF(COUNTIF(D239:F239,"?*")=$D$4,"✅ CUBIERTO", IF(COUNTIF(D239:F239,"?*")>$D$4,"⚠ EXCESO",IF(COUNTIF(D239:F239,"?*")>0,"⚠ FALTANTE", "❌ SIN COMPLETAR"))) -> ✅ CUBIERTO | I239: 46016 | J239: =TEXT(I239,"ddd") -> jue | K239: 0.5 | O239: FERIADO
A240: 45986 | B240: =TEXT(A240,"ddd") -> mar | C240: 0.54166667 | D240: Maitena | E240: Maitena | G240: =IF(COUNTIF(D240:F240,"?*")=$D$4,"✅ CUBIERTO", IF(COUNTIF(D240:F240,"?*")>$D$4,"⚠ EXCESO",IF(COUNTIF(D240:F240,"?*")>0,"⚠ FALTANTE", "❌ SIN COMPLETAR"))) -> ✅ CUBIERTO | I240: 46016 | J240: =TEXT(I240,"ddd") -> jue | K240: 0.54166667 | O240: FERIADO
A241: 45986 | B241: =TEXT(A241,"ddd") -> mar | C241: 0.58333333 | D241: Maitena | E241: Maitena | G241: =IF(COUNTIF(D241:F241,"?*")=$D$4,"✅ CUBIERTO", IF(COUNTIF(D241:F241,"?*")>$D$4,"⚠ EXCESO",IF(COUNTIF(D241:F241,"?*")>0,"⚠ FALTANTE", "❌ SIN COMPLETAR"))) -> ✅ CUBIERTO | I241: 46016 | J241: =TEXT(I241,"ddd") -> jue | K241: 0.58333333 | O241: FERIADO
A242: 45986 | B242: =TEXT(A242,"ddd") -> mar | C242: 0.625 | D242: Maitena | E242: Maitena | G242: =IF(COUNTIF(D242:F242,"?*")=$D$4,"✅ CUBIERTO", IF(COUNTIF(D242:F242,"?*")>$D$4,"⚠ EXCESO",IF(COUNTIF(D242:F242,"?*")>0,"⚠ FALTANTE", "❌ SIN COMPLETAR"))) -> ✅ CUBIERTO | I242: 46016 | J242: =TEXT(I242,"ddd") -> jue | K242: 0.625 | O242: FERIADO
A243: 45986 | B243: =TEXT(A243,"ddd") -> mar | C243: 0.66666667 | D243: Maitena | E243: Maitena | G243: =IF(COUNTIF(D243:F243,"?*")=$D$4,"✅ CUBIERTO", IF(COUNTIF(D243:F243,"?*")>$D$4,"⚠ EXCESO",IF(COUNTIF(D243:F243,"?*")>0,"⚠ FALTANTE", "❌ SIN COMPLETAR"))) -> ✅ CUBIERTO | I243: 46016 | J243: =TEXT(I243,"ddd") -> jue | K243: 0.66666667 | O243: FERIADO
A244: 45986 | B244: =TEXT(A244,"ddd") -> mar | C244: 0.70833333 | D244: Maitena | E244: Maitena | G244: =IF(COUNTIF(D244:F244,"?*")=$D$4,"✅ CUBIERTO", IF(COUNTIF(D244:F244,"?*")>$D$4,"⚠ EXCESO",IF(COUNTIF(D244:F244,"?*")>0,"⚠ FALTANTE", "❌ SIN COMPLETAR"))) -> ✅ CUBIERTO | I244: 46016 | J244: =TEXT(I244,"ddd") -> jue | K244: 0.70833333 | O244: FERIADO
A245: 45986 | B245: =TEXT(A245,"ddd") -> mar | C245: 0.75 | D245: Maitena | E245: Maitena | G245: =IF(COUNTIF(D245:F245,"?*")=$D$4,"✅ CUBIERTO", IF(COUNTIF(D245:F245,"?*")>$D$4,"⚠ EXCESO",IF(COUNTIF(D245:F245,"?*")>0,"⚠ FALTANTE", "❌ SIN COMPLETAR"))) -> ✅ CUBIERTO | I245: 46016 | J245: =TEXT(I245,"ddd") -> jue | K245: 0.75 | O245: FERIADO
A246: 45986 | B246: =TEXT(A246,"ddd") -> mar | C246: 0.79166667 | D246: Maitena | E246: Maitena | G246: =IF(COUNTIF(D246:F246,"?*")=$D$4,"✅ CUBIERTO", IF(COUNTIF(D246:F246,"?*")>$D$4,"⚠ EXCESO",IF(COUNTIF(D246:F246,"?*")>0,"⚠ FALTANTE", "❌ SIN COMPLETAR"))) -> ✅ CUBIERTO | I246: 46016 | J246: =TEXT(I246,"ddd") -> jue | K246: 0.79166667 | O246: FERIADO
A247: 45987 | B247: =TEXT(A247,"ddd") -> mié | C247: 0.45833333 | D247: Maitena | E247: Maitena | G247: =IF(COUNTIF(D247:F247,"?*")=$D$4,"✅ CUBIERTO", IF(COUNTIF(D247:F247,"?*")>$D$4,"⚠ EXCESO",IF(COUNTIF(D247:F247,"?*")>0,"⚠ FALTANTE", "❌ SIN COMPLETAR"))) -> ✅ CUBIERTO | I247: 46017 | J247: =TEXT(I247,"ddd") -> vie | K247: 0.45833333 | L247: Maitena | M247: Maitena | O247: =IF(COUNTIF(L247:N247,"?*")>=$L$4, "✅ CUBIERTO", IF(COUNTIF(L247:N247,"?*")>0, "⚠ FALTANTE", "❌ SIN COMPLETAR")) -> ✅ CUBIERTO
...

Sheet Guemes
A1: GUEMES | I1: GUEMES
A2: NOVIEMBRE | I2: DICIEMBRE
A4: Personal Mínimo Requerido por turno: | D4: 1 | I4: Personal Mínimo Requerido por turno: | L4: 1
A6: Resumen de horas por vendedora | I6: Resumen de horas por vendedora
A7: Vendedoras | B7: Horas normales trabajadas | C7: Horas feriados trabajados | D7: Horas totales trabajadas | G7: HORAS EN GÜEMES | I7: Vendedoras | J7: Horas trabajadas | K7: Horas feriados no trabajados | L7: Horas totales | M7: Horas máximas | O7: HORAS
A8: ='Resumen zona'!A6 -> Sofía | B8: =SUMPRODUCT((TablaFloridaNov[Vendedora 1]=A8)+(TablaFloridaNov[Vendedora 2]=A8)+(TablaFloridaNov[Vendedora 3]=A8),--(TablaFloridaNov[Día]<>$G$14)) + SUMPRODUCT((TablaGuemesNov[Vendedora 1]=A8)+(TablaGuemesNov[Vendedora 2]=A8)+(TablaGuemesNov[Vendedora 3]=A8),--(TablaGuemesNov[Día]<>$G$14)) + SUMPRODUCT((TablaRecoletaNov[Vendedora 1]=A8)+(TablaRecoletaNov[Vendedora 2]=A8)+(TablaRecoletaNov[Vendedora 3]=A8),--(TablaRecoletaNov[Día]<>$G$14)) -> 143 | C8: =SUMPRODUCT((TablaFloridaNov[Vendedora 1]=A8)+(TablaFloridaNov[Vendedora 2]=A8)+(TablaFloridaNov[Vendedora 3]=A8),--(TablaFloridaNov[Día]=$G$14)) + SUMPRODUCT((TablaGuemesNov[Vendedora 1]=A8)+(TablaGuemesNov[Vendedora 2]=A8)+(TablaGuemesNov[Vendedora 3]=A8),--(TablaGuemesNov[Día]=$G$14)) + SUMPRODUCT((TablaRecoletaNov[Vendedora 1]=A8)+(TablaRecoletaNov[Vendedora 2]=A8)+(TablaRecoletaNov[Vendedora 3]=A8),--(TablaRecoletaNov[Día]=$G$14)) -> 9 | D8: =SUM(B8:C8) -> 152 | G8: Máximas | I8: ='Resumen zona'!A25 -> Sofía | J8: =COUNTIF(TablaGuemesDic[[Vendedora 1]:[Vendedora 3]],I8) -> 9 | L8: =J8+K8 -> 9 | M8: 132 | O8: Máximas
A9: ='Resumen zona'!A7 -> Giselle | B9: =SUMPRODUCT((TablaFloridaNov[Vendedora 1]=A9)+(TablaFloridaNov[Vendedora 2]=A9)+(TablaFloridaNov[Vendedora 3]=A9),--(TablaFloridaNov[Día]<>$G$14)) + SUMPRODUCT((TablaGuemesNov[Vendedora 1]=A9)+(TablaGuemesNov[Vendedora 2]=A9)+(TablaGuemesNov[Vendedora 3]=A9),--(TablaGuemesNov[Día]<>$G$14)) + SUMPRODUCT((TablaRecoletaNov[Vendedora 1]=A9)+(TablaRecoletaNov[Vendedora 2]=A9)+(TablaRecoletaNov[Vendedora 3]=A9),--(TablaRecoletaNov[Día]<>$G$14)) -> 0 | C9: =SUMPRODUCT((TablaFloridaNov[Vendedora 1]=A9)+(TablaFloridaNov[Vendedora 2]=A9)+(TablaFloridaNov[Vendedora 3]=A9),--(TablaFloridaNov[Día]=$G$14)) + SUMPRODUCT((TablaGuemesNov[Vendedora 1]=A9)+(TablaGuemesNov[Vendedora 2]=A9)+(TablaGuemesNov[Vendedora 3]=A9),--(TablaGuemesNov[Día]=$G$14)) + SUMPRODUCT((TablaRecoletaNov[Vendedora 1]=A9)+(TablaRecoletaNov[Vendedora 2]=A9)+(TablaRecoletaNov[Vendedora 3]=A9),--(TablaRecoletaNov[Día]=$G$14)) -> 0 | D9: =SUM(B9:C9) -> 0 | G9: ='Resumen zona'!M6 -> 300 | I9: ='Resumen zona'!A26 -> Giselle | J9: =COUNTIF(TablaGuemesDic[[Vendedora 1]:[Vendedora 3]],I9) -> 0 | L9: =J9+K9 -> 0 | M9: 132 | O9: 600
A10: ='Resumen zona'!A8 -> Maitena | B10: =SUMPRODUCT((TablaFloridaNov[Vendedora 1]=A10)+(TablaFloridaNov[Vendedora 2]=A10)+(TablaFloridaNov[Vendedora 3]=A10),--(TablaFloridaNov[Día]<>$G$14)) + SUMPRODUCT((TablaGuemesNov[Vendedora 1]=A10)+(TablaGuemesNov[Vendedora 2]=A10)+(TablaGuemesNov[Vendedora 3]=A10),--(TablaGuemesNov[Día]<>$G$14)) + SUMPRODUCT((TablaRecoletaNov[Vendedora 1]=A10)+(TablaRecoletaNov[Vendedora 2]=A10)+(TablaRecoletaNov[Vendedora 3]=A10),--(TablaRecoletaNov[Día]<>$G$14)) -> 504 | C10: =SUMPRODUCT((TablaFloridaNov[Vendedora 1]=A10)+(TablaFloridaNov[Vendedora 2]=A10)+(TablaFloridaNov[Vendedora 3]=A10),--(TablaFloridaNov[Día]=$G$14)) + SUMPRODUCT((TablaGuemesNov[Vendedora 1]=A10)+(TablaGuemesNov[Vendedora 2]=A10)+(TablaGuemesNov[Vendedora 3]=A10),--(TablaGuemesNov[Día]=$G$14)) + SUMPRODUCT((TablaRecoletaNov[Vendedora 1]=A10)+(TablaRecoletaNov[Vendedora 2]=A10)+(TablaRecoletaNov[Vendedora 3]=A10),--(TablaRecoletaNov[Día]=$G$14)) -> 8 | D10: =SUM(B10:C10) -> 512 | G10: Ocupadas | I10: ='Resumen zona'!A27 -> Maitena | J10: =COUNTIF(TablaGuemesDic[[Vendedora 1]:[Vendedora 3]],I10) -> 204 | K10: 4 | L10: =J10+K10 -> 208 | M10: 132 | O10: Ocupadas
