Workbook

Sheet RESERVA
AP1: Cotizaciones | AU1: De | AV1: Hasta
A2: Empresa: EL LUCERO CUERO S.A. | AU2: ='LUCERO RECOLETA'!AX2 | AV2: ='LUCERO RECOLETA'!AY2 | AW2: ='LUCERO RECOLETA'!AZ2 | AX2: ='LUCERO RECOLETA'!BA2 | AY2: ='LUCERO RECOLETA'!BB2 | AZ2: ='LUCERO RECOLETA'!BC2 | BA2: ='LUCERO RECOLETA'!BD2 | BB2: ='LUCERO RECOLETA'!BE2 | ... BG2: ='LUCERO RECOLETA'!BJ2
A3: Sucursal: LUCERO FLORIDA - Florida 823 CABA - Caja 1 - CP C1005AAQ | AP3: ='LUCERO RECOLETA'!AS3 | AU3: ='LUCERO RECOLETA'!AX3 | AV3: ='LUCERO RECOLETA'!AY3 | AW3: ='LUCERO RECOLETA'!AZ3 | AX3: ='LUCERO RECOLETA'!BA3 | AY3: ='LUCERO RECOLETA'!BB3 | AZ3: ='LUCERO RECOLETA'!BC3 | BA3: ='LUCERO RECOLETA'!BD3 | BB3: ='LUCERO RECOLETA'!BE3 | ... BG3: ='LUCERO RECOLETA'!BJ3
AP4: ='LUCERO RECOLETA'!AS4 | AU4: ='LUCERO RECOLETA'!AX4 | AV4: ='LUCERO RECOLETA'!AY4 | AW4: ='LUCERO RECOLETA'!AZ4 | AX4: ='LUCERO RECOLETA'!BA4 | AY4: ='LUCERO RECOLETA'!BB4 | AZ4: ='LUCERO RECOLETA'!BC4 | BA4: ='LUCERO RECOLETA'!BD4 | BB4: ='LUCERO RECOLETA'!BE4 | ... BG4: ='LUCERO RECOLETA'!BJ4
A5: INFORME DE VENTAS MENSUAL | E5: pv 26 | AP5: ='LUCERO RECOLETA'!AS5 | AU5: ='LUCERO RECOLETA'!AX5 | AV5: ='LUCERO RECOLETA'!AY5 | AW5: ='LUCERO RECOLETA'!AZ5 | AX5: ='LUCERO RECOLETA'!BA5 | AY5: ='LUCERO RECOLETA'!BB5 | AZ5: ='LUCERO RECOLETA'!BC5 | BA5: ='LUCERO RECOLETA'!BD5 | BB5: ='LUCERO RECOLETA'!BE5 | ... BF5: ='LUCERO RECOLETA'!BI5
AU6: ='LUCERO RECOLETA'!AX6 | AY6: 1450
A7: ='LUCERO RECOLETA'!A7 -> ABRIL | B7: Detalle de TICKETS | L7: Detalle de FACTURAS B | Q7: Detalle de FACTURAS A | V7: Detalle de NOTAS DE CREDITO | AA7: VENTA FINAL | AB7: INFORME SEGÚN MAIL | AM7: DIFERENCIA | AN7: CONTROL DE CIERRE DE CAJA
A8: Fecha | B8: Informe de cierre | C8: N° Tickets | D8: Desde | E8: Hasta | F8: Anulados y/o cancelados | G8: Cant. de art. | H8: Imp. de VTA gravado | I8: IVA 21% | J8: Otros imp. | K8: Imp. de VTA total | L8: Desde | M8: Hasta | N8: Imp.de VTA gravado | O8: IVA 21% | P8: Imp.de vta total | Q8: Desde | R8: Hasta | S8: Imp.de VTA gravado | T8: IVA 21% | U8: Imp.de vta total | V8: Desde | W8: Hasta | X8: Imp.de VTA gravado | Y8: IVA 21% | Z8: Imp.de vta total | AB8: VENTA TOTAL | AC8: EFECTIVO $ | AD8: TARJETAS | AE8: MERCADO PAGO | AF8: Real | AH8: Dolar | AJ8: EURO | AL8: TOTAL DE INGRESO | AN8: $ Efectivo | AO8: $ Deposito / PIX | AP8: TARJ SEGUN PLANILLA | AQ8: TOTAL TARJETAS OK | AR8: TARJETA DEBITO | AS8: TARJETA CREDITO | AT8: Mercado Pago / TF | AU8: Gastos | AV8: Real | AX8: Dólar 100 | AZ8: Dólar 50 | BB8: Dólar 10. 20 | BD8: Dólar 1. 5 | BF8: EURO | BH8: Total | BI8: CIERRE | BJ8: DIFERENCIA | BL8: =AN8 -> $ Efectivo | BM8: =AR8 -> TARJETA DEBITO | BN8: =AS8 -> TARJETA CREDITO | BO8: =AT8 -> Mercado Pago / TF | BP8: =AV8 -> Real | BQ8: Dólar | BR8: Euro | BS8: Total | BT8: Venta x día
A9: ='LUCERO RECOLETA'!A9 -> 46143 | B9: 940 | D9: 9715 | E9: =IF(C9="","",C9+D9-1) | I9: =H9*21% -> 0 | K9: =H9+I9+J9 -> 0 | O9: =N9*21% -> 0 | P9: =+N9+O9 -> 0 | T9: =S9*21% -> 0 | U9: =SUM(S9:T9) -> 0 | Y9: =X9*21% -> 0 | Z9: =SUM(X9:Y9) -> 0 | AA9: =+K9+P9+U9-Z9 -> 0 | AG9: =AF9*220 -> 0 | AI9: =AH9*1200 -> 0 | AK9: =AJ9*1200 -> 0 | AL9: =AC9+AD9+AE9+AG9+AI9+AK9 -> 0 | AM9: =SUM(AL9-BH9) -> 0 | AP9: =AD9 | AQ9: =SUM(AR9:AS9) -> 0 | AW9: =AV9*AW$2 -> 0 | AY9: =AX9*AY$2 -> 0 | BA9: =AZ9*BA$2 -> 0 | BC9: =BB9*BC$2 -> 0 | BE9: =BD9*BE$2 -> 0 | BG9: =BF9*BG$2 -> 0 | BH9: =+AN9+AO9+AQ9+AT9+AU9+AW9+AY9+BA9+BC9+BE8+BG9 -> 0 | BI9: =AA9 -> 0 | BJ9: =SUM(BH9-BI9) -> 0 | BL9: =IF(AN9+AO9=0,0,(AN9+AO9)/AA9) -> 0 | BM9: =IF(AR9=0,0,AR9/AA9) -> 0 | BN9: =IF(AS9=0,0,AS9/AA9) -> 0 | BO9: =IF(AT9=0,0,AT9/AA9) -> 0 | BP9: =IF(AW9=0,0,AW9/AA9) -> 0 | BQ9: =IF(AY9+BA9+BC9=0,0,(AY9+BA9+BC9)/AA9) -> 0 | BR9: =IF(BG9=0,0,BG9/AA9) -> 0 | BS9: =SUM(BL9:BR9) -> 0 | BT9: =AA9/$AA$41 -> #DIV/0!
A10: ='LUCERO RECOLETA'!A10 -> 46144 | B10: =B9+1 -> 941 | D10: =E9+1 -> 1 | E10: =IF(C10="","",C10+D10-1) | I10: =H10*21% -> 0 | K10: =H10+I10+J10 -> 0 | O10: =N10*21% -> 0 | P10: =+N10+O10 -> 0 | T10: =S10*21% -> 0 | U10: =SUM(S10:T10) -> 0 | Y10: =X10*21% -> 0 | Z10: =SUM(X10:Y10) -> 0 | AA10: =+K10+P10+U10-Z10 -> 0 | AG10: =AF10*220 -> 0 | AI10: =AH10*1200 -> 0 | AK10: =AJ10*1200 -> 0 | AL10: =AC10+AD10+AE10+AG10+AI10+AK10 -> 0 | AM10: =SUM(AL10-BH10) -> 0 | AP10: =AD10 | AQ10: =SUM(AR10:AS10) -> 0 | AW10: =AV10*AW$2 -> 0 | AY10: =AX10*AY$2 -> 0 | BA10: =AZ10*BA$2 -> 0 | BC10: =BB10*BC$2 -> 0 | BE10: =BD10*BE$2 -> 0 | BG10: =BF10*BG$2 -> 0 | BH10: =+AN10+AO10+AQ10+AT10+AU10+AW10+AY10+BA10+BC10+BE9+BG10 -> 0 | BI10: =AA10 -> 0 | BJ10: =SUM(BH10-BI10) -> 0 | BL10: =IF(AN10+AO10=0,0,(AN10+AO10)/AA10) -> 0 | BM10: =IF(AR10=0,0,AR10/AA10) -> 0 | BN10: =IF(AS10=0,0,AS10/AA10) -> 0 | BO10: =IF(AT10=0,0,AT10/AA10) -> 0 | BP10: =IF(AW10=0,0,AW10/AA10) -> 0 | BQ10: =IF(AY10+BA10+BC10=0,0,(AY10+BA10+BC10)/AA10) -> 0 | BR10: =IF(BG10=0,0,BG10/AA10) -> 0 | BS10: =SUM(BL10:BR10) -> 0 | BT10: =AA10/$AA$41 -> #DIV/0!
A11: ='LUCERO RECOLETA'!A11 -> 46145 | B11: =B10+1 -> 942 | D11: =E10+1 -> 1 | E11: =IF(C11="","",C11+D11-1) | I11: =H11*21% -> 0 | K11: =H11+I11+J11 -> 0 | O11: =N11*21% -> 0 | P11: =+N11+O11 -> 0 | T11: =S11*21% -> 0 | U11: =SUM(S11:T11) -> 0 | Y11: =X11*21% -> 0 | Z11: =SUM(X11:Y11) -> 0 | AA11: =+K11+P11+U11-Z11 -> 0 | AG11: =AF11*220 -> 0 | AI11: =AH11*1200 -> 0 | AK11: =AJ11*1200 -> 0 | AL11: =AC11+AD11+AE11+AG11+AI11+AK11 -> 0 | AM11: =SUM(AL11-BH11) -> 0 | AP11: =AD11 | AQ11: =AR11+AS11 -> 0 | AW11: =AV11*AW$3 -> 0 | AY11: =AX11*AY$2 -> 0 | BA11: =AZ11*BA$2 -> 0 | BC11: =BB11*BC$2 -> 0 | BE11: =BD11*BE$2 -> 0 | BG11: =BF11*BG$2 -> 0 | BH11: =+AN11+AO11+AQ11+AT11+AU11+AW11+AY11+BA11+BC11+BE11+BG11 -> 0 | BI11: =AA11 -> 0 | BJ11: =SUM(BH11-BI11) -> 0 | BL11: =IF(AN11+AO11=0,0,(AN11+AO11)/AA11) -> 0 | BM11: =IF(AR11=0,0,AR11/AA11) -> 0 | BN11: =IF(AS11=0,0,AS11/AA11) -> 0 | BO11: =IF(AT11=0,0,AT11/AA11) -> 0 | BP11: =IF(AW11=0,0,AW11/AA11) -> 0 | BQ11: =IF(AY11+BA11+BC11=0,0,(AY11+BA11+BC11)/AA11) -> 0 | BR11: =IF(BG11=0,0,BG11/AA11) -> 0 | BS11: =SUM(BL11:BR11) -> 0 | BT11: =AA11/$AA$41 -> #DIV/0!
A12: ='LUCERO RECOLETA'!A12 -> 46146 | B12: =B11+1 -> 943 | D12: =E11+1 -> 1 | E12: =IF(C12="","",C12+D12-1) | I12: =H12*21% -> 0 | K12: =H12+I12+J12 -> 0 | O12: =N12*21% -> 0 | P12: =+N12+O12 -> 0 | T12: =S12*21% -> 0 | U12: =SUM(S12:T12) -> 0 | Y12: =X12*21% -> 0 | Z12: =SUM(X12:Y12) -> 0 | AA12: =+K12+P12+U12-Z12 -> 0 | AG12: =AF12*220 -> 0 | AI12: =AH12*1200 -> 0 | AK12: =AJ12*1200 -> 0 | AL12: =AC12+AD12+AE12+AG12+AI12+AK12 -> 0 | AM12: =SUM(AL12-BH12) -> 0 | AP12: =AD12 | AQ12: =SUM(AR12:AS12) -> 0 | AW12: =AV12*AW$3 -> 0 | AY12: =AX12*AY$2 -> 0 | BA12: =AZ12*BA$2 -> 0 | BC12: =BB12*BC$2 -> 0 | BE12: =BD12*BE$2 -> 0 | BG12: =BF12*BG$2 -> 0 | BH12: =+AN12+AO12+AQ12+AT12+AU12+AW12+AY12+BA12+BC12+BE12+BG12 -> 0 | BI12: =AA12 -> 0 | BJ12: =SUM(BH12-BI12) -> 0 | BL12: =IF(AN12+AO12=0,0,(AN12+AO12)/AA12) -> 0 | BM12: =IF(AR12=0,0,AR12/AA12) -> 0 | BN12: =IF(AS12=0,0,AS12/AA12) -> 0 | BO12: =IF(AT12=0,0,AT12/AA12) -> 0 | BP12: =IF(AW12=0,0,AW12/AA12) -> 0 | BQ12: =IF(AY12+BA12+BC12=0,0,(AY12+BA12+BC12)/AA12) -> 0 | BR12: =IF(BG12=0,0,BG12/AA12) -> 0 | BS12: =SUM(BL12:BR12) -> 0 | BT12: =AA12/$AA$41 -> #DIV/0!
A13: ='LUCERO RECOLETA'!A13 -> 46147 | B13: =B12+1 -> 944 | D13: =E12+1 -> 1 | E13: =IF(C13="","",C13+D13-1) | I13: =H13*21% -> 0 | K13: =H13+I13+J13 -> 0 | O13: =N13*21% -> 0 | P13: =+N13+O13 -> 0 | T13: =S13*21% -> 0 | U13: =SUM(S13:T13) -> 0 | Y13: =X13*21% -> 0 | Z13: =SUM(X13:Y13) -> 0 | AA13: =+K13+P13+U13-Z13 -> 0 | AG13: =AF13*220 -> 0 | AI13: =AH13*1200 -> 0 | AK13: =AJ13*1200 -> 0 | AL13: =AC13+AD13+AE13+AG13+AI13+AK13 -> 0 | AM13: =SUM(AL13-BH13) -> 0 | AP13: =AD13 | AQ13: =SUM(AR13:AS13) -> 0 | AW13: =AV13*AW$3 -> 0 | AY13: =AX13*AY$2 -> 0 | BA13: =AZ13*BA$2 -> 0 | BC13: =BB13*BC$2 -> 0 | BE13: =BD13*BE$2 -> 0 | BG13: =BF13*BG$2 -> 0 | BH13: =+AN13+AO13+AQ13+AT13+AU13+AW13+AY13+BA13+BC13+BE13+BG13 -> 0 | BI13: =AA13 -> 0 | BJ13: =SUM(BH13-BI13) -> 0 | BL13: =IF(AN13+AO13=0,0,(AN13+AO13)/AA13) -> 0 | BM13: =IF(AR13=0,0,AR13/AA13) -> 0 | BN13: =IF(AS13=0,0,AS13/AA13) -> 0 | BO13: =IF(AT13=0,0,AT13/AA13) -> 0 | BP13: =IF(AW13=0,0,AW13/AA13) -> 0 | BQ13: =IF(AY13+BA13+BC13=0,0,(AY13+BA13+BC13)/AA13) -> 0 | BR13: =IF(BG13=0,0,BG13/AA13) -> 0 | BS13: =SUM(BL13:BR13) -> 0 | BT13: =AA13/$AA$41 -> #DIV/0!
A14: ='LUCERO RECOLETA'!A14 -> 46148 | B14: =B13+1 -> 945 | D14: =E13+1 -> 1 | E14: =IF(C14="","",C14+D14-1) | I14: =H14*21% -> 0 | K14: =H14+I14+J14 -> 0 | O14: =N14*21% -> 0 | P14: =+N14+O14 -> 0 | T14: =S14*21% -> 0 | U14: =SUM(S14:T14) -> 0 | Y14: =X14*21% -> 0 | Z14: =SUM(X14:Y14) -> 0 | AA14: =+K14+P14+U14-Z14 -> 0 | AG14: =AF14*220 -> 0 | AI14: =AH14*1200 -> 0 | AK14: =AJ14*1200 -> 0 | AL14: =AC14+AD14+AE14+AG14+AI14+AK14 -> 0 | AM14: =SUM(AL14-BH14) -> 0 | AP14: =AD14 | AQ14: =SUM(AR14:AS14) -> 0 | AW14: =AV14*AW$3 -> 0 | AY14: =AX14*AY$2 -> 0 | BA14: =AZ14*BA$2 -> 0 | BC14: =BB14*BC$2 -> 0 | BE14: =BD14*BE$2 -> 0 | BG14: =BF14*BG$2 -> 0 | BH14: =+AN14+AO14+AQ14+AT14+AU14+AW14+AY14+BA14+BC14+BE14+BG14 -> 0 | BI14: =AA14 -> 0 | BJ14: =SUM(BH14-BI14) -> 0 | BL14: =IF(AN14+AO14=0,0,(AN14+AO14)/AA14) -> 0 | BM14: =IF(AR14=0,0,AR14/AA14) -> 0 | BN14: =IF(AS14=0,0,AS14/AA14) -> 0 | BO14: =IF(AT14=0,0,AT14/AA14) -> 0 | BP14: =IF(AW14=0,0,AW14/AA14) -> 0 | BQ14: =IF(AY14+BA14+BC14=0,0,(AY14+BA14+BC14)/AA14) -> 0 | BR14: =IF(BG14=0,0,BG14/AA14) -> 0 | BS14: =SUM(BL14:BR14) -> 0 | BT14: =AA14/$AA$41 -> #DIV/0!
A15: ='LUCERO RECOLETA'!A15 -> 46149 | B15: =B14+1 -> 946 | D15: =E14+1 -> 1 | E15: =IF(C15="","",C15+D15-1) | I15: =H15*21% -> 0 | K15: =H15+I15+J15 -> 0 | O15: =N15*21% -> 0 | P15: =+N15+O15 -> 0 | T15: =S15*21% -> 0 | U15: =SUM(S15:T15) -> 0 | Y15: =X15*21% -> 0 | Z15: =SUM(X15:Y15) -> 0 | AA15: =+K15+P15+U15-Z15 -> 0 | AG15: =AF15*220 -> 0 | AI15: =AH15*1200 -> 0 | AK15: =AJ15*1200 -> 0 | AL15: =AC15+AD15+AE15+AG15+AI15+AK15 -> 0 | AM15: =SUM(AL15-BH15) -> 0 | AP15: =AD15 | AQ15: =SUM(AR15:AS15) -> 0 | AW15: =AV15*AW$3 -> 0 | AY15: =AX15*AY$2 -> 0 | BA15: =AZ15*BA$2 -> 0 | BC15: =BB15*BC$2 -> 0 | BE15: =BD15*BE$2 -> 0 | BG15: =BF15*BG$4 -> 0 | BH15: =+AN15+AO15+AQ15+AT15+AU15+AW15+AY15+BA15+BC15+BE15+BG15 -> 0 | BI15: =AA15 -> 0 | BJ15: =SUM(BH15-BI15) -> 0 | BL15: =IF(AN15+AO15=0,0,(AN15+AO15)/AA15) -> 0 | BM15: =IF(AR15=0,0,AR15/AA15) -> 0 | BN15: =IF(AS15=0,0,AS15/AA15) -> 0 | BO15: =IF(AT15=0,0,AT15/AA15) -> 0 | BP15: =IF(AW15=0,0,AW15/AA15) -> 0 | BQ15: =IF(AY15+BA15+BC15=0,0,(AY15+BA15+BC15)/AA15) -> 0 | BR15: =IF(BG15=0,0,BG15/AA15) -> 0 | BS15: =SUM(BL15:BR15) -> 0 | BT15: =AA15/$AA$41 -> #DIV/0!
A16: ='LUCERO RECOLETA'!A16 -> 46150 | B16: =B15+1 -> 947 | D16: =E15+1 -> 1 | E16: =IF(C16="","",C16+D16-1) | I16: =H16*21% -> 0 | K16: =H16+I16+J16 -> 0 | O16: =N16*21% -> 0 | P16: =+N16+O16 -> 0 | T16: =S16*21% -> 0 | U16: =SUM(S16:T16) -> 0 | Y16: =X16*21% -> 0 | Z16: =SUM(X16:Y16) -> 0 | AA16: =+K16+P16+U16-Z16 -> 0 | AG16: =AF16*220 -> 0 | AI16: =AH16*1200 -> 0 | AK16: =AJ16*1200 -> 0 | AL16: =AC16+AD16+AE16+AG16+AI16+AK16 -> 0 | AM16: =SUM(AL16-BH16) -> 0 | AP16: =AD16 | AQ16: =SUM(AR16:AS16) -> 0 | AW16: =AV16*AW$3 -> 0 | AY16: =AX16*AY$2 -> 0 | BA16: =AZ16*BA$2 -> 0 | BC16: =BB16*BC$2 -> 0 | BE16: =BD16*BE$2 -> 0 | BG16: =BF16*BG$4 -> 0 | BH16: =+AN16+AO16+AQ16+AT16+AU16+AW16+AY16+BA16+BC16+BE16+BG16 -> 0 | BI16: =AA16 -> 0 | BJ16: =SUM(BH16-BI16) -> 0 | BL16: =IF(AN16+AO16=0,0,(AN16+AO16)/AA16) -> 0 | BM16: =IF(AR16=0,0,AR16/AA16) -> 0 | BN16: =IF(AS16=0,0,AS16/AA16) -> 0 | BO16: =IF(AT16=0,0,AT16/AA16) -> 0 | BP16: =IF(AW16=0,0,AW16/AA16) -> 0 | BQ16: =IF(AY16+BA16+BC16=0,0,(AY16+BA16+BC16)/AA16) -> 0 | BR16: =IF(BG16=0,0,BG16/AA16) -> 0 | BS16: =SUM(BL16:BR16) -> 0 | BT16: =AA16/$AA$41 -> #DIV/0!
A17: ='LUCERO RECOLETA'!A17 -> 46151 | B17: =B16+1 -> 948 | D17: =E16+1 -> 1 | E17: =IF(C17="","",C17+D17-1) | I17: =H17*21% -> 0 | K17: =H17+I17+J17 -> 0 | O17: =N17*21% -> 0 | P17: =+N17+O17 -> 0 | T17: =S17*21% -> 0 | U17: =SUM(S17:T17) -> 0 | Y17: =X17*21% -> 0 | Z17: =SUM(X17:Y17) -> 0 | AA17: =+K17+P17+U17-Z17 -> 0 | AG17: =AF17*220 -> 0 | AI17: =AH17*1200 -> 0 | AK17: =AJ17*1200 -> 0 | AL17: =AC17+AD17+AE17+AG17+AI17+AK17 -> 0 | AM17: =SUM(AL17-BH17) -> 0 | AP17: =AD17 | AQ17: =SUM(AR17:AS17) -> 0 | AW17: =AV17*AW$3 -> 0 | AY17: =AX17*AY$2 -> 0 | BA17: =AZ17*BA$2 -> 0 | BC17: =BB17*BC$2 -> 0 | BE17: =BD17*BE$2 -> 0 | BG17: =BF17*BG$4 -> 0 | BH17: =+AN17+AO17+AQ17+AT17+AU17+AW17+AY17+BA17+BC17+BE17+BG17 -> 0 | BI17: =AA17 -> 0 | BJ17: =SUM(BH17-BI17) -> 0 | BL17: =IF(AN17+AO17=0,0,(AN17+AO17)/AA17) -> 0 | BM17: =IF(AR17=0,0,AR17/AA17) -> 0 | BN17: =IF(AS17=0,0,AS17/AA17) -> 0 | BO17: =IF(AT17=0,0,AT17/AA17) -> 0 | BP17: =IF(AW17=0,0,AW17/AA17) -> 0 | BQ17: =IF(AY17+BA17+BC17=0,0,(AY17+BA17+BC17)/AA17) -> 0 | BR17: =IF(BG17=0,0,BG17/AA17) -> 0 | BS17: =SUM(BL17:BR17) -> 0 | BT17: =AA17/$AA$41 -> #DIV/0!
A18: ='LUCERO RECOLETA'!A18 -> 46152 | B18: =B17+1 -> 949 | D18: =E17+1 -> 1 | E18: =IF(C18="","",C18+D18-1) | I18: =H18*21% -> 0 | K18: =H18+I18+J18 -> 0 | O18: =N18*21% -> 0 | P18: =+N18+O18 -> 0 | T18: =S18*21% -> 0 | U18: =SUM(S18:T18) -> 0 | Y18: =X18*21% -> 0 | Z18: =SUM(X18:Y18) -> 0 | AA18: =+K18+P18+U18-Z18 -> 0 | AG18: =AF18*220 -> 0 | AI18: =AH18*1200 -> 0 | AK18: =AJ18*1200 -> 0 | AL18: =AC18+AD18+AE18+AG18+AI18+AK18 -> 0 | AM18: =SUM(AL18-BH18) -> 0 | AP18: =AD18 | AQ18: =SUM(AR18:AS18) -> 0 | AW18: =AV18*AW$3 -> 0 | AY18: =AX18*AY$2 -> 0 | BA18: =AZ18*BA$2 -> 0 | BC18: =BB18*BC$2 -> 0 | BE18: =BD18*BE$2 -> 0 | BG18: =BF18*BG$4 -> 0 | BH18: =+AN18+AO18+AQ18+AT18+AU18+AW18+AY18+BA18+BC18+BE18+BG18 -> 0 | BI18: =AA18 -> 0 | BJ18: =SUM(BH18-BI18) -> 0 | BL18: =IF(AN18+AO18=0,0,(AN18+AO18)/AA18) -> 0 | BM18: =IF(AR18=0,0,AR18/AA18) -> 0 | BN18: =IF(AS18=0,0,AS18/AA18) -> 0 | BO18: =IF(AT18=0,0,AT18/AA18) -> 0 | BP18: =IF(AW18=0,0,AW18/AA18) -> 0 | BQ18: =IF(AY18+BA18+BC18=0,0,(AY18+BA18+BC18)/AA18) -> 0 | BR18: =IF(BG18=0,0,BG18/AA18) -> 0 | BS18: =SUM(BL18:BR18) -> 0 | BT18: =AA18/$AA$41 -> #DIV/0!
A19: ='LUCERO RECOLETA'!A19 -> 46153 | B19: =B18+1 -> 950 | D19: =E18+1 -> 1 | E19: =IF(C19="","",C19+D19-1) | I19: =H19*21% -> 0 | K19: =H19+I19+J19 -> 0 | O19: =N19*21% -> 0 | P19: =+N19+O19 -> 0 | T19: =S19*21% -> 0 | U19: =SUM(S19:T19) -> 0 | Y19: =X19*21% -> 0 | Z19: =+X19+Y19 -> 0 | AA19: =+K19+P19+U19-Z19 -> 0 | AG19: =AF19*220 -> 0 | AI19: =AH19*1200 -> 0 | AK19: =AJ19*1200 -> 0 | AL19: =AC19+AD19+AE19+AG19+AI19+AK19 -> 0 | AM19: =SUM(AL19-BH19) -> 0 | AP19: =AD19 | AQ19: =SUM(AR19:AS19) -> 0 | AW19: =AV19*AW$3 -> 0 | AY19: =AX19*AY$2 -> 0 | BA19: =AZ19*BA$2 -> 0 | BC19: =BB19*BC$2 -> 0 | BE19: =BD19*BE$2 -> 0 | BG19: =BF19*BG$4 -> 0 | BH19: =+AN19+AO19+AQ19+AT19+AU19+AW19+AY19+BA19+BC19+BE19+BG19 -> 0 | BI19: =AA19 -> 0 | BJ19: =SUM(BH19-BI19) -> 0 | BL19: =IF(AN19+AO19=0,0,(AN19+AO19)/AA19) -> 0 | BM19: =IF(AR19=0,0,AR19/AA19) -> 0 | BN19: =IF(AS19=0,0,AS19/AA19) -> 0 | BO19: =IF(AT19=0,0,AT19/AA19) -> 0 | BP19: =IF(AW19=0,0,AW19/AA19) -> 0 | BQ19: =IF(AY19+BA19+BC19=0,0,(AY19+BA19+BC19)/AA19) -> 0 | BR19: =IF(BG19=0,0,BG19/AA19) -> 0 | BS19: =SUM(BL19:BR19) -> 0 | BT19: =AA19/$AA$41 -> #DIV/0!
A20: ='LUCERO RECOLETA'!A20 -> 46154 | B20: =B19+1 -> 951 | D20: =E19+1 -> 1 | E20: =IF(C20="","",C20+D20-1) | I20: =H20*21% -> 0 | K20: =H20+I20+J20 -> 0 | O20: =N20*21% -> 0 | P20: =+N20+O20 -> 0 | T20: =S20*21% -> 0 | U20: =SUM(S20:T20) -> 0 | Y20: =X20*21% -> 0 | Z20: =SUM(X20:Y20) -> 0 | AA20: =+K20+P20+U20-Z20 -> 0 | AG20: =AF20*220 -> 0 | AI20: =AH20*1200 -> 0 | AK20: =AJ20*1200 -> 0 | AL20: =AC20+AD20+AE20+AG20+AI20+AK20 -> 0 | AM20: =SUM(AL20-BH20) -> 0 | AP20: =AD20 | AQ20: =SUM(AR20:AS20) -> 0 | AW20: =AV20*AW$3 -> 0 | AY20: =AX20*AY$2 -> 0 | BA20: =AZ20*BA$2 -> 0 | BC20: =BB20*BC$2 -> 0 | BE20: =BD20*BE$2 -> 0 | BG20: =BF20*BG$4 -> 0 | BH20: =+AN20+AO20+AQ20+AT20+AU20+AW20+AY20+BA20+BC20+BE20+BG20 -> 0 | BI20: =AA20 -> 0 | BJ20: =SUM(BH20-BI20) -> 0 | BL20: =IF(AN20+AO20=0,0,(AN20+AO20)/AA20) -> 0 | BM20: =IF(AR20=0,0,AR20/AA20) -> 0 | BN20: =IF(AS20=0,0,AS20/AA20) -> 0 | BO20: =IF(AT20=0,0,AT20/AA20) -> 0 | BP20: =IF(AW20=0,0,AW20/AA20) -> 0 | BQ20: =IF(AY20+BA20+BC20=0,0,(AY20+BA20+BC20)/AA20) -> 0 | BR20: =IF(BG20=0,0,BG20/AA20) -> 0 | BS20: =SUM(BL20:BR20) -> 0 | BT20: =AA20/$AA$41 -> #DIV/0!
A21: ='LUCERO RECOLETA'!A21 -> 46155 | B21: =B20+1 -> 952 | D21: =E20+1 -> 1 | E21: =IF(C21="","",C21+D21-1) | I21: =H21*21% -> 0 | K21: =H21+I21+J21 -> 0 | O21: =N21*21% -> 0 | P21: =+N21+O21 -> 0 | T21: =S21*21% -> 0 | U21: =SUM(S21:T21) -> 0 | Y21: =X21*21% -> 0 | Z21: =SUM(X21:Y21) -> 0 | AA21: =+K21+P21+U21-Z21 -> 0 | AG21: =AF21*220 -> 0 | AI21: =AH21*1200 -> 0 | AK21: =AJ21*1200 -> 0 | AL21: =AC21+AD21+AE21+AG21+AI21+AK21 -> 0 | AM21: =SUM(AL21-BH21) -> 0 | AP21: =AD21 | AQ21: =SUM(AR21:AS21) -> 0 | AW21: =AV21*AW$3 -> 0 | AY21: =AX21*AY$2 -> 0 | BA21: =AZ21*BA$2 -> 0 | BC21: =BB21*BC$2 -> 0 | BE21: =BD21*BE$2 -> 0 | BG21: =BF21*BG$4 -> 0 | BH21: =+AN21+AO21+AQ21+AT21+AU21+AW21+AY21+BA21+BC21+BE21+BG21 -> 0 | BI21: =AA21 -> 0 | BJ21: =SUM(BH21-BI21) -> 0 | BL21: =IF(AN21+AO21=0,0,(AN21+AO21)/AA21) -> 0 | BM21: =IF(AR21=0,0,AR21/AA21) -> 0 | BN21: =IF(AS21=0,0,AS21/AA21) -> 0 | BO21: =IF(AT21=0,0,AT21/AA21) -> 0 | BP21: =IF(AW21=0,0,AW21/AA21) -> 0 | BQ21: =IF(AY21+BA21+BC21=0,0,(AY21+BA21+BC21)/AA21) -> 0 | BR21: =IF(BG21=0,0,BG21/AA21) -> 0 | BS21: =SUM(BL21:BR21) -> 0 | BT21: =AA21/$AA$41 -> #DIV/0!
A22: ='LUCERO RECOLETA'!A22 -> 46156 | B22: =B21+1 -> 953 | D22: =E21+1 -> 1 | E22: =IF(C22="","",C22+D22-1) | I22: =H22*21% -> 0 | K22: =H22+I22+J22 -> 0 | O22: =N22*21% -> 0 | P22: =+N22+O22 -> 0 | T22: =S22*21% -> 0 | U22: =SUM(S22:T22) -> 0 | Y22: =X22*21% -> 0 | Z22: =SUM(X22:Y22) -> 0 | AA22: =+K22+P22+U22-Z22 -> 0 | AG22: =AF22*220 -> 0 | AI22: =AH22*1200 -> 0 | AK22: =AJ22*1200 -> 0 | AL22: =AC22+AD22+AE22+AG22+AI22+AK22 -> 0 | AM22: =SUM(AL22-BH22) -> 0 | AP22: =AD22 | AQ22: =SUM(AR22:AS22) -> 0 | AW22: =AV22*AW$3 -> 0 | AY22: =AX22*AY$2 -> 0 | BA22: =AZ22*BA$2 -> 0 | BC22: =BB22*BC$2 -> 0 | BE22: =BD22*BE$2 -> 0 | BG22: =BF22*BG$4 -> 0 | BH22: =+AN22+AO22+AQ22+AT22+AU22+AW22+AY22+BA22+BC22+BE22+BG22 -> 0 | BI22: =AA22 -> 0 | BJ22: =SUM(BH22-BI22) -> 0 | BL22: =IF(AN22+AO22=0,0,(AN22+AO22)/AA22) -> 0 | BM22: =IF(AR22=0,0,AR22/AA22) -> 0 | BN22: =IF(AS22=0,0,AS22/AA22) -> 0 | BO22: =IF(AT22=0,0,AT22/AA22) -> 0 | BP22: =IF(AW22=0,0,AW22/AA22) -> 0 | BQ22: =IF(AY22+BA22+BC22=0,0,(AY22+BA22+BC22)/AA22) -> 0 | BR22: =IF(BG22=0,0,BG22/AA22) -> 0 | BS22: =SUM(BL22:BR22) -> 0 | BT22: =AA22/$AA$41 -> #DIV/0!
A23: ='LUCERO RECOLETA'!A23 -> 46157 | B23: =B22+1 -> 954 | D23: =E22+1 -> 1 | E23: =IF(C23="","",C23+D23-1) | I23: =H23*21% -> 0 | K23: =H23+I23+J23 -> 0 | O23: =N23*21% -> 0 | P23: =+N23+O23 -> 0 | T23: =S23*21% -> 0 | U23: =SUM(S23:T23) -> 0 | Y23: =X23*21% -> 0 | Z23: =SUM(X23:Y23) -> 0 | AA23: =+K23+P23+U23-Z23 -> 0 | AG23: =AF23*220 -> 0 | AI23: =AH23*1200 -> 0 | AK23: =AJ23*1200 -> 0 | AL23: =AC23+AD23+AE23+AG23+AI23+AK23 -> 0 | AM23: =SUM(AL23-BH23) -> 0 | AP23: =AD23 | AQ23: =SUM(AR23:AS23) -> 0 | AW23: =AV23*AW$3 -> 0 | AY23: =AX23*AY$2 -> 0 | BA23: =AZ23*BA$2 -> 0 | BC23: =BB23*BC$2 -> 0 | BE23: =BD23*BE$2 -> 0 | BG23: =BF23*BG$4 -> 0 | BH23: =+AN23+AO23+AQ23+AT23+AU23+AW23+AY23+BA23+BC23+BE23+BG23 -> 0 | BI23: =AA23 -> 0 | BJ23: =SUM(BH23-BI23) -> 0 | BL23: =IF(AN23+AO23=0,0,(AN23+AO23)/AA23) -> 0 | BM23: =IF(AR23=0,0,AR23/AA23) -> 0 | BN23: =IF(AS23=0,0,AS23/AA23) -> 0 | BO23: =IF(AT23=0,0,AT23/AA23) -> 0 | BP23: =IF(AW23=0,0,AW23/AA23) -> 0 | BQ23: =IF(AY23+BA23+BC23=0,0,(AY23+BA23+BC23)/AA23) -> 0 | BR23: =IF(BG23=0,0,BG23/AA23) -> 0 | BS23: =SUM(BL23:BR23) -> 0 | BT23: =AA23/$AA$41 -> #DIV/0!
A24: ='LUCERO RECOLETA'!A24 -> 46158 | B24: =B23+1 -> 955 | D24: =E23+1 -> 1 | E24: =IF(C24="","",C24+D24-1) | I24: =H24*21% -> 0 | K24: =H24+I24+J24 -> 0 | O24: =N24*21% -> 0 | P24: =+N24+O24 -> 0 | T24: =S24*21% -> 0 | U24: =SUM(S24:T24) -> 0 | Y24: =X24*21% -> 0 | Z24: =SUM(X24:Y24) -> 0 | AA24: =+K24+P24+U24-Z24 -> 0 | AG24: =AF24*220 -> 0 | AI24: =AH24*1200 -> 0 | AK24: =AJ24*1200 -> 0 | AL24: =AC24+AD24+AE24+AG24+AI24+AK24 -> 0 | AM24: =SUM(AL24-BH24) -> 0 | AP24: =AD24 | AQ24: =SUM(AR24:AS24) -> 0 | AW24: =AV24*AW$3 -> 0 | AY24: =AX24*AY$2 -> 0 | BA24: =AZ24*BA$2 -> 0 | BC24: =BB24*BC$2 -> 0 | BE24: =BD24*BE$2 -> 0 | BG24: =BF24*BG$4 -> 0 | BH24: =+AN24+AO24+AQ24+AT24+AU24+AW24+AY24+BA24+BC24+BE24+BG24 -> 0 | BI24: =AA24 -> 0 | BJ24: =SUM(BH24-BI24) -> 0 | BL24: =IF(AN24+AO24=0,0,(AN24+AO24)/AA24) -> 0 | BM24: =IF(AR24=0,0,AR24/AA24) -> 0 | BN24: =IF(AS24=0,0,AS24/AA24) -> 0 | BO24: =IF(AT24=0,0,AT24/AA24) -> 0 | BP24: =IF(AW24=0,0,AW24/AA24) -> 0 | BQ24: =IF(AY24+BA24+BC24=0,0,(AY24+BA24+BC24)/AA24) -> 0 | BR24: =IF(BG24=0,0,BG24/AA24) -> 0 | BS24: =SUM(BL24:BR24) -> 0 | BT24: =AA24/$AA$41 -> #DIV/0!
A25: ='LUCERO RECOLETA'!A25 -> 46159 | B25: =B24+1 -> 956 | D25: =E24+1 -> 1 | E25: =IF(C25="","",C25+D25-1) | I25: =H25*21% -> 0 | K25: =H25+I25+J25 -> 0 | O25: =N25*21% -> 0 | P25: =+N25+O25 -> 0 | T25: =S25*21% -> 0 | U25: =SUM(S25:T25) -> 0 | Y25: =X25*21% -> 0 | Z25: =SUM(X25:Y25) -> 0 | AA25: =+K25+P25+U25-Z25 -> 0 | AG25: =AF25*220 -> 0 | AI25: =AH25*1200 -> 0 | AK25: =AJ25*1200 -> 0 | AL25: =AC25+AD25+AE25+AG25+AI25+AK25 -> 0 | AM25: =SUM(AL25-BH25) -> 0 | AP25: =AD25 | AQ25: =SUM(AR25:AS25) -> 0 | AW25: =AV25*AW$3 -> 0 | AY25: =AX25*AY$2 -> 0 | BA25: =AZ25*BA$2 -> 0 | BC25: =BB25*BC$2 -> 0 | BE25: =BD25*BE$2 -> 0 | BG25: =BF25*BG$4 -> 0 | BH25: =+AN25+AO25+AQ25+AT25+AU25+AW25+AY25+BA25+BC25+BE25+BG25 -> 0 | BI25: =AA25 -> 0 | BJ25: =SUM(BH25-BI25) -> 0 | BL25: =IF(AN25+AO25=0,0,(AN25+AO25)/AA25) -> 0 | BM25: =IF(AR25=0,0,AR25/AA25) -> 0 | BN25: =IF(AS25=0,0,AS25/AA25) -> 0 | BO25: =IF(AT25=0,0,AT25/AA25) -> 0 | BP25: =IF(AW25=0,0,AW25/AA25) -> 0 | BQ25: =IF(AY25+BA25+BC25=0,0,(AY25+BA25+BC25)/AA25) -> 0 | BR25: =IF(BG25=0,0,BG25/AA25) -> 0 | BS25: =SUM(BL25:BR25) -> 0 | BT25: =AA25/$AA$41 -> #DIV/0!
A26: ='LUCERO RECOLETA'!A26 -> 46160 | B26: =B25+1 -> 957 | D26: =E25+1 -> 1 | E26: =IF(C26="","",C26+D26-1) | I26: =H26*21% -> 0 | K26: =H26+I26+J26 -> 0 | O26: =N26*21% -> 0 | P26: =+N26+O26 -> 0 | T26: =S26*21% -> 0 | U26: =SUM(S26:T26) -> 0 | Y26: =X26*21% -> 0 | Z26: =SUM(X26:Y26) -> 0 | AA26: =+K26+P26+U26-Z26 -> 0 | AG26: =AF26*220 -> 0 | AI26: =AH26*1200 -> 0 | AK26: =AJ26*1200 -> 0 | AL26: =AC26+AD26+AE26+AG26+AI26+AK26 -> 0 | AM26: =SUM(AL26-BH26) -> 0 | AP26: =AD26 | AQ26: =SUM(AR26:AS26) -> 0 | AW26: =AV26*AW$3 -> 0 | AY26: =AX26*AY$2 -> 0 | BA26: =AZ26*BA$2 -> 0 | BC26: =BB26*BC$2 -> 0 | BE26: =BD26*BE$2 -> 0 | BG26: =BF26*BG$4 -> 0 | BH26: =+AN26+AO26+AQ26+AT26+AU26+AW26+AY26+BA26+BC26+BE26+BG26 -> 0 | BI26: =AA26 -> 0 | BJ26: =SUM(BH26-BI26) -> 0 | BL26: =IF(AN26+AO26=0,0,(AN26+AO26)/AA26) -> 0 | BM26: =IF(AR26=0,0,AR26/AA26) -> 0 | BN26: =IF(AS26=0,0,AS26/AA26) -> 0 | BO26: =IF(AT26=0,0,AT26/AA26) -> 0 | BP26: =IF(AW26=0,0,AW26/AA26) -> 0 | BQ26: =IF(AY26+BA26+BC26=0,0,(AY26+BA26+BC26)/AA26) -> 0 | BR26: =IF(BG26=0,0,BG26/AA26) -> 0 | BS26: =SUM(BL26:BR26) -> 0 | BT26: =AA26/$AA$41 -> #DIV/0!
A27: ='LUCERO RECOLETA'!A27 -> 46161 | B27: =B26+1 -> 958 | D27: =E26+1 -> 1 | E27: =IF(C27="","",C27+D27-1) | I27: =H27*21% -> 0 | K27: =H27+I27+J27 -> 0 | O27: =N27*21% -> 0 | P27: =+N27+O27 -> 0 | T27: =S27*21% -> 0 | U27: =SUM(S27:T27) -> 0 | Y27: =X27*21% -> 0 | Z27: =SUM(X27:Y27) -> 0 | AA27: =+K27+P27+U27-Z27 -> 0 | AG27: =AF27*220 -> 0 | AI27: =AH27*1200 -> 0 | AK27: =AJ27*1200 -> 0 | AL27: =AC27+AD27+AE27+AG27+AI27+AK27 -> 0 | AM27: =SUM(AL27-BH27) -> 0 | AP27: =AD27 | AQ27: =SUM(AR27:AS27) -> 0 | AW27: =AV27*AW$3 -> 0 | AY27: =AX27*AY$2 -> 0 | BA27: =AZ27*BA$2 -> 0 | BC27: =BB27*BC$2 -> 0 | BE27: =BD27*BE$2 -> 0 | BG27: =BF27*BG$4 -> 0 | BH27: =+AN27+AO27+AQ27+AT27+AU27+AW27+AY27+BA27+BC27+BE27+BG27 -> 0 | BI27: =AA27 -> 0 | BJ27: =SUM(BH27-BI27) -> 0 | BL27: =IF(AN27+AO27=0,0,(AN27+AO27)/AA27) -> 0 | BM27: =IF(AR27=0,0,AR27/AA27) -> 0 | BN27: =IF(AS27=0,0,AS27/AA27) -> 0 | BO27: =IF(AT27=0,0,AT27/AA27) -> 0 | BP27: =IF(AW27=0,0,AW27/AA27) -> 0 | BQ27: =IF(AY27+BA27+BC27=0,0,(AY27+BA27+BC27)/AA27) -> 0 | BR27: =IF(BG27=0,0,BG27/AA27) -> 0 | BS27: =SUM(BL27:BR27) -> 0 | BT27: =AA27/$AA$41 -> #DIV/0!
A28: ='LUCERO RECOLETA'!A28 -> 46162 | B28: =B27+1 -> 959 | D28: =E27+1 -> 1 | E28: =IF(C28="","",C28+D28-1) | I28: =H28*21% -> 0 | K28: =H28+I28+J28 -> 0 | O28: =N28*21% -> 0 | P28: =+N28+O28 -> 0 | T28: =S28*21% -> 0 | U28: =SUM(S28:T28) -> 0 | Y28: =X28*21% -> 0 | Z28: =SUM(X28:Y28) -> 0 | AA28: =+K28+P28+U28-Z28 -> 0 | AG28: =AF28*220 -> 0 | AI28: =AH28*1200 -> 0 | AK28: =AJ28*1200 -> 0 | AL28: =AC28+AD28+AE28+AG28+AI28+AK28 -> 0 | AM28: =SUM(AL28-BH28) -> 0 | AP28: =AD28 | AQ28: =SUM(AR28:AS28) -> 0 | AW28: =AV28*AW$3 -> 0 | AY28: =AX28*AY$2 -> 0 | BA28: =AZ28*BA$2 -> 0 | BC28: =BB28*BC$2 -> 0 | BE28: =BD28*BE$2 -> 0 | BG28: =BF28*BG$4 -> 0 | BH28: =+AN28+AO28+AQ28+AT28+AU28+AW28+AY28+BA28+BC28+BE28+BG28 -> 0 | BI28: =AA28 -> 0 | BJ28: =SUM(BH28-BI28) -> 0 | BL28: =IF(AN28+AO28=0,0,(AN28+AO28)/AA28) -> 0 | BM28: =IF(AR28=0,0,AR28/AA28) -> 0 | BN28: =IF(AS28=0,0,AS28/AA28) -> 0 | BO28: =IF(AT28=0,0,AT28/AA28) -> 0 | BP28: =IF(AW28=0,0,AW28/AA28) -> 0 | BQ28: =IF(AY28+BA28+BC28=0,0,(AY28+BA28+BC28)/AA28) -> 0 | BR28: =IF(BG28=0,0,BG28/AA28) -> 0 | BS28: =SUM(BL28:BR28) -> 0 | BT28: =AA28/$AA$41 -> #DIV/0!
A29: ='LUCERO RECOLETA'!A29 -> 46163 | B29: =B28+1 -> 960 | D29: =E28+1 -> 1 | E29: =IF(C29="","",C29+D29-1) | I29: =H29*21% -> 0 | K29: =H29+I29+J29 -> 0 | O29: =N29*21% -> 0 | P29: =+N29+O29 -> 0 | T29: =S29*21% -> 0 | U29: =SUM(S29:T29) -> 0 | Y29: =X29*21% -> 0 | Z29: =SUM(X29:Y29) -> 0 | AA29: =+K29+P29+U29-Z29 -> 0 | AG29: =AF29*220 -> 0 | AI29: =AH29*1200 -> 0 | AK29: =AJ29*1200 -> 0 | AL29: =AC29+AD29+AE29+AG29+AI29+AK29 -> 0 | AM29: =SUM(AL29-BH29) -> 0 | AP29: =AD29 | AQ29: =SUM(AR29:AS29) -> 0 | AW29: =AV29*AW$3 -> 0 | AY29: =AX29*AY$2 -> 0 | BA29: =AZ29*BA$2 -> 0 | BC29: =BB29*BC$2 -> 0 | BE29: =BD29*BE$2 -> 0 | BG29: =BF29*BG$4 -> 0 | BH29: =+AN29+AO29+AQ29+AT29+AU29+AW29+AY29+BA29+BC29+BE29+BG29 -> 0 | BI29: =AA29 -> 0 | BJ29: =SUM(BH29-BI29) -> 0 | BL29: =IF(AN29+AO29=0,0,(AN29+AO29)/AA29) -> 0 | BM29: =IF(AR29=0,0,AR29/AA29) -> 0 | BN29: =IF(AS29=0,0,AS29/AA29) -> 0 | BO29: =IF(AT29=0,0,AT29/AA29) -> 0 | BP29: =IF(AW29=0,0,AW29/AA29) -> 0 | BQ29: =IF(AY29+BA29+BC29=0,0,(AY29+BA29+BC29)/AA29) -> 0 | BR29: =IF(BG29=0,0,BG29/AA29) -> 0 | BS29: =SUM(BL29:BR29) -> 0 | BT29: =AA29/$AA$41 -> #DIV/0!
A30: ='LUCERO RECOLETA'!A30 -> 46164 | B30: =B29+1 -> 961 | D30: =E29+1 -> 1 | E30: =IF(C30="","",C30+D30-1) | I30: =H30*21% -> 0 | K30: =H30+I30+J30 -> 0 | O30: =N30*21% -> 0 | P30: =+N30+O30 -> 0 | T30: =S30*21% -> 0 | U30: =SUM(S30:T30) -> 0 | Y30: =X30*21% -> 0 | Z30: =SUM(X30:Y30) -> 0 | AA30: =+K30+P30+U30-Z30 -> 0 | AG30: =AF30*220 -> 0 | AI30: =AH30*1200 -> 0 | AK30: =AJ30*1200 -> 0 | AL30: =AC30+AD30+AE30+AG30+AI30+AK30 -> 0 | AM30: =SUM(AL30-BH30) -> 0 | AP30: =AD30 | AQ30: =SUM(AR30:AS30) -> 0 | AW30: =AV30*AW$3 -> 0 | AY30: =AX30*AY$2 -> 0 | BA30: =AZ30*BA$2 -> 0 | BC30: =BB30*BC$2 -> 0 | BE30: =BD30*BE$2 -> 0 | BG30: =BF30*BG$4 -> 0 | BH30: =+AN30+AO30+AQ30+AT30+AU30+AW30+AY30+BA30+BC30+BE30+BG30 -> 0 | BI30: =AA30 -> 0 | BJ30: =SUM(BH30-BI30) -> 0 | BL30: =IF(AN30+AO30=0,0,(AN30+AO30)/AA30) -> 0 | BM30: =IF(AR30=0,0,AR30/AA30) -> 0 | BN30: =IF(AS30=0,0,AS30/AA30) -> 0 | BO30: =IF(AT30=0,0,AT30/AA30) -> 0 | BP30: =IF(AW30=0,0,AW30/AA30) -> 0 | BQ30: =IF(AY30+BA30+BC30=0,0,(AY30+BA30+BC30)/AA30) -> 0 | BR30: =IF(BG30=0,0,BG30/AA30) -> 0 | BS30: =SUM(BL30:BR30) -> 0 | BT30: =AA30/$AA$41 -> #DIV/0!
A31: ='LUCERO RECOLETA'!A31 -> 46165 | B31: =B30+1 -> 962 | D31: =E30+1 -> 1 | E31: =IF(C31="","",C31+D31-1) | I31: =H31*21% -> 0 | K31: =H31+I31+J31 -> 0 | O31: =N31*21% -> 0 | P31: =+N31+O31 -> 0 | T31: =S31*21% -> 0 | U31: =SUM(S31:T31) -> 0 | Y31: =X31*21% -> 0 | Z31: =SUM(X31:Y31) -> 0 | AA31: =+K31+P31+U31-Z31 -> 0 | AG31: =AF31*220 -> 0 | AI31: =AH31*1200 -> 0 | AK31: =AJ31*1200 -> 0 | AL31: =AC31+AD31+AE31+AG31+AI31+AK31 -> 0 | AM31: =SUM(AL31-BH31) -> 0 | AP31: =AD31 | AQ31: =SUM(AR31:AS31) -> 0 | AW31: =AV31*AW$3 -> 0 | AY31: =AX31*AY$2 -> 0 | BA31: =AZ31*BA$2 -> 0 | BC31: =BB31*BC$2 -> 0 | BE31: =BD31*BE$2 -> 0 | BG31: =BF31*BG$4 -> 0 | BH31: =+AN31+AO31+AQ31+AT31+AU31+AW31+AY31+BA31+BC31+BE31+BG31 -> 0 | BI31: =AA31 -> 0 | BJ31: =SUM(BH31-BI31) -> 0 | BL31: =IF(AN31+AO31=0,0,(AN31+AO31)/AA31) -> 0 | BM31: =IF(AR31=0,0,AR31/AA31) -> 0 | BN31: =IF(AS31=0,0,AS31/AA31) -> 0 | BO31: =IF(AT31=0,0,AT31/AA31) -> 0 | BP31: =IF(AW31=0,0,AW31/AA31) -> 0 | BQ31: =IF(AY31+BA31+BC31=0,0,(AY31+BA31+BC31)/AA31) -> 0 | BR31: =IF(BG31=0,0,BG31/AA31) -> 0 | BS31: =SUM(BL31:BR31) -> 0 | BT31: =AA31/$AA$41 -> #DIV/0!
... A38: ='LUCERO RECOLETA'!A38 -> 46172 | B38: =B37+1 -> 969 | D38: =E37+1 -> 1 | E38: =IF(C38="","",C38+D38-1) | I38: =H38*21% -> 0 | K38: =H38+I38+J38 -> 0 | O38: =N38*21% -> 0 | P38: =+N38+O38 -> 0 | T38: =S38*21% -> 0 | U38: =SUM(S38:T38) -> 0 | Y38: =X38*21% -> 0 | Z38: =SUM(X38:Y38) -> 0 | AA38: =+K38+P38+U38-Z38 -> 0 | AG38: =AF38*220 -> 0 | AI38: =AH38*1200 -> 0 | AK38: =AJ38*1200 -> 0 | AL38: =AC38+AD38+AE38+AG38+AI38+AK38 -> 0 | AM38: =SUM(AL38-BH38) -> 0 | AP38: =AD38 | AQ38: =SUM(AR38:AS38) -> 0 | AW38: =AV38*AW$3 -> 0 | AY38: =AX38*AY$2 -> 0 | BA38: =AZ38*BA$2 -> 0 | BC38: =BB38*BC$2 -> 0 | BE38: =BD38*BE$2 -> 0 | BG38: =BF38*BG$4 -> 0 | BH38: =+AN38+AO38+AQ38+AT38+AU38+AW38+AY38+BA38+BC38+BE38+BG38 -> 0 | BI38: =AA38 -> 0 | BJ38: =SUM(BH38-BI38) -> 0 | BL38: =IF(AN38+AO38=0,0,(AN38+AO38)/AA38) -> 0 | BM38: =IF(AR38=0,0,AR38/AA38) -> 0 | BN38: =IF(AS38=0,0,AS38/AA38) -> 0 | BO38: =IF(AT38=0,0,AT38/AA38) -> 0 | BP38: =IF(AW38=0,0,AW38/AA38) -> 0 | BQ38: =IF(AY38+BA38+BC38=0,0,(AY38+BA38+BC38)/AA38) -> 0 | BR38: =IF(BG38=0,0,BG38/AA38) -> 0 | BS38: =SUM(BL38:BR38) -> 0 | BT38: =AA38/$AA$41 -> #DIV/0!
A39: ='LUCERO RECOLETA'!A39 -> 46173 | B39: =B38+1 -> 970 | I39: =H39*21% -> 0 | K39: =H39+I39+J39 -> 0 | O39: =N39*21% -> 0 | P39: =+N39+O39 -> 0 | T39: =S39*21% -> 0 | U39: =SUM(S39:T39) -> 0 | Y39: =X39*21% -> 0 | Z39: =SUM(X39:Y39) -> 0 | AA39: =+K39+P39+U39-Z39 -> 0 | AG39: =AF39*220 -> 0 | AI39: =AH39*1200 -> 0 | AK39: =AJ39*1200 -> 0 | AQ39: =SUM(AR39:AS39) -> 0 | AW39: =AV39*AW$3 -> 0 | AY39: =AX39*AY$2 -> 0 | BA39: =AZ39*BA$2 -> 0 | BC39: =BB39*BC$2 -> 0 | BE39: =BD39*BE$2 -> 0 | BG39: =BF39*BG$4 -> 0 | BH39: =+AN39+AO39+AQ39+AT39+AU39+AW39+AY39+BA39+BC39+BE39+BG39 -> 0 | BI39: =AA39 -> 0 | BJ39: =SUM(BH39-BI39) -> 0 | BL39: =IF(AN39+AO39=0,0,(AN39+AO39)/AA39) -> 0 | BM39: =IF(AR39=0,0,AR39/AA39) -> 0 | BN39: =IF(AS39=0,0,AS39/AA39) -> 0 | BO39: =IF(AT39=0,0,AT39/AA39) -> 0 | BP39: =IF(AW39=0,0,AW39/AA39) -> 0 | BQ39: =IF(AY39+BA39+BC39=0,0,(AY39+BA39+BC39)/AA39) -> 0 | BR39: =IF(BG39=0,0,BG39/AA39) -> 0 | BS39: =SUM(BL39:BR39) -> 0 | BT39: =AA39/$AA$41 -> #DIV/0!
O40: =N40*21% -> 0 | T40: =S40*21% -> 0 | Y40: =X40*21% -> 0 | AW40: =AV40*AW$3 -> 0 | AY40: =AX40*AY$2 -> 0 | BA40: =AZ40*BA$2 -> 0 | BC40: =BB40*BC$2 -> 0 | BE40: =BD40*BE$2 -> 0 | BG40: =BF40*BG$4 -> 0 | BH40: =+AN40+AO40+AQ40+AT40+AU40+AW40+AY40+BA40+BC40+BE40+BG40 -> 0 | BJ40: =SUM(BH40-BI40) -> 0
A41: TOTALES | B41: =MAX(B9:B40) -> 970 | C41: =SUM(C9:C40) -> 0 | D41: =MIN(D9:D40) -> 1 | E41: =MAX(E9:E40) -> 0 | F41: =SUM(F9:F40) -> 0 | G41: =SUM(G9:G40) -> 0 | H41: =SUM(H9:H40) -> 0 | I41: =SUM(I9:I40) -> 0 | K41: =SUM(K9:K40) -> 0 | L41: =MIN(L9:L40) -> 0 | M41: =MAX(M9:M40) -> 0 | N41: =SUM(N9:N40) -> 0 | O41: =SUM(O9:O40) -> 0 | P41: =SUM(P9:P40) -> 0 | Q41: =MIN(Q9:Q40) -> 0 | R41: =MAX(R9:R40) -> 0 | S41: =SUM(S9:S40) -> 0 | T41: =SUM(T9:T40) -> 0 | U41: =SUM(U9:U40) -> 0 | V41: =MIN(V9:V40) -> 0 | W41: =MAX(W9:W40) -> 0 | X41: =SUM(X9:X40) -> 0 | Y41: =SUM(Y9:Y40) -> 0 | Z41: =SUM(Z9:Z40) -> 0 | AA41: =SUM(AA9:AA40) -> 0 | AB41: =SUM(AB9:AB38) -> 0 | AC41: =SUM(AC9:AC38) -> 0 | AD41: =SUM(AD9:AD38) -> 0 | AE41: =SUM(AE9:AE38) -> 0 | AF41: =SUM(AF9:AF38) -> 0 | AG41: =SUM(AG9:AG38) -> 0 | AH41: =SUM(AH9:AH38) -> 0 | AI41: =SUM(AI9:AI38) -> 0 | ... AM41: =SUM(AM9:AM38) -> 0 | AN41: =SUM(AN9:AN40) -> 0 | AO41: =SUM(AO9:AO40) -> 0 | AP41: =SUM(AP9:AP40) -> 0 | AQ41: =SUM(AQ9:AQ40) -> 0 | AR41: =SUM(AR9:AR40) -> 0 | AS41: =SUM(AS9:AS40) -> 0 | AT41: =SUM(AT9:AT40) -> 0 | AU41: =SUM(AU9:AU40) -> 0 | ... BJ41: =SUM(BJ9:BJ40) -> 0 | BL41: =IF(AA41=0,0,(AN41+AO41)/AA41) -> 0 | BM41: =IF(AA41=0,0,(AR41)/AA41) -> 0 | BN41: =IF(AA41=0,0,(AS41)/AA41) -> 0 | BO41: =IF($AA$41=0,0,(AT41)/$AA$41) -> 0 | BP41: =IF($AA$41=0,0,(AU41)/$AA$41) -> 0 | BQ41: =IF($AA$41=0,0,(AY41+BA41+BC41)/AA41) -> 0 | BR41: =IF($AA$41=0,0,BG41/AA41) -> 0 | BS41: =SUM(BL41:BR41) -> 0
B42: 939 | D42: 9714 | L42: 13 | Q42: 32 | V42: 84
A43: CONTROL | B43: =B9-B42 -> 1 | D43: =D41-D42 -> -9713 | L43: =L41-L42 -> -13 | Q43: =Q41-Q42 -> -32 | V43: =V41-V42 -> -84 | AB43: 0 | AC43: 0 | AD43: 0 | AE43: 0 | AF43: 0 | AG43: 0 | AH43: 0 | AI43: 0 | AJ43: 0 | AK43: 0 | AL43: 0
Z46: TOTAL | AA46: =AA41+AA45 -> 0 | AN46: $ Efectivo | AO46: $ Deposito / PIX | AP46: TARJETA DEBITO | AQ46: TARJETA CREDITO | AR46: Mercado Pago / TF | AS46: Real | AT46: Dólares | AU46: Euros
AM47: RESUMEN COBRANZA | AN47: =AN41 -> 0 | AO47: =AO41 -> 0 | AP47: =AR41 -> 0 | AQ47: =AS41 -> 0 | AR47: =AT41 -> 0 | AS47: =AW41 -> 0 | AT47: =BA41+BC41+BE41+AY41 -> 0 | AU47: =BG41 -> 0
AN48: =AN47/$AA$41 -> #DIV/0! | AO48: =AO47/$AA$41 -> #DIV/0! | AP48: =AP47/$AA$41 -> #DIV/0! | AQ48: =AQ47/$AA$41 -> #DIV/0! | AR48: =AR47/$AA$41 -> #DIV/0! | AS48: =AS47/$AA$41 -> #DIV/0! | AT48: =AT47/$AA$41 -> #DIV/0! | AU48: =AU47/$AA$41 -> #DIV/0!

Sheet SD 2468
AP1: Cotizaciones | AU1: De | AV1: Hasta
A2: Empresa: SUCCESSFUL BOXES SRL | AU2: ='LUCERO RECOLETA'!AX2 | AV2: ='LUCERO RECOLETA'!AY2 | AW2: ='LUCERO RECOLETA'!AZ2 | AX2: ='LUCERO RECOLETA'!BA2 | AY2: ='LUCERO RECOLETA'!BB2 | AZ2: ='LUCERO RECOLETA'!BC2 | BA2: ='LUCERO RECOLETA'!BD2 | BB2: ='LUCERO RECOLETA'!BE2 | ... BG2: ='LUCERO RECOLETA'!BJ2
A3: Sucursal: LUCERO CENTRAL - Santo Domingo 2468 - CP 1290 | AU3: ='LUCERO RECOLETA'!AX3 | AV3: ='LUCERO RECOLETA'!AY3 | AW3: ='LUCERO RECOLETA'!AZ3 | AX3: ='LUCERO RECOLETA'!BA3 | AY3: ='LUCERO RECOLETA'!BB3 | AZ3: ='LUCERO RECOLETA'!BC3 | BA3: ='LUCERO RECOLETA'!BD3 | BB3: ='LUCERO RECOLETA'!BE3 | ... BG3: ='LUCERO RECOLETA'!BJ3
A5: INFORME DE VENTAS MENSUAL | F5: pv 20 | BA5: =19960+141980+26990+15990+55990+99990+81980+22000+108980+826900+39980+9990+9990 -> 1460720
A7: JUNIO | B7: Detalle de TICKETS | L7: Detalle de FACTURAS B | Q7: Detalle de FACTURAS A | V7: Detalle de NOTAS DE CREDITO | AA7: VENTA FINAL | AB7: INFORME SEGÚN MAIL | AM7: DIFERENCIA | AN7: CONTROL DE CIERRE DE CAJA
A8: Fecha | B8: Informe de cierre | C8: N° Tickets | D8: Desde | E8: Hasta | F8: Anulados y/o cancelados | G8: Cant. de art. | H8: Imp. de VTA gravado | I8: IVA 21% | J8: Otros imp. | K8: Imp. de VTA total | L8: Desde | M8: Hasta | N8: Imp.de VTA gravado | O8: IVA 21% | P8: Imp.de vta total | Q8: Desde | R8: Hasta | S8: Imp.de VTA gravado | T8: IVA 21% | U8: Imp.de vta total | V8: Desde | W8: Hasta | X8: Imp.de VTA gravado | Y8: IVA 21% | Z8: Imp.de vta total | AB8: VENTA TOTAL | AC8: EFECTIVO $ | AD8: TARJETAS | AE8: MERCADO PAGO | AF8: Real | AH8: Dolar | AJ8: EURO | AL8: TOTAL DE INGRESO | AN8: $ Efectivo | AO8: $ Deposito / PIX | AP8: TARJ SEGUN PLANILLA | AQ8: TOTAL TARJETAS OK | AR8: TARJETA DEBITO | AS8: TARJETA CREDITO | AT8: Mercado Pago / TF | AU8: Gastos | AV8: Real | AX8: Dólar 100 | AZ8: Dólar 50 | BB8: Dólar 10. 20 | BD8: Dólar 1. 5 | BF8: EURO | BH8: Total | BI8: CIERRE | BJ8: DIFERENCIA | BL8: =AN8 -> $ Efectivo | BM8: =AR8 -> TARJETA DEBITO | BN8: =AS8 -> TARJETA CREDITO | BO8: =AT8 -> Mercado Pago / TF | BP8: =AV8 -> Real | BQ8: Dólar | BR8: Euro | BS8: Total | BT8: Venta x día
A9: ='LUCERO RECOLETA'!A9 -> 46143 | I9: =H9*21% -> 0 | K9: =H9+I9+J9 -> 0 | O9: =N9*21% -> 0 | P9: =+N9+O9 -> 0 | T9: =S9*21% -> 0 | U9: =SUM(S9:T9) -> 0 | Y9: =X9*21% -> 0 | Z9: =SUM(X9:Y9) -> 0 | AA9: =+K9+P9+U9-Z9 -> 0 | AG9: =AF9*220 -> 0 | AI9: =AH9*1200 -> 0 | AK9: =AJ9*1200 -> 0 | AL9: =AC9+AD9+AE9+AG9+AI9+AK9 -> 0 | AM9: =SUM(AL9-BH9) -> 0 | AP9: =AD9 | AQ9: =SUM(AR9:AS9) -> 0 | AW9: =AV9*AW$2 -> 0 | AY9: =AX9*AY$2 -> 0 | BA9: =AZ9*BA$2 -> 0 | BC9: =BB9*BC$2 -> 0 | BE9: =BD9*BE$2 -> 0 | BG9: =BF9*BG$2 -> 0 | BH9: =+AN9+AO9+AQ9+AT9+AU9+AW9+AY9+BA9+BC9+BE8+BG9 -> 0 | BI9: =AA9 -> 0 | BJ9: =SUM(BH9-BI9) -> 0 | BL9: =IF(AN9+AO9=0,0,(AN9+AO9)/AA9) -> 0 | BM9: =IF(AR9=0,0,AR9/AA9) -> 0 | BN9: =IF(AS9=0,0,AS9/AA9) -> 0 | BO9: =IF(AT9=0,0,AT9/AA9) -> 0 | BP9: =IF(AW9=0,0,AW9/AA9) -> 0 | BQ9: =IF(AY9+BA9+BC9=0,0,(AY9+BA9+BC9)/AA9) -> 0 | BR9: =IF(BG9=0,0,BG9/AA9) -> 0 | BS9: =SUM(BL9:BR9) -> 0 | BT9: =AA9/$AA$41 -> #DIV/0!
A10: =A9+1 -> 46144 | I10: =H10*21% -> 0 | K10: =H10+I10+J10 -> 0 | O10: =N10*21% -> 0 | P10: =+N10+O10 -> 0 | T10: =S10*21% -> 0 | U10: =SUM(S10:T10) -> 0 | Y10: =X10*21% -> 0 | Z10: =SUM(X10:Y10) -> 0 | AA10: =+K10+P10+U10-Z10 -> 0 | AG10: =AF10*220 -> 0 | AI10: =AH10*1200 -> 0 | AK10: =AJ10*1200 -> 0 | AL10: =AC10+AD10+AE10+AG10+AI10+AK10 -> 0 | AM10: =SUM(AL10-BH10) -> 0 | AP10: =AD10 | AQ10: =SUM(AR10:AS10) -> 0 | AW10: =AV10*AW$2 -> 0 | AY10: =AX10*AY$2 -> 0 | BA10: =AZ10*BA$2 -> 0 | BC10: =BB10*BC$2 -> 0 | BE10: =BD10*BE$2 -> 0 | BG10: =BF10*BG$2 -> 0 | BH10: =+AN10+AO10+AQ10+AT10+AU10+AW10+AY10+BA10+BC10+BE9+BG10 -> 0 | BI10: =AA10 -> 0 | BJ10: =SUM(BH10-BI10) -> 0 | BL10: =IF(AN10+AO10=0,0,(AN10+AO10)/AA10) -> 0 | BM10: =IF(AR10=0,0,AR10/AA10) -> 0 | BN10: =IF(AS10=0,0,AS10/AA10) -> 0 | BO10: =IF(AT10=0,0,AT10/AA10) -> 0 | BP10: =IF(AW10=0,0,AW10/AA10) -> 0 | BQ10: =IF(AY10+BA10+BC10=0,0,(AY10+BA10+BC10)/AA10) -> 0 | BR10: =IF(BG10=0,0,BG10/AA10) -> 0 | BS10: =SUM(BL10:BR10) -> 0 | BT10: =AA10/$AA$41 -> #DIV/0!
A11: =A10+1 -> 46145 | I11: =H11*21% -> 0 | K11: =H11+I11+J11 -> 0 | O11: =N11*21% -> 0 | P11: =+N11+O11 -> 0 | T11: =S11*21% -> 0 | U11: =SUM(S11:T11) -> 0 | Y11: =X11*21% -> 0 | Z11: =SUM(X11:Y11) -> 0 | AA11: =+K11+P11+U11-Z11 -> 0 | AG11: =AF11*220 -> 0 | AI11: =AH11*1200 -> 0 | AK11: =AJ11*1200 -> 0 | AL11: =AC11+AD11+AE11+AG11+AI11+AK11 -> 0 | AM11: =SUM(AL11-BH11) -> 0 | AP11: =AD11 | AQ11: =AR11+AS11 -> 0 | AW11: =AV11*AW$3 -> 0 | AY11: =AX11*AY$2 -> 0 | BA11: =AZ11*BA$2 -> 0 | BC11: =BB11*BC$2 -> 0 | BE11: =BD11*BE$2 -> 0 | BG11: =BF11*BG$2 -> 0 | BH11: =+AN11+AO11+AQ11+AT11+AU11+AW11+AY11+BA11+BC11+BE11+BG11 -> 0 | BI11: =AA11 -> 0 | BJ11: =SUM(BH11-BI11) -> 0 | BL11: =IF(AN11+AO11=0,0,(AN11+AO11)/AA11) -> 0 | BM11: =IF(AR11=0,0,AR11/AA11) -> 0 | BN11: =IF(AS11=0,0,AS11/AA11) -> 0 | BO11: =IF(AT11=0,0,AT11/AA11) -> 0 | BP11: =IF(AW11=0,0,AW11/AA11) -> 0 | BQ11: =IF(AY11+BA11+BC11=0,0,(AY11+BA11+BC11)/AA11) -> 0 | BR11: =IF(BG11=0,0,BG11/AA11) -> 0 | BS11: =SUM(BL11:BR11) -> 0 | BT11: =AA11/$AA$41 -> #DIV/0!
A12: =A11+1 -> 46146 | I12: =H12*21% -> 0 | K12: =H12+I12+J12 -> 0 | O12: =N12*21% -> 0 | P12: =+N12+O12 -> 0 | T12: =S12*21% -> 0 | U12: =SUM(S12:T12) -> 0 | Y12: =X12*21% -> 0 | Z12: =SUM(X12:Y12) -> 0 | AA12: =+K12+P12+U12-Z12 -> 0 | AG12: =AF12*220 -> 0 | AI12: =AH12*1200 -> 0 | AK12: =AJ12*1200 -> 0 | AL12: =AC12+AD12+AE12+AG12+AI12+AK12 -> 0 | AM12: =SUM(AL12-BH12) -> 0 | AP12: =AD12 | AQ12: =SUM(AR12:AS12) -> 0 | AW12: =AV12*AW$3 -> 0 | AY12: =AX12*AY$2 -> 0 | BA12: =AZ12*BA$2 -> 0 | BC12: =BB12*BC$2 -> 0 | BE12: =BD12*BE$2 -> 0 | BG12: =BF12*BG$2 -> 0 | BH12: =+AN12+AO12+AQ12+AT12+AU12+AW12+AY12+BA12+BC12+BE12+BG12 -> 0 | BI12: =AA12 -> 0 | BJ12: =SUM(BH12-BI12) -> 0 | BL12: =IF(AN12+AO12=0,0,(AN12+AO12)/AA12) -> 0 | BM12: =IF(AR12=0,0,AR12/AA12) -> 0 | BN12: =IF(AS12=0,0,AS12/AA12) -> 0 | BO12: =IF(AT12=0,0,AT12/AA12) -> 0 | BP12: =IF(AW12=0,0,AW12/AA12) -> 0 | BQ12: =IF(AY12+BA12+BC12=0,0,(AY12+BA12+BC12)/AA12) -> 0 | BR12: =IF(BG12=0,0,BG12/AA12) -> 0 | BS12: =SUM(BL12:BR12) -> 0 | BT12: =AA12/$AA$41 -> #DIV/0!
A13: =A12+1 -> 46147 | I13: =H13*21% -> 0 | K13: =H13+I13+J13 -> 0 | O13: =N13*21% -> 0 | P13: =+N13+O13 -> 0 | T13: =S13*21% -> 0 | U13: =SUM(S13:T13) -> 0 | Y13: =X13*21% -> 0 | Z13: =SUM(X13:Y13) -> 0 | AA13: =+K13+P13+U13-Z13 -> 0 | AG13: =AF13*220 -> 0 | AI13: =AH13*1200 -> 0 | AK13: =AJ13*1200 -> 0 | AL13: =AC13+AD13+AE13+AG13+AI13+AK13 -> 0 | AM13: =SUM(AL13-BH13) -> 0 | AP13: =AD13 | AQ13: =SUM(AR13:AS13) -> 0 | AW13: =AV13*AW$3 -> 0 | AY13: =AX13*AY$2 -> 0 | BA13: =AZ13*BA$2 -> 0 | BC13: =BB13*BC$2 -> 0 | BE13: =BD13*BE$2 -> 0 | BG13: =BF13*BG$2 -> 0 | BH13: =+AN13+AO13+AQ13+AT13+AU13+AW13+AY13+BA13+BC13+BE13+BG13 -> 0 | BI13: =AA13 -> 0 | BJ13: =SUM(BH13-BI13) -> 0 | BL13: =IF(AN13+AO13=0,0,(AN13+AO13)/AA13) -> 0 | BM13: =IF(AR13=0,0,AR13/AA13) -> 0 | BN13: =IF(AS13=0,0,AS13/AA13) -> 0 | BO13: =IF(AT13=0,0,AT13/AA13) -> 0 | BP13: =IF(AW13=0,0,AW13/AA13) -> 0 | BQ13: =IF(AY13+BA13+BC13=0,0,(AY13+BA13+BC13)/AA13) -> 0 | BR13: =IF(BG13=0,0,BG13/AA13) -> 0 | BS13: =SUM(BL13:BR13) -> 0 | BT13: =AA13/$AA$41 -> #DIV/0!
A14: =A13+1 -> 46148 | I14: =H14*21% -> 0 | K14: =H14+I14+J14 -> 0 | O14: =N14*21% -> 0 | P14: =+N14+O14 -> 0 | T14: =S14*21% -> 0 | U14: =SUM(S14:T14) -> 0 | Y14: =X14*21% -> 0 | Z14: =SUM(X14:Y14) -> 0 | AA14: =+K14+P14+U14-Z14 -> 0 | AG14: =AF14*220 -> 0 | AI14: =AH14*1200 -> 0 | AK14: =AJ14*1200 -> 0 | AL14: =AC14+AD14+AE14+AG14+AI14+AK14 -> 0 | AM14: =SUM(AL14-BH14) -> 0 | AP14: =AD14 | AQ14: =SUM(AR14:AS14) -> 0 | AW14: =AV14*AW$3 -> 0 | AY14: =AX14*AY$2 -> 0 | BA14: =AZ14*BA$2 -> 0 | BC14: =BB14*BC$2 -> 0 | BE14: =BD14*BE$2 -> 0 | BG14: =BF14*BG$2 -> 0 | BH14: =+AN14+AO14+AQ14+AT14+AU14+AW14+AY14+BA14+BC14+BE14+BG14 -> 0 | BI14: =AA14 -> 0 | BJ14: =SUM(BH14-BI14) -> 0 | BL14: =IF(AN14+AO14=0,0,(AN14+AO14)/AA14) -> 0 | BM14: =IF(AR14=0,0,AR14/AA14) -> 0 | BN14: =IF(AS14=0,0,AS14/AA14) -> 0 | BO14: =IF(AT14=0,0,AT14/AA14) -> 0 | BP14: =IF(AW14=0,0,AW14/AA14) -> 0 | BQ14: =IF(AY14+BA14+BC14=0,0,(AY14+BA14+BC14)/AA14) -> 0 | BR14: =IF(BG14=0,0,BG14/AA14) -> 0 | BS14: =SUM(BL14:BR14) -> 0 | BT14: =AA14/$AA$41 -> #DIV/0!
A15: =A14+1 -> 46149 | I15: =H15*21% -> 0 | K15: =H15+I15+J15 -> 0 | O15: =N15*21% -> 0 | P15: =+N15+O15 -> 0 | T15: =S15*21% -> 0 | U15: =SUM(S15:T15) -> 0 | Y15: =X15*21% -> 0 | Z15: =SUM(X15:Y15) -> 0 | AA15: =+K15+P15+U15-Z15 -> 0 | AG15: =AF15*220 -> 0 | AI15: =AH15*1200 -> 0 | AK15: =AJ15*1200 -> 0 | AL15: =AC15+AD15+AE15+AG15+AI15+AK15 -> 0 | AM15: =SUM(AL15-BH15) -> 0 | AP15: =AD15 | AQ15: =SUM(AR15:AS15) -> 0 | AW15: =AV15*AW$3 -> 0 | AY15: =AX15*AY$2 -> 0 | BA15: =AZ15*BA$2 -> 0 | BC15: =BB15*BC$2 -> 0 | BE15: =BD15*BE$2 -> 0 | BG15: =BF15*BG$4 -> 0 | BH15: =+AN15+AO15+AQ15+AT15+AU15+AW15+AY15+BA15+BC15+BE15+BG15 -> 0 | BI15: =AA15 -> 0 | BJ15: =SUM(BH15-BI15) -> 0 | BL15: =IF(AN15+AO15=0,0,(AN15+AO15)/AA15) -> 0 | BM15: =IF(AR15=0,0,AR15/AA15) -> 0 | BN15: =IF(AS15=0,0,AS15/AA15) -> 0 | BO15: =IF(AT15=0,0,AT15/AA15) -> 0 | BP15: =IF(AW15=0,0,AW15/AA15) -> 0 | BQ15: =IF(AY15+BA15+BC15=0,0,(AY15+BA15+BC15)/AA15) -> 0 | BR15: =IF(BG15=0,0,BG15/AA15) -> 0 | BS15: =SUM(BL15:BR15) -> 0 | BT15: =AA15/$AA$41 -> #DIV/0!
A16: =A15+1 -> 46150 | I16: =H16*21% -> 0 | K16: =H16+I16+J16 -> 0 | O16: =N16*21% -> 0 | P16: =+N16+O16 -> 0 | T16: =S16*21% -> 0 | U16: =SUM(S16:T16) -> 0 | Y16: =X16*21% -> 0 | Z16: =SUM(X16:Y16) -> 0 | AA16: =+K16+P16+U16-Z16 -> 0 | AG16: =AF16*220 -> 0 | AI16: =AH16*1200 -> 0 | AK16: =AJ16*1200 -> 0 | AL16: =AC16+AD16+AE16+AG16+AI16+AK16 -> 0 | AM16: =SUM(AL16-BH16) -> 0 | AP16: =AD16 | AQ16: =SUM(AR16:AS16) -> 0 | AW16: =AV16*AW$3 -> 0 | AY16: =AX16*AY$2 -> 0 | BA16: =AZ16*BA$2 -> 0 | BC16: =BB16*BC$2 -> 0 | BE16: =BD16*BE$2 -> 0 | BG16: =BF16*BG$4 -> 0 | BH16: =+AN16+AO16+AQ16+AT16+AU16+AW16+AY16+BA16+BC16+BE16+BG16 -> 0 | BI16: =AA16 -> 0 | BJ16: =SUM(BH16-BI16) -> 0 | BL16: =IF(AN16+AO16=0,0,(AN16+AO16)/AA16) -> 0 | BM16: =IF(AR16=0,0,AR16/AA16) -> 0 | BN16: =IF(AS16=0,0,AS16/AA16) -> 0 | BO16: =IF(AT16=0,0,AT16/AA16) -> 0 | BP16: =IF(AW16=0,0,AW16/AA16) -> 0 | BQ16: =IF(AY16+BA16+BC16=0,0,(AY16+BA16+BC16)/AA16) -> 0 | BR16: =IF(BG16=0,0,BG16/AA16) -> 0 | BS16: =SUM(BL16:BR16) -> 0 | BT16: =AA16/$AA$41 -> #DIV/0!
A17: =A16+1 -> 46151 | I17: =H17*21% -> 0 | K17: =H17+I17+J17 -> 0 | O17: =N17*21% -> 0 | P17: =+N17+O17 -> 0 | T17: =S17*21% -> 0 | U17: =SUM(S17:T17) -> 0 | Y17: =X17*21% -> 0 | Z17: =SUM(X17:Y17) -> 0 | AA17: =+K17+P17+U17-Z17 -> 0 | AG17: =AF17*220 -> 0 | AI17: =AH17*1200 -> 0 | AK17: =AJ17*1200 -> 0 | AL17: =AC17+AD17+AE17+AG17+AI17+AK17 -> 0 | AM17: =SUM(AL17-BH17) -> 0 | AP17: =AD17 | AQ17: =SUM(AR17:AS17) -> 0 | AW17: =AV17*AW$3 -> 0 | AY17: =AX17*AY$2 -> 0 | BA17: =AZ17*BA$2 -> 0 | BC17: =BB17*BC$2 -> 0 | BE17: =BD17*BE$2 -> 0 | BG17: =BF17*BG$4 -> 0 | BH17: =+AN17+AO17+AQ17+AT17+AU17+AW17+AY17+BA17+BC17+BE17+BG17 -> 0 | BI17: =AA17 -> 0 | BJ17: =SUM(BH17-BI17) -> 0 | BL17: =IF(AN17+AO17=0,0,(AN17+AO17)/AA17) -> 0 | BM17: =IF(AR17=0,0,AR17/AA17) -> 0 | BN17: =IF(AS17=0,0,AS17/AA17) -> 0 | BO17: =IF(AT17=0,0,AT17/AA17) -> 0 | BP17: =IF(AW17=0,0,AW17/AA17) -> 0 | BQ17: =IF(AY17+BA17+BC17=0,0,(AY17+BA17+BC17)/AA17) -> 0 | BR17: =IF(BG17=0,0,BG17/AA17) -> 0 | BS17: =SUM(BL17:BR17) -> 0 | BT17: =AA17/$AA$41 -> #DIV/0!
A18: =A17+1 -> 46152 | I18: =H18*21% -> 0 | K18: =H18+I18+J18 -> 0 | O18: =N18*21% -> 0 | P18: =+N18+O18 -> 0 | T18: =S18*21% -> 0 | U18: =SUM(S18:T18) -> 0 | Y18: =X18*21% -> 0 | Z18: =SUM(X18:Y18) -> 0 | AA18: =+K18+P18+U18-Z18 -> 0 | AG18: =AF18*220 -> 0 | AI18: =AH18*1200 -> 0 | AK18: =AJ18*1200 -> 0 | AL18: =AC18+AD18+AE18+AG18+AI18+AK18 -> 0 | AM18: =SUM(AL18-BH18) -> 0 | AP18: =AD18 | AQ18: =SUM(AR18:AS18) -> 0 | AW18: =AV18*AW$3 -> 0 | AY18: =AX18*AY$2 -> 0 | BA18: =AZ18*BA$2 -> 0 | BC18: =BB18*BC$2 -> 0 | BE18: =BD18*BE$2 -> 0 | BG18: =BF18*BG$4 -> 0 | BH18: =+AN18+AO18+AQ18+AT18+AU18+AW18+AY18+BA18+BC18+BE18+BG18 -> 0 | BI18: =AA18 -> 0 | BJ18: =SUM(BH18-BI18) -> 0 | BL18: =IF(AN18+AO18=0,0,(AN18+AO18)/AA18) -> 0 | BM18: =IF(AR18=0,0,AR18/AA18) -> 0 | BN18: =IF(AS18=0,0,AS18/AA18) -> 0 | BO18: =IF(AT18=0,0,AT18/AA18) -> 0 | BP18: =IF(AW18=0,0,AW18/AA18) -> 0 | BQ18: =IF(AY18+BA18+BC18=0,0,(AY18+BA18+BC18)/AA18) -> 0 | BR18: =IF(BG18=0,0,BG18/AA18) -> 0 | BS18: =SUM(BL18:BR18) -> 0 | BT18: =AA18/$AA$41 -> #DIV/0!
A19: =A18+1 -> 46153 | I19: =H19*21% -> 0 | K19: =H19+I19+J19 -> 0 | O19: =N19*21% -> 0 | P19: =+N19+O19 -> 0 | T19: =S19*21% -> 0 | U19: =SUM(S19:T19) -> 0 | Y19: =X19*21% -> 0 | Z19: =+X19+Y19 -> 0 | AA19: =+K19+P19+U19-Z19 -> 0 | AG19: =AF19*220 -> 0 | AI19: =AH19*1200 -> 0 | AK19: =AJ19*1200 -> 0 | AL19: =AC19+AD19+AE19+AG19+AI19+AK19 -> 0 | AM19: =SUM(AL19-BH19) -> 0 | AP19: =AD19 | AQ19: =SUM(AR19:AS19) -> 0 | AW19: =AV19*AW$3 -> 0 | AY19: =AX19*AY$2 -> 0 | BA19: =AZ19*BA$2 -> 0 | BC19: =BB19*BC$2 -> 0 | BE19: =BD19*BE$2 -> 0 | BG19: =BF19*BG$4 -> 0 | BH19: =+AN19+AO19+AQ19+AT19+AU19+AW19+AY19+BA19+BC19+BE19+BG19 -> 0 | BI19: =AA19 -> 0 | BJ19: =SUM(BH19-BI19) -> 0 | BL19: =IF(AN19+AO19=0,0,(AN19+AO19)/AA19) -> 0 | BM19: =IF(AR19=0,0,AR19/AA19) -> 0 | BN19: =IF(AS19=0,0,AS19/AA19) -> 0 | BO19: =IF(AT19=0,0,AT19/AA19) -> 0 | BP19: =IF(AW19=0,0,AW19/AA19) -> 0 | BQ19: =IF(AY19+BA19+BC19=0,0,(AY19+BA19+BC19)/AA19) -> 0 | BR19: =IF(BG19=0,0,BG19/AA19) -> 0 | BS19: =SUM(BL19:BR19) -> 0 | BT19: =AA19/$AA$41 -> #DIV/0!
A20: =A19+1 -> 46154 | I20: =H20*21% -> 0 | K20: =H20+I20+J20 -> 0 | O20: =N20*21% -> 0 | P20: =+N20+O20 -> 0 | T20: =S20*21% -> 0 | U20: =SUM(S20:T20) -> 0 | Y20: =X20*21% -> 0 | Z20: =SUM(X20:Y20) -> 0 | AA20: =+K20+P20+U20-Z20 -> 0 | AG20: =AF20*220 -> 0 | AI20: =AH20*1200 -> 0 | AK20: =AJ20*1200 -> 0 | AL20: =AC20+AD20+AE20+AG20+AI20+AK20 -> 0 | AM20: =SUM(AL20-BH20) -> 0 | AP20: =AD20 | AQ20: =SUM(AR20:AS20) -> 0 | AW20: =AV20*AW$3 -> 0 | AY20: =AX20*AY$2 -> 0 | BA20: =AZ20*BA$2 -> 0 | BC20: =BB20*BC$2 -> 0 | BE20: =BD20*BE$2 -> 0 | BG20: =BF20*BG$4 -> 0 | BH20: =+AN20+AO20+AQ20+AT20+AU20+AW20+AY20+BA20+BC20+BE20+BG20 -> 0 | BI20: =AA20 -> 0 | BJ20: =SUM(BH20-BI20) -> 0 | BL20: =IF(AN20+AO20=0,0,(AN20+AO20)/AA20) -> 0 | BM20: =IF(AR20=0,0,AR20/AA20) -> 0 | BN20: =IF(AS20=0,0,AS20/AA20) -> 0 | BO20: =IF(AT20=0,0,AT20/AA20) -> 0 | BP20: =IF(AW20=0,0,AW20/AA20) -> 0 | BQ20: =IF(AY20+BA20+BC20=0,0,(AY20+BA20+BC20)/AA20) -> 0 | BR20: =IF(BG20=0,0,BG20/AA20) -> 0 | BS20: =SUM(BL20:BR20) -> 0 | BT20: =AA20/$AA$41 -> #DIV/0!
A21: =A20+1 -> 46155 | I21: =H21*21% -> 0 | K21: =H21+I21+J21 -> 0 | O21: =N21*21% -> 0 | P21: =+N21+O21 -> 0 | T21: =S21*21% -> 0 | U21: =SUM(S21:T21) -> 0 | Y21: =X21*21% -> 0 | Z21: =SUM(X21:Y21) -> 0 | AA21: =+K21+P21+U21-Z21 -> 0 | AG21: =AF21*220 -> 0 | AI21: =AH21*1200 -> 0 | AK21: =AJ21*1200 -> 0 | AL21: =AC21+AD21+AE21+AG21+AI21+AK21 -> 0 | AM21: =SUM(AL21-BH21) -> 0 | AP21: =AD21 | AQ21: =SUM(AR21:AS21) -> 0 | AW21: =AV21*AW$3 -> 0 | AY21: =AX21*AY$2 -> 0 | BA21: =AZ21*BA$2 -> 0 | BC21: =BB21*BC$2 -> 0 | BE21: =BD21*BE$2 -> 0 | BG21: =BF21*BG$4 -> 0 | BH21: =+AN21+AO21+AQ21+AT21+AU21+AW21+AY21+BA21+BC21+BE21+BG21 -> 0 | BI21: =AA21 -> 0 | BJ21: =SUM(BH21-BI21) -> 0 | BL21: =IF(AN21+AO21=0,0,(AN21+AO21)/AA21) -> 0 | BM21: =IF(AR21=0,0,AR21/AA21) -> 0 | BN21: =IF(AS21=0,0,AS21/AA21) -> 0 | BO21: =IF(AT21=0,0,AT21/AA21) -> 0 | BP21: =IF(AW21=0,0,AW21/AA21) -> 0 | BQ21: =IF(AY21+BA21+BC21=0,0,(AY21+BA21+BC21)/AA21) -> 0 | BR21: =IF(BG21=0,0,BG21/AA21) -> 0 | BS21: =SUM(BL21:BR21) -> 0 | BT21: =AA21/$AA$41 -> #DIV/0!
A22: =A21+1 -> 46156 | I22: =H22*21% -> 0 | K22: =H22+I22+J22 -> 0 | O22: =N22*21% -> 0 | P22: =+N22+O22 -> 0 | T22: =S22*21% -> 0 | U22: =SUM(S22:T22) -> 0 | Y22: =X22*21% -> 0 | Z22: =SUM(X22:Y22) -> 0 | AA22: =+K22+P22+U22-Z22 -> 0 | AG22: =AF22*220 -> 0 | AI22: =AH22*1200 -> 0 | AK22: =AJ22*1200 -> 0 | AL22: =AC22+AD22+AE22+AG22+AI22+AK22 -> 0 | AM22: =SUM(AL22-BH22) -> 0 | AP22: =AD22 | AQ22: =SUM(AR22:AS22) -> 0 | AW22: =AV22*AW$3 -> 0 | AY22: =AX22*AY$2 -> 0 | BA22: =AZ22*BA$2 -> 0 | BC22: =BB22*BC$2 -> 0 | BE22: =BD22*BE$2 -> 0 | BG22: =BF22*BG$4 -> 0 | BH22: =+AN22+AO22+AQ22+AT22+AU22+AW22+AY22+BA22+BC22+BE22+BG22 -> 0 | BI22: =AA22 -> 0 | BJ22: =SUM(BH22-BI22) -> 0 | BL22: =IF(AN22+AO22=0,0,(AN22+AO22)/AA22) -> 0 | BM22: =IF(AR22=0,0,AR22/AA22) -> 0 | BN22: =IF(AS22=0,0,AS22/AA22) -> 0 | BO22: =IF(AT22=0,0,AT22/AA22) -> 0 | BP22: =IF(AW22=0,0,AW22/AA22) -> 0 | BQ22: =IF(AY22+BA22+BC22=0,0,(AY22+BA22+BC22)/AA22) -> 0 | BR22: =IF(BG22=0,0,BG22/AA22) -> 0 | BS22: =SUM(BL22:BR22) -> 0 | BT22: =AA22/$AA$41 -> #DIV/0!
A23: =A22+1 -> 46157 | I23: =H23*21% -> 0 | K23: =H23+I23+J23 -> 0 | O23: =N23*21% -> 0 | P23: =+N23+O23 -> 0 | T23: =S23*21% -> 0 | U23: =SUM(S23:T23) -> 0 | Y23: =X23*21% -> 0 | Z23: =SUM(X23:Y23) -> 0 | AA23: =+K23+P23+U23-Z23 -> 0 | AG23: =AF23*220 -> 0 | AI23: =AH23*1200 -> 0 | AK23: =AJ23*1200 -> 0 | AL23: =AC23+AD23+AE23+AG23+AI23+AK23 -> 0 | AM23: =SUM(AL23-BH23) -> 0 | AP23: =AD23 | AQ23: =SUM(AR23:AS23) -> 0 | AW23: =AV23*AW$3 -> 0 | AY23: =AX23*AY$2 -> 0 | BA23: =AZ23*BA$2 -> 0 | BC23: =BB23*BC$2 -> 0 | BE23: =BD23*BE$2 -> 0 | BG23: =BF23*BG$4 -> 0 | BH23: =+AN23+AO23+AQ23+AT23+AU23+AW23+AY23+BA23+BC23+BE23+BG23 -> 0 | BI23: =AA23 -> 0 | BJ23: =SUM(BH23-BI23) -> 0 | BL23: =IF(AN23+AO23=0,0,(AN23+AO23)/AA23) -> 0 | BM23: =IF(AR23=0,0,AR23/AA23) -> 0 | BN23: =IF(AS23=0,0,AS23/AA23) -> 0 | BO23: =IF(AT23=0,0,AT23/AA23) -> 0 | BP23: =IF(AW23=0,0,AW23/AA23) -> 0 | BQ23: =IF(AY23+BA23+BC23=0,0,(AY23+BA23+BC23)/AA23) -> 0 | BR23: =IF(BG23=0,0,BG23/AA23) -> 0 | BS23: =SUM(BL23:BR23) -> 0 | BT23: =AA23/$AA$41 -> #DIV/0!
A24: =A23+1 -> 46158 | I24: =H24*21% -> 0 | K24: =H24+I24+J24 -> 0 | O24: =N24*21% -> 0 | P24: =+N24+O24 -> 0 | T24: =S24*21% -> 0 | U24: =SUM(S24:T24) -> 0 | Y24: =X24*21% -> 0 | Z24: =SUM(X24:Y24) -> 0 | AA24: =+K24+P24+U24-Z24 -> 0 | AG24: =AF24*220 -> 0 | AI24: =AH24*1200 -> 0 | AK24: =AJ24*1200 -> 0 | AL24: =AC24+AD24+AE24+AG24+AI24+AK24 -> 0 | AM24: =SUM(AL24-BH24) -> 0 | AP24: =AD24 | AQ24: =SUM(AR24:AS24) -> 0 | AW24: =AV24*AW$3 -> 0 | AY24: =AX24*AY$2 -> 0 | BA24: =AZ24*BA$2 -> 0 | BC24: =BB24*BC$2 -> 0 | BE24: =BD24*BE$2 -> 0 | BG24: =BF24*BG$4 -> 0 | BH24: =+AN24+AO24+AQ24+AT24+AU24+AW24+AY24+BA24+BC24+BE24+BG24 -> 0 | BI24: =AA24 -> 0 | BJ24: =SUM(BH24-BI24) -> 0 | BL24: =IF(AN24+AO24=0,0,(AN24+AO24)/AA24) -> 0 | BM24: =IF(AR24=0,0,AR24/AA24) -> 0 | BN24: =IF(AS24=0,0,AS24/AA24) -> 0 | BO24: =IF(AT24=0,0,AT24/AA24) -> 0 | BP24: =IF(AW24=0,0,AW24/AA24) -> 0 | BQ24: =IF(AY24+BA24+BC24=0,0,(AY24+BA24+BC24)/AA24) -> 0 | BR24: =IF(BG24=0,0,BG24/AA24) -> 0 | BS24: =SUM(BL24:BR24) -> 0 | BT24: =AA24/$AA$41 -> #DIV/0!
A25: =A24+1 -> 46159 | I25: =H25*21% -> 0 | K25: =H25+I25+J25 -> 0 | O25: =N25*21% -> 0 | P25: =+N25+O25 -> 0 | T25: =S25*21% -> 0 | U25: =SUM(S25:T25) -> 0 | Y25: =X25*21% -> 0 | Z25: =SUM(X25:Y25) -> 0 | AA25: =+K25+P25+U25-Z25 -> 0 | AG25: =AF25*220 -> 0 | AI25: =AH25*1200 -> 0 | AK25: =AJ25*1200 -> 0 | AL25: =AC25+AD25+AE25+AG25+AI25+AK25 -> 0 | AM25: =SUM(AL25-BH25) -> 0 | AP25: =AD25 | AQ25: =SUM(AR25:AS25) -> 0 | AW25: =AV25*AW$3 -> 0 | AY25: =AX25*AY$2 -> 0 | BA25: =AZ25*BA$2 -> 0 | BC25: =BB25*BC$2 -> 0 | BE25: =BD25*BE$2 -> 0 | BG25: =BF25*BG$4 -> 0 | BH25: =+AN25+AO25+AQ25+AT25+AU25+AW25+AY25+BA25+BC25+BE25+BG25 -> 0 | BI25: =AA25 -> 0 | BJ25: =SUM(BH25-BI25) -> 0 | BL25: =IF(AN25+AO25=0,0,(AN25+AO25)/AA25) -> 0 | BM25: =IF(AR25=0,0,AR25/AA25) -> 0 | BN25: =IF(AS25=0,0,AS25/AA25) -> 0 | BO25: =IF(AT25=0,0,AT25/AA25) -> 0 | BP25: =IF(AW25=0,0,AW25/AA25) -> 0 | BQ25: =IF(AY25+BA25+BC25=0,0,(AY25+BA25+BC25)/AA25) -> 0 | BR25: =IF(BG25=0,0,BG25/AA25) -> 0 | BS25: =SUM(BL25:BR25) -> 0 | BT25: =AA25/$AA$41 -> #DIV/0!
A26: =A25+1 -> 46160 | I26: =H26*21% -> 0 | K26: =H26+I26+J26 -> 0 | O26: =N26*21% -> 0 | P26: =+N26+O26 -> 0 | T26: =S26*21% -> 0 | U26: =SUM(S26:T26) -> 0 | Y26: =X26*21% -> 0 | Z26: =SUM(X26:Y26) -> 0 | AA26: =+K26+P26+U26-Z26 -> 0 | AG26: =AF26*220 -> 0 | AI26: =AH26*1200 -> 0 | AK26: =AJ26*1200 -> 0 | AL26: =AC26+AD26+AE26+AG26+AI26+AK26 -> 0 | AM26: =SUM(AL26-BH26) -> 0 | AP26: =AD26 | AQ26: =SUM(AR26:AS26) -> 0 | AW26: =AV26*AW$3 -> 0 | AY26: =AX26*AY$2 -> 0 | BA26: =AZ26*BA$2 -> 0 | BC26: =BB26*BC$2 -> 0 | BE26: =BD26*BE$2 -> 0 | BG26: =BF26*BG$4 -> 0 | BH26: =+AN26+AO26+AQ26+AT26+AU26+AW26+AY26+BA26+BC26+BE26+BG26 -> 0 | BI26: =AA26 -> 0 | BJ26: =SUM(BH26-BI26) -> 0 | BL26: =IF(AN26+AO26=0,0,(AN26+AO26)/AA26) -> 0 | BM26: =IF(AR26=0,0,AR26/AA26) -> 0 | BN26: =IF(AS26=0,0,AS26/AA26) -> 0 | BO26: =IF(AT26=0,0,AT26/AA26) -> 0 | BP26: =IF(AW26=0,0,AW26/AA26) -> 0 | BQ26: =IF(AY26+BA26+BC26=0,0,(AY26+BA26+BC26)/AA26) -> 0 | BR26: =IF(BG26=0,0,BG26/AA26) -> 0 | BS26: =SUM(BL26:BR26) -> 0 | BT26: =AA26/$AA$41 -> #DIV/0!
A27: =A26+1 -> 46161 | I27: =H27*21% -> 0 | K27: =H27+I27+J27 -> 0 | O27: =N27*21% -> 0 | P27: =+N27+O27 -> 0 | T27: =S27*21% -> 0 | U27: =SUM(S27:T27) -> 0 | Y27: =X27*21% -> 0 | Z27: =SUM(X27:Y27) -> 0 | AA27: =+K27+P27+U27-Z27 -> 0 | AG27: =AF27*220 -> 0 | AI27: =AH27*1200 -> 0 | AK27: =AJ27*1200 -> 0 | AL27: =AC27+AD27+AE27+AG27+AI27+AK27 -> 0 | AM27: =SUM(AL27-BH27) -> 0 | AP27: =AD27 | AQ27: =SUM(AR27:AS27) -> 0 | AW27: =AV27*AW$3 -> 0 | AY27: =AX27*AY$2 -> 0 | BA27: =AZ27*BA$2 -> 0 | BC27: =BB27*BC$2 -> 0 | BE27: =BD27*BE$2 -> 0 | BG27: =BF27*BG$4 -> 0 | BH27: =+AN27+AO27+AQ27+AT27+AU27+AW27+AY27+BA27+BC27+BE27+BG27 -> 0 | BI27: =AA27 -> 0 | BJ27: =SUM(BH27-BI27) -> 0 | BL27: =IF(AN27+AO27=0,0,(AN27+AO27)/AA27) -> 0 | BM27: =IF(AR27=0,0,AR27/AA27) -> 0 | BN27: =IF(AS27=0,0,AS27/AA27) -> 0 | BO27: =IF(AT27=0,0,AT27/AA27) -> 0 | BP27: =IF(AW27=0,0,AW27/AA27) -> 0 | BQ27: =IF(AY27+BA27+BC27=0,0,(AY27+BA27+BC27)/AA27) -> 0 | BR27: =IF(BG27=0,0,BG27/AA27) -> 0 | BS27: =SUM(BL27:BR27) -> 0 | BT27: =AA27/$AA$41 -> #DIV/0!
A28: =A27+1 -> 46162 | I28: =H28*21% -> 0 | K28: =H28+I28+J28 -> 0 | O28: =N28*21% -> 0 | P28: =+N28+O28 -> 0 | T28: =S28*21% -> 0 | U28: =SUM(S28:T28) -> 0 | Y28: =X28*21% -> 0 | Z28: =SUM(X28:Y28) -> 0 | AA28: =+K28+P28+U28-Z28 -> 0 | AG28: =AF28*220 -> 0 | AI28: =AH28*1200 -> 0 | AK28: =AJ28*1200 -> 0 | AL28: =AC28+AD28+AE28+AG28+AI28+AK28 -> 0 | AM28: =SUM(AL28-BH28) -> 0 | AP28: =AD28 | AQ28: =SUM(AR28:AS28) -> 0 | AW28: =AV28*AW$3 -> 0 | AY28: =AX28*AY$2 -> 0 | BA28: =AZ28*BA$2 -> 0 | BC28: =BB28*BC$2 -> 0 | BE28: =BD28*BE$2 -> 0 | BG28: =BF28*BG$4 -> 0 | BH28: =+AN28+AO28+AQ28+AT28+AU28+AW28+AY28+BA28+BC28+BE28+BG28 -> 0 | BI28: =AA28 -> 0 | BJ28: =SUM(BH28-BI28) -> 0 | BL28: =IF(AN28+AO28=0,0,(AN28+AO28)/AA28) -> 0 | BM28: =IF(AR28=0,0,AR28/AA28) -> 0 | BN28: =IF(AS28=0,0,AS28/AA28) -> 0 | BO28: =IF(AT28=0,0,AT28/AA28) -> 0 | BP28: =IF(AW28=0,0,AW28/AA28) -> 0 | BQ28: =IF(AY28+BA28+BC28=0,0,(AY28+BA28+BC28)/AA28) -> 0 | BR28: =IF(BG28=0,0,BG28/AA28) -> 0 | BS28: =SUM(BL28:BR28) -> 0 | BT28: =AA28/$AA$41 -> #DIV/0!
A29: =A28+1 -> 46163 | I29: =H29*21% -> 0 | K29: =H29+I29+J29 -> 0 | O29: =N29*21% -> 0 | P29: =+N29+O29 -> 0 | T29: =S29*21% -> 0 | U29: =SUM(S29:T29) -> 0 | Y29: =X29*21% -> 0 | Z29: =SUM(X29:Y29) -> 0 | AA29: =+K29+P29+U29-Z29 -> 0 | AG29: =AF29*220 -> 0 | AI29: =AH29*1200 -> 0 | AK29: =AJ29*1200 -> 0 | AL29: =AC29+AD29+AE29+AG29+AI29+AK29 -> 0 | AM29: =SUM(AL29-BH29) -> 0 | AP29: =AD29 | AQ29: =SUM(AR29:AS29) -> 0 | AW29: =AV29*AW$3 -> 0 | AY29: =AX29*AY$2 -> 0 | BA29: =AZ29*BA$2 -> 0 | BC29: =BB29*BC$2 -> 0 | BE29: =BD29*BE$2 -> 0 | BG29: =BF29*BG$4 -> 0 | BH29: =+AN29+AO29+AQ29+AT29+AU29+AW29+AY29+BA29+BC29+BE29+BG29 -> 0 | BI29: =AA29 -> 0 | BJ29: =SUM(BH29-BI29) -> 0 | BK29: =SUM(BJ9:BJ29) -> 0 | BL29: =IF(AN29+AO29=0,0,(AN29+AO29)/AA29) -> 0 | BM29: =IF(AR29=0,0,AR29/AA29) -> 0 | BN29: =IF(AS29=0,0,AS29/AA29) -> 0 | BO29: =IF(AT29=0,0,AT29/AA29) -> 0 | BP29: =IF(AW29=0,0,AW29/AA29) -> 0 | BQ29: =IF(AY29+BA29+BC29=0,0,(AY29+BA29+BC29)/AA29) -> 0 | BR29: =IF(BG29=0,0,BG29/AA29) -> 0 | BS29: =SUM(BL29:BR29) -> 0 | BT29: =AA29/$AA$41 -> #DIV/0!
A30: =A29+1 -> 46164 | I30: =H30*21% -> 0 | K30: =H30+I30+J30 -> 0 | O30: =N30*21% -> 0 | P30: =+N30+O30 -> 0 | T30: =S30*21% -> 0 | U30: =SUM(S30:T30) -> 0 | Y30: =X30*21% -> 0 | Z30: =SUM(X30:Y30) -> 0 | AA30: =+K30+P30+U30-Z30 -> 0 | AG30: =AF30*220 -> 0 | AI30: =AH30*1200 -> 0 | AK30: =AJ30*1200 -> 0 | AL30: =AC30+AD30+AE30+AG30+AI30+AK30 -> 0 | AM30: =SUM(AL30-BH30) -> 0 | AP30: =AD30 | AQ30: =SUM(AR30:AS30) -> 0 | AW30: =AV30*AW$3 -> 0 | AY30: =AX30*AY$2 -> 0 | BA30: =AZ30*BA$2 -> 0 | BC30: =BB30*BC$2 -> 0 | BE30: =BD30*BE$2 -> 0 | BG30: =BF30*BG$4 -> 0 | BH30: =+AN30+AO30+AQ30+AT30+AU30+AW30+AY30+BA30+BC30+BE30+BG30 -> 0 | BI30: =AA30 -> 0 | BJ30: =SUM(BH30-BI30) -> 0 | BL30: =IF(AN30+AO30=0,0,(AN30+AO30)/AA30) -> 0 | BM30: =IF(AR30=0,0,AR30/AA30) -> 0 | BN30: =IF(AS30=0,0,AS30/AA30) -> 0 | BO30: =IF(AT30=0,0,AT30/AA30) -> 0 | BP30: =IF(AW30=0,0,AW30/AA30) -> 0 | BQ30: =IF(AY30+BA30+BC30=0,0,(AY30+BA30+BC30)/AA30) -> 0 | BR30: =IF(BG30=0,0,BG30/AA30) -> 0 | BS30: =SUM(BL30:BR30) -> 0 | BT30: =AA30/$AA$41 -> #DIV/0!
A31: =A30+1 -> 46165 | I31: =H31*21% -> 0 | K31: =H31+I31+J31 -> 0 | O31: =N31*21% -> 0 | P31: =+N31+O31 -> 0 | T31: =S31*21% -> 0 | U31: =SUM(S31:T31) -> 0 | Y31: =X31*21% -> 0 | Z31: =SUM(X31:Y31) -> 0 | AA31: =+K31+P31+U31-Z31 -> 0 | AG31: =AF31*220 -> 0 | AI31: =AH31*1200 -> 0 | AK31: =AJ31*1200 -> 0 | AL31: =AC31+AD31+AE31+AG31+AI31+AK31 -> 0 | AM31: =SUM(AL31-BH31) -> 0 | AP31: =AD31 | AQ31: =SUM(AR31:AS31) -> 0 | AW31: =AV31*AW$3 -> 0 | AY31: =AX31*AY$2 -> 0 | BA31: =AZ31*BA$2 -> 0 | BC31: =BB31*BC$2 -> 0 | BE31: =BD31*BE$2 -> 0 | BG31: =BF31*BG$4 -> 0 | BH31: =+AN31+AO31+AQ31+AT31+AU31+AW31+AY31+BA31+BC31+BE31+BG31 -> 0 | BI31: =AA31 -> 0 | BJ31: =SUM(BH31-BI31) -> 0 | BL31: =IF(AN31+AO31=0,0,(AN31+AO31)/AA31) -> 0 | BM31: =IF(AR31=0,0,AR31/AA31) -> 0 | BN31: =IF(AS31=0,0,AS31/AA31) -> 0 | BO31: =IF(AT31=0,0,AT31/AA31) -> 0 | BP31: =IF(AW31=0,0,AW31/AA31) -> 0 | BQ31: =IF(AY31+BA31+BC31=0,0,(AY31+BA31+BC31)/AA31) -> 0 | BR31: =IF(BG31=0,0,BG31/AA31) -> 0 | BS31: =SUM(BL31:BR31) -> 0 | BT31: =AA31/$AA$41 -> #DIV/0!
