Workbook

Sheet junio 2026
B2: TIENDA | C2: Venta | D2: Sueldos | E2: Alquileres | F2: Expensas | G2: Total_alquileres+expensas | H2: Otros_gastos
B3: Florida | C3: 34652652 | D3: 5097043.9 | E3: 7325000 | F3: 482850.5 | G3: 7807850.5 | H3: 2955396.8
B4: Recoleta | C4: 20340886 | D4: 5697753.3 | E4: 2504086.5 | F4: 2407649.6 | G4: 4911736.1 | H4: 369356.47
B5: Lucero_Zona Centro | C5: 54993538 | D5: 10794797 | E5: 9829086.5 | F5: 2890500.1 | G5: 12719587 | H5: 3324753.2
B6: San Telmo | C6: 24815646 | D6: 3798819.7 | E6: 2204956.6 | F6: 672700.36 | G6: 2877657 | H6: 298106.64
B7: French | C7: 16141614 | D7: 3364928.1 | E7: 1002486.6 | F7: 300750 | G7: 1303236.6 | H7: 561863.97
B8: Lucero_Zona San Telmo | C8: 40957260 | D8: 7163747.8 | E8: 3207443.2 | F8: 973450.36 | G8: 4180893.6 | H8: 859970.61
B9: Güemes | C9: 2753095.3 | D9: 1800413.9 | E9: 798015.19 | F9: 372568.23 | G9: 1170583.4 | H9: 311502
B10: San Telmo 2 | C10: 2768399.9 | D10: 3634013.1 | E10: 1079060 | F10: 672700.36 | G10: 1751760.4 | H10: 310276.85
B11: Lucero_Güemes+San Telmo 2 | C11: 5521495.3 | D11: 5434426.9 | E11: 1877075.2 | F11: 1045268.6 | G11: 2922343.8 | H11: 621778.85
B12: Güemes 2 | C12: 7504369.8 | D12: 3681519.1 | E12: 589066.89 | F12: 57000.46 | G12: 646067.35 | H12: 81624.85
B13: El Solar | C13: 7338710.3 | D13: 4333806.5 | E13: 1822860.5 | F13: 184127.32 | G13: 2006987.8 | H13: 47124.76
B14: Lucero Joyería | C14: 14843080 | D14: 8015325.5 | E14: 2411927.4 | F14: 241127.78 | G14: 2653055.1 | H14: 128749.61
... B16: Total general | C16: 1.2810551e+08 | D16: 34973324 | E16: 18567437 | F16: 6495747.6 | G16: 25063185 | H16: 5367972.3
B18: Tienda_Zona | C18: Sueldos | D18: Alquileres | E18: Expensas | F18: Total alquileres + expensas | G18: Otros gastos
B19: Florida | C19: =D3/$C3 -> 0.14708958 | D19: =E3/$C3 -> 0.21138353 | E19: =D3/$C3 -> 0.14708958 | F19: =E3/$C3 -> 0.21138353 | G19: =F3/$C3 -> 0.013934013
B20: Recoleta | C20: =D4/$C4 -> 0.28011333 | D20: =E4/$C4 -> 0.12310607 | E20: =D4/$C4 -> 0.28011333 | F20: =E4/$C4 -> 0.12310607 | G20: =F4/$C4 -> 0.11836503
B21: Lucero_Zona Centro | C21: =D5/$C5 -> 0.1962921 | D21: =E5/$C5 -> 0.17873166 | E21: =D5/$C5 -> 0.1962921 | F21: =E5/$C5 -> 0.17873166 | G21: =F5/$C5 -> 0.052560723
B22: San Telmo | C22: =D6/$C6 -> 0.15308163 | D22: =E6/$C6 -> 0.088853485 | E22: =D6/$C6 -> 0.15308163 | F22: =E6/$C6 -> 0.088853485 | G22: =F6/$C6 -> 0.027107912
B23: French | C23: =D7/$C7 -> 0.20846293 | D23: =E7/$C7 -> 0.062105723 | E23: =D7/$C7 -> 0.20846293 | F23: =E7/$C7 -> 0.062105723 | G23: =F7/$C7 -> 0.018631966
B24: Lucero_Zona San Telmo | C24: =D8/$C8 -> 0.17490789 | D24: =E8/$C8 -> 0.078311959 | E24: =D8/$C8 -> 0.17490789 | F24: =E8/$C8 -> 0.078311959 | G24: =F8/$C8 -> 0.023767468
B25: Güemes | C25: =D9/$C9 -> 0.65395987 | D25: =E9/$C9 -> 0.28986108 | E25: =D9/$C9 -> 0.65395987 | F25: =E9/$C9 -> 0.28986108 | G25: =F9/$C9 -> 0.13532704
B26: San Telmo 2 | C26: =D10/$C10 -> 1.3126763 | D26: =E10/$C10 -> 0.3897775 | E26: =D10/$C10 -> 1.3126763 | F26: =E10/$C10 -> 0.3897775 | G26: =F10/$C10 -> 0.24299248
B27: Lucero_Güemes+San Telmo 2 | C27: =D11/$C11 -> 0.98423102 | D27: =E11/$C11 -> 0.33995776 | E27: =D11/$C11 -> 0.98423102 | F27: =E11/$C11 -> 0.33995776 | G27: =F11/$C11 -> 0.18930897
B28: Güemes 2 | C28: =D12/$C12 -> 0.49058337 | D28: =E12/$C12 -> 0.078496516 | E28: =D12/$C12 -> 0.49058337 | F28: =E12/$C12 -> 0.078496516 | G28: =F12/$C12 -> 0.0075956358
B29: El Solar | C29: =D13/$C13 -> 0.59054061 | D29: =E13/$C13 -> 0.24838976 | E29: =D13/$C13 -> 0.59054061 | F29: =E13/$C13 -> 0.24838976 | G29: =F13/$C13 -> 0.025089874
B30: Lucero Joyería | C30: =D14/$C14 -> 0.54000419 | D30: =E14/$C14 -> 0.16249507 | E30: =D14/$C14 -> 0.54000419 | F30: =E14/$C14 -> 0.16249507 | G30: =F14/$C14 -> 0.016245131
... B32: Total general | C32: =D16/$C16 -> 0.27300405 | D32: =E16/$C16 -> 0.14493863 | E32: =D16/$C16 -> 0.27300405 | F32: =E16/$C16 -> 0.14493863 | G32: =F16/$C16 -> 0.050706231

Sheet mayo 2026
B2: TIENDA | C2: Venta | D2: Sueldos | E2: Alquileres | F2: Expensas | G2: Total_alquileres+expensas | H2: Otros_gastos
B3: Florida | C3: 46311462 | D3: 6677551.9 | E3: 7050000 | F3: 381156.89 | G3: 7431156.9 | H3: 2189051.7
B4: Recoleta | C4: 14240375 | D4: 4062211 | E4: 2504086.5 | F4: 2420500.3 | G4: 4924586.8 | H4: 407998.9
B5: Lucero_Zona Centro | C5: 60551837 | D5: 10739763 | E5: 9554086.5 | F5: 2801657.1 | G5: 12355744 | H5: 2597050.6
B6: San Telmo | C6: 33349970 | D6: 3738132.4 | E6: 2056151.5 | F6: 672700.36 | G6: 2728851.9 | H6: 346009.13
B7: French | C7: 19982041 | D7: 3352593.3 | E7: 923100 | F7: 290225.35 | G7: 1213325.4 | H7: 524638.93
B8: Lucero_Zona San Telmo | C8: 53332011 | D8: 7090725.7 | E8: 2979251.5 | F8: 962925.71 | G8: 3942177.2 | H8: 870648.06
B9: Güemes | C9: 1967146.4 | D9: 1325711.2 | E9: 715965.54 | F9: 383750.2 | G9: 1099715.7 | H9: 321670
B10: San Telmo 2 | C10: 4196030 | D10: 3082313.5 | E10: 1079060 | F10: 672700.36 | G10: 1751760.4 | H10: 257897.74
B11: Lucero_Güemes+San Telmo 2 | C11: 6163176.4 | D11: 4408024.7 | E11: 1795025.5 | F11: 1056450.6 | G11: 2851476.1 | H11: 579567.74
B12: Güemes 2 | C12: 7131739.9 | D12: 2173173.7 | E12: 565405.38 | F12: 58711.23 | G12: 624116.61 | H12: 130390.4
B13: El Solar | C13: 8053769.9 | D13: 4767586.3 | E13: 1822860.5 | F13: 184127.32 | G13: 2006987.8 | H13: 46309.06
B14: Lucero Joyería | C14: 15185510 | D14: 6940760 | E14: 2388265.9 | F14: 242838.55 | G14: 2631104.4 | H14: 176699.46
... B16: Total general | C16: 1.5192925e+08 | D16: 32596127 | E16: 17763721 | F16: 6409272.7 | G16: 24172994 | H16: 4601276.3
B18: Tienda_Zona | C18: Sueldos | D18: Alquileres | E18: Expensas | F18: Total alquileres + expensas | G18: Otros gastos
B19: Florida | C19: =D3/$C3 -> 0.14418789 | D19: =E3/$C3 -> 0.15223013 | E19: =F3/$C3 -> 0.0082302927 | F19: =G3/$C3 -> 0.16046042 | G19: =H3/$C3 -> 0.047268033
B20: Recoleta | C20: =D4/$C4 -> 0.28526011 | D20: =E4/$C4 -> 0.17584414 | E20: =F4/$C4 -> 0.16997447 | F20: =G4/$C4 -> 0.34581861 | G20: =H4/$C4 -> 0.028650853
B21: Lucero_Zona Centro | C21: =D5/$C5 -> 0.17736477 | D21: =E5/$C5 -> 0.15778359 | E21: =F5/$C5 -> 0.046268739 | F21: =G5/$C5 -> 0.20405233 | G21: =H5/$C5 -> 0.042889708
B22: San Telmo | C22: =D6/$C6 -> 0.11208803 | D22: =E6/$C6 -> 0.061653774 | E22: =F6/$C6 -> 0.020170944 | F22: =G6/$C6 -> 0.081824718 | G22: =H6/$C6 -> 0.010375096
B23: French | C23: =D7/$C7 -> 0.16778033 | D23: =E7/$C7 -> 0.046196483 | E23: =F7/$C7 -> 0.01452431 | F23: =G7/$C7 -> 0.060720793 | G23: =H7/$C7 -> 0.026255523
B24: Lucero_Zona San Telmo | C24: =D8/$C8 -> 0.1329544 | D24: =E8/$C8 -> 0.055862352 | E24: =F8/$C8 -> 0.018055305 | F24: =G8/$C8 -> 0.073917656 | G24: =H8/$C8 -> 0.016325056
B25: Güemes | C25: =D9/$C9 -> 0.67392606 | D25: =E9/$C9 -> 0.36396149 | E25: =F9/$C9 -> 0.19507963 | F25: =G9/$C9 -> 0.55904113 | G25: =H9/$C9 -> 0.16352113
B26: San Telmo 2 | C26: =D10/$C10 -> 0.7345785 | D26: =E10/$C10 -> 0.25716213 | E26: =F10/$C10 -> 0.16031829 | F26: =G10/$C10 -> 0.41748042 | G26: =H10/$C10 -> 0.06146232
B27: Lucero_Güemes+San Telmo 2 | C27: =D11/$C11 -> 0.71521962 | D27: =E11/$C11 -> 0.29125007 | E27: =F11/$C11 -> 0.17141332 | F27: =G11/$C11 -> 0.46266339 | G27: =H11/$C11 -> 0.094037181
B28: Güemes 2 | C28: =D12/$C12 -> 0.30471859 | D28: =E12/$C12 -> 0.079280146 | E28: =F12/$C12 -> 0.0082323852 | F28: =G12/$C12 -> 0.087512531 | G28: =H12/$C12 -> 0.018283112
B29: El Solar | C29: =D13/$C13 -> 0.59196952 | D29: =E13/$C13 -> 0.2263363 | E29: =F13/$C13 -> 0.022862252 | F29: =G13/$C13 -> 0.24919855 | G29: =H13/$C13 -> 0.0057499855
B30: Lucero Joyería | C30: =D14/$C14 -> 0.45706467 | D30: =E14/$C14 -> 0.15727268 | E30: =F14/$C14 -> 0.015991465 | F30: =G14/$C14 -> 0.17326415 | G30: =H14/$C14 -> 0.011636057
... B32: Total general | C32: =D16/$C16 -> 0.21454807 | D32: =E16/$C16 -> 0.11692101 | E32: =F16/$C16 -> 0.042185904 | F32: =G16/$C16 -> 0.15910691 | G32: =H16/$C16 -> 0.030285652

Sheet abril 2026
B2: TIENDA | C2: Venta | D2: Sueldos | E2: Alquileres | F2: Expensas | G2: Total_alquileres+expensas | H2: Otros_gastos
B3: Florida | C3: 50187137 | D3: 6457325.6 | E3: 6900000 | F3: 482850.5 | G3: 7382850.5 | H3: 2450130.5
B4: Recoleta | C4: 20708446 | D4: 3889349.6 | E4: 2504086.5 | F4: 2350582.7 | G4: 4854669.2 | H4: 394599.88
B5: Lucero_Zona Centro | C5: 70895584 | D5: 10346675 | E5: 9404086.5 | F5: 2833433.2 | G5: 12237520 | H5: 2844730.4
B6: San Telmo | C6: 31099293 | D6: 3977837.8 | E6: 2239641 | F6: 671764.67 | G6: 2911405.6 | H6: 429067.75
B7: French | C7: 15741035 | D7: 3131288.5 | E7: 923100 | F7: 298257.44 | G7: 1221357.4 | H7: 510093.31
B8: Lucero_Zona San Telmo | C8: 46840328 | D8: 7109126.4 | E8: 3162741 | F8: 970022.11 | G8: 4132763.1 | H8: 939161.06
B9: Güemes | C9: 3226471.9 | D9: 1754163.6 | E9: 715965.54 | F9: 327251.57 | G9: 1043217.1 | H9: 332449.9
B10: San Telmo 2 | C10: 10134262 | D10: 3022479.2 | E10: 1230248.2 | F10: 671764.67 | G10: 1902012.9 | H10: 279131
B11: Lucero_Güemes+San Telmo 2 | C11: 13360734 | D11: 4776642.8 | E11: 1946213.7 | F11: 999016.24 | G11: 2945230 | H11: 611580.9
B12: Güemes 2 | C12: 7638188.2 | D12: 2484034.2 | E12: 536812.83 | F12: 50067.31 | G12: 586880.14 | H12: 71633.13
B13: El Solar | C13: 10038251 | D13: 4431995.8 | E13: 1872828.4 | F13: 173089.62 | G13: 2045918.1 | H13: 44070.92
B14: Lucero Joyería | C14: 17676439 | D14: 6916030 | E14: 2409641.3 | F14: 223156.93 | G14: 2632798.2 | H14: 115704.05
... B16: Total general | C16: 1.6284518e+08 | D16: 32686737 | E16: 18012553 | F16: 6369157.8 | G16: 24381711 | H16: 5095623.2
B18: Tienda_Zona | C18: Sueldos | D18: Alquileres | E18: Expensas | F18: Total alquileres + expensas | G18: Otros gastos
B19: Florida | C19: =D3/$C3 -> 0.12866495 | D19: =E3/$C3 -> 0.13748543 | E19: =F3/$C3 -> 0.009621001 | F19: =G3/$C3 -> 0.14710643 | G19: =H3/$C3 -> 0.04881989
B20: Recoleta | C20: =D4/$C4 -> 0.18781465 | D20: =E4/$C4 -> 0.12092102 | E20: =F4/$C4 -> 0.11350841 | F20: =G4/$C4 -> 0.23442943 | G20: =H4/$C4 -> 0.019055021
B21: Lucero_Zona Centro | C21: =D5/$C5 -> 0.14594245 | D21: =E5/$C5 -> 0.132647 | E21: =F5/$C5 -> 0.039966287 | F21: =G5/$C5 -> 0.17261329 | G21: =H5/$C5 -> 0.040125636
B22: San Telmo | C22: =D6/$C6 -> 0.12790766 | D22: =E6/$C6 -> 0.072015816 | E22: =F6/$C6 -> 0.021600641 | F22: =G6/$C6 -> 0.093616457 | G22: =H6/$C6 -> 0.013796704
B23: French | C23: =D7/$C7 -> 0.1989252 | D23: =E7/$C7 -> 0.058642902 | E23: =F7/$C7 -> 0.018947765 | F23: =G7/$C7 -> 0.077590668 | G23: =H7/$C7 -> 0.032405321
B24: Lucero_Zona San Telmo | C24: =D8/$C8 -> 0.15177362 | D24: =E8/$C8 -> 0.06752175 | E24: =F8/$C8 -> 0.020709123 | F24: =G8/$C8 -> 0.088230873 | G24: =H8/$C8 -> 0.020050266
B25: Güemes | C25: =D9/$C9 -> 0.54367855 | D25: =E9/$C9 -> 0.22190354 | E25: =F9/$C9 -> 0.10142706 | F25: =G9/$C9 -> 0.32333061 | G25: =H9/$C9 -> 0.10303821
B26: San Telmo 2 | C26: =D10/$C10 -> 0.29824365 | D26: =E10/$C10 -> 0.12139495 | E26: =F10/$C10 -> 0.066286491 | F26: =G10/$C10 -> 0.18768144 | G26: =H10/$C10 -> 0.027543298
B27: Lucero_Güemes+San Telmo 2 | C27: =D11/$C11 -> 0.35751351 | D27: =E11/$C11 -> 0.14566668 | E27: =F11/$C11 -> 0.074772557 | F27: =G11/$C11 -> 0.22043924 | G27: =H11/$C11 -> 0.045774499
B28: Güemes 2 | C28: =D12/$C12 -> 0.32521249 | D28: =E12/$C12 -> 0.070280126 | E28: =F12/$C12 -> 0.0065548673 | F28: =G12/$C12 -> 0.076834994 | G28: =H12/$C12 -> 0.0093782882
B29: El Solar | C29: =D13/$C13 -> 0.44151075 | D29: =E13/$C13 -> 0.18656919 | E29: =F13/$C13 -> 0.017243006 | F29: =G13/$C13 -> 0.2038122 | G29: =H13/$C13 -> 0.0043902986
B30: Lucero Joyería | C30: =D14/$C14 -> 0.39125696 | D30: =E14/$C14 -> 0.13631938 | E30: =F14/$C14 -> 0.012624541 | F30: =G14/$C14 -> 0.14894392 | G30: =H14/$C14 -> 0.006545665
... B32: Total general | C32: =D16/$C16 -> 0.20072278 | D32: =E16/$C16 -> 0.11061152 | E32: =F16/$C16 -> 0.039111737 | F32: =G16/$C16 -> 0.14972326 | G32: =H16/$C16 -> 0.031291213

Sheet marzo 2026
C1: =1335 -> 1335
B2: Tienda_Zona | C2: Venta | D2: Sueldos | E2: Alquileres | F2: Expensas | G2: Total alquileres + expensas | H2: Otros gastos
B3: Florida | C3: 63788151 | D3: 5789234.2 | E3: 7100000 | F3: 482850.5 | G3: 7582850.5 | H3: 2290137.1
B4: Recoleta | C4: 29608258 | D4: 3538018.2 | E4: 2300000 | F4: 2262542.1 | G4: 4562542.1 | H4: 417466.31
B5: Lucero_Zona Centro | C5: 93396408 | D5: 9327252.4 | E5: 9400000 | F5: 2745392.6 | G5: 12145393 | H5: 2707603.4
B6: San Telmo | C6: 33874570 | D6: 3332241.1 | E6: 2012472 | F6: 599981.67 | G6: 2612453.7 | H6: 352366.35
B7: French | C7: 22059684 | D7: 3016698.5 | E7: 923100 | F7: 319028.67 | G7: 1242128.7 | H7: 557100.82
B8: Lucero_Zona San Telmo | C8: 55934254 | D8: 6348939.6 | E8: 2935572 | F8: 919010.34 | G8: 3854582.3 | H8: 909467.17
B9: Güemes | C9: 3804986.8 | D9: 2064206.9 | E9: 715965.54 | F9: 373918.78 | G9: 1089884.3 | H9: 378712
B10: San Telmo 2 | C10: 15136894 | D10: 2666231 | E10: 1070367.2 | F10: 599981.67 | G10: 1670348.9 | H10: 368667.34
B11: Lucero_Güemes+San Telmo 2 | C11: 18941881 | D11: 4730437.9 | E11: 1786332.7 | F11: 973900.45 | G11: 2760233.2 | H11: 747379.34
B12: Güemes 2 | C12: 8695899.9 | D12: 2254785.2 | E12: 583226.46 | F12: 57207.09 | G12: 640433.55 | H12: 73091.13
B13: El Solar | C13: 10328000 | D13: 3723645.2 | E13: 1872828.4 | F13: 173089.62 | G13: 2045918.1 | H13: 43291.42
B14: Lucero Joyería | C14: 19023900 | D14: 5978430.4 | E14: 2456054.9 | F14: 230296.71 | G14: 2686351.6 | H14: 116382.55
... B16: Total general | C16: 2.0194914e+08 | D16: 29484561 | E16: 17604354 | F16: 6068563.4 | G16: 23672917 | H16: 4965836.9
B18: Tienda_Zona | C18: Sueldos | D18: Alquileres | E18: Expensas | F18: Total alquileres + expensas | G18: Otros gastos
B19: Florida | C19: =D3/$C3 -> 0.090757205 | D19: =E3/$C3 -> 0.11130594 | E19: =F3/$C3 -> 0.0075695955 | F19: =G3/$C3 -> 0.11887553 | G19: =H3/$C3 -> 0.035902234
B20: Recoleta | C20: =D4/$C4 -> 0.11949431 | D20: =E4/$C4 -> 0.077681032 | E20: =F4/$C4 -> 0.076415914 | F20: =G4/$C4 -> 0.15409695 | G20: =H4/$C4 -> 0.014099658
B21: Lucero_Zona Centro | C21: =D5/$C5 -> 0.099867357 | D21: =E5/$C5 -> 0.10064627 | E21: =F5/$C5 -> 0.029395055 | F21: =G5/$C5 -> 0.13004132 | G21: =H5/$C5 -> 0.028990445
B22: San Telmo | C22: =D6/$C6 -> 0.098369989 | D22: =E6/$C6 -> 0.059409522 | E22: =F6/$C6 -> 0.017711861 | F22: =G6/$C6 -> 0.077121382 | G22: =H6/$C6 -> 0.010402091
B23: French | C23: =D7/$C7 -> 0.13675167 | D23: =E7/$C7 -> 0.041845568 | E23: =F7/$C7 -> 0.014462069 | F23: =G7/$C7 -> 0.056307637 | G23: =H7/$C7 -> 0.025254252
B24: Lucero_Zona San Telmo | C24: =D8/$C8 -> 0.11350718 | D24: =E8/$C8 -> 0.052482545 | E24: =F8/$C8 -> 0.016430189 | F24: =G8/$C8 -> 0.068912734 | G24: =H8/$C8 -> 0.016259575
B25: Güemes | C25: =D9/$C9 -> 0.54250042 | D25: =E9/$C9 -> 0.18816505 | E25: =F9/$C9 -> 0.098270716 | F25: =G9/$C9 -> 0.28643577 | G25: =H9/$C9 -> 0.099530436
B26: San Telmo 2 | C26: =D10/$C10 -> 0.17614122 | D26: =E10/$C10 -> 0.070712472 | E26: =F10/$C10 -> 0.03963704 | F26: =G10/$C10 -> 0.11034951 | G26: =H10/$C10 -> 0.024355547
B27: Lucero_Güemes+San Telmo 2 | C27: =D11/$C11 -> 0.24973433 | D27: =E11/$C11 -> 0.094305985 | E27: =F11/$C11 -> 0.051415192 | F27: =G11/$C11 -> 0.14572118 | G27: =H11/$C11 -> 0.039456448
B28: Güemes 2 | C28: =D12/$C12 -> 0.25929291 | D28: =E12/$C12 -> 0.067069133 | E28: =F12/$C12 -> 0.006578628 | F28: =G12/$C12 -> 0.07364776 | G28: =H12/$C12 -> 0.0084052405
B29: El Solar | C29: =D13/$C13 -> 0.36053886 | D29: =E13/$C13 -> 0.18133506 | E29: =F13/$C13 -> 0.016759259 | F29: =G13/$C13 -> 0.19809432 | G29: =H13/$C13 -> 0.0041916558
B30: Lucero Joyería | C30: =D14/$C14 -> 0.31425893 | D30: =E14/$C14 -> 0.12910365 | E30: =F14/$C14 -> 0.012105652 | F30: =G14/$C14 -> 0.1412093 | G30: =H14/$C14 -> 0.0061177021
... B32: Total general | C32: =D16/$C16 -> 0.14599993 | D32: =E16/$C16 -> 0.087172216 | E32: =F16/$C16 -> 0.030049959 | F32: =G16/$C16 -> 0.11722218 | G32: =H16/$C16 -> 0.024589542

Sheet febrero 2026
C1: =1335 -> 1335
B2: Tienda_Zona | C2: Venta | D2: Sueldos | E2: Alquileres | F2: Expensas | G2: Total alquileres + expensas | H2: Otros gastos
B3: Florida | C3: 56105566 | D3: 5348154.3 | E3: 7100000 | F3: 482850.5 | G3: 7582850.5 | H3: 2075480.1
B4: Recoleta | C4: 20943355 | D4: 3256861.3 | E4: 2300000 | F4: 2339286.6 | G4: 4639286.6 | H4: 505129.77
B5: Lucero_Zona Centro | C5: 77048921 | D5: 8605015.6 | E5: 9400000 | F5: 2822137.1 | G5: 12222137 | H5: 2580609.9
B6: San Telmo | C6: 30438640 | D6: 3337332.3 | E6: 2622347 | F6: 576451.13 | G6: 3198798.2 | H6: 360694.71
B7: French | C7: 16278682 | D7: 2878986.9 | E7: 850000 | F7: 334847.68 | G7: 1184847.7 | H7: 1013046.5
B8: Lucero_Zona San Telmo | C8: 46717322 | D8: 6216319.2 | E8: 3472347 | F8: 911298.81 | G8: 4383645.8 | H8: 1373741.2
B9: Güemes | C9: 2967396.8 | D9: 1665379.7 | E9: 715965.54 | F9: 372670.03 | G9: 1088635.6 | H9: 316430
B10: San Telmo 2 | C10: 12951444 | D10: 2674137.9 | E10: 1473060.3 | F10: 576451.13 | G10: 2049511.4 | H10: 389877.91
B11: Lucero_Güemes+San Telmo 2 | C11: 15918841 | D11: 4339517.6 | E11: 2189025.8 | F11: 949121.16 | G11: 3138147 | H11: 706307.91
B12: Güemes 2 | C12: 9447799.9 | D12: 1907298.4 | E12: 511403.96 | F12: 57016.04 | G12: 568420 | H12: 71157.4
B13: El Solar | C13: 7961629.9 | D13: 3366978.3 | E13: 1619513.2 | F13: 163587.19 | G13: 1783100.4 | H13: 42642.82
B14: Lucero Joyería | C14: 17409430 | D14: 5274276.6 | E14: 2130917.1 | F14: 220603.23 | G14: 2351520.4 | H14: 113800.22
... B16: Total general | C16: 1.7089381e+08 | D16: 27620766 | E16: 18391591 | F16: 6056062.6 | G16: 24447653 | H16: 5240382.1
B18: Tienda_Zona | C18: Sueldos | D18: Alquileres | E18: Expensas | F18: Total alquileres + expensas | G18: Otros gastos
B19: Florida | C19: =D3/$C3 -> 0.09532306 | D19: =E3/$C3 -> 0.12654716 | E19: =F3/$C3 -> 0.0086061069 | F19: =G3/$C3 -> 0.13515327 | G19: =H3/$C3 -> 0.03699241
B20: Recoleta | C20: =D4/$C4 -> 0.1555081 | D20: =E4/$C4 -> 0.10982003 | E20: =F4/$C4 -> 0.11169589 | F20: =G4/$C4 -> 0.22151592 | G20: =H4/$C4 -> 0.024118856
B21: Lucero_Zona Centro | C21: =D5/$C5 -> 0.11168249 | D21: =E5/$C5 -> 0.12200041 | E21: =F5/$C5 -> 0.03662786 | F21: =G5/$C5 -> 0.15862827 | G21: =H5/$C5 -> 0.033493135
B22: San Telmo | C22: =D6/$C6 -> 0.10964131 | D22: =E6/$C6 -> 0.086151912 | E22: =F6/$C6 -> 0.018938137 | F22: =G6/$C6 -> 0.10509005 | G22: =H6/$C6 -> 0.011849896
B23: French | C23: =D7/$C7 -> 0.17685627 | D23: =E7/$C7 -> 0.05221553 | E23: =F7/$C7 -> 0.020569705 | F23: =G7/$C7 -> 0.072785235 | G23: =H7/$C7 -> 0.062231483
B24: Lucero_Zona San Telmo | C24: =D8/$C8 -> 0.1330624 | D24: =E8/$C8 -> 0.074326757 | E24: =F8/$C8 -> 0.019506658 | F24: =G8/$C8 -> 0.093833415 | G24: =H8/$C8 -> 0.029405393
B25: Güemes | C25: =D9/$C9 -> 0.56122582 | D25: =E9/$C9 -> 0.24127732 | E25: =F9/$C9 -> 0.1255882 | F25: =G9/$C9 -> 0.36686552 | G25: =H9/$C9 -> 0.10663555
B26: San Telmo 2 | C26: =D10/$C10 -> 0.20647411 | D26: =E10/$C10 -> 0.11373715 | E26: =F10/$C10 -> 0.044508638 | F26: =G10/$C10 -> 0.15824579 | G26: =H10/$C10 -> 0.030103046
B27: Lucero_Güemes+San Telmo 2 | C27: =D11/$C11 -> 0.27260261 | D27: =E11/$C11 -> 0.13751164 | E27: =F11/$C11 -> 0.059622505 | F27: =G11/$C11 -> 0.19713414 | G27: =H11/$C11 -> 0.044369305
B28: Güemes 2 | C28: =D12/$C12 -> 0.20187752 | D28: =E12/$C12 -> 0.054129424 | E28: =F12/$C12 -> 0.0060348484 | F28: =G12/$C12 -> 0.060164272 | G28: =H12/$C12 -> 0.0075316371
B29: El Solar | C29: =D13/$C13 -> 0.42290062 | D29: =E13/$C13 -> 0.20341478 | E29: =F13/$C13 -> 0.020546947 | F29: =G13/$C13 -> 0.22396172 | G29: =H13/$C13 -> 0.0053560415
B30: Lucero Joyería | C30: =D14/$C14 -> 0.30295516 | D30: =E14/$C14 -> 0.12240017 | E30: =F14/$C14 -> 0.012671479 | F30: =G14/$C14 -> 0.13507165 | G30: =H14/$C14 -> 0.0065367
... B32: Total general | C32: =D16/$C16 -> 0.16162531 | D32: =E16/$C16 -> 0.10761999 | E32: =F16/$C16 -> 0.035437577 | F32: =G16/$C16 -> 0.14305757 | G32: =H16/$C16 -> 0.030664552

Sheet enero 2026
C1: =1335 -> 1335
B2: Tienda_Zona | C2: Venta | D2: Sueldos | E2: Alquileres | F2: Expensas | G2: Total alquileres + expensas | H2: Otros gastos
B3: Florida | C3: 49769692 | D3: 5886604.4 | E3: 7525000 | F3: 482850.5 | G3: 8007850.5 | H3: 1912542.8
B4: Recoleta | C4: 25475593 | D4: 3367054.2 | E4: 2451875.2 | F4: 2223483.5 | G4: 4675358.7 | H4: 339520.31
B5: Lucero_Zona Centro | C5: 75245286 | D5: 9253658.6 | E5: 9976875.2 | F5: 2706334 | G5: 12683209 | H5: 2252063.1
B6: San Telmo | C6: 39663000 | D6: 4129920.5 | E6: 3323410.5 | F6: 576451.13 | G6: 3899861.6 | H6: 2698204.6
B7: French | C7: 21769882 | D7: 2821120 | E7: 850000 | F7: 279156.28 | G7: 1129156.3 | H7: 600917.63
B8: Lucero_Zona San Telmo | C8: 61432882 | D8: 6951040.5 | E8: 4173410.5 | F8: 855607.41 | G8: 5029017.9 | H8: 3299122.2
B9: Güemes | C9: 3623340 | D9: 1936660.8 | E9: 645479.21 | F9: 373255.01 | G9: 1018734.2 | H9: 310950
B10: San Telmo 2 | C10: 17824030 | D10: 2718682.2 | E10: 1374452 | F10: 576451.13 | G10: 1950903.1 | H10: 304572.59
B11: Lucero_Güemes+San Telmo 2 | C11: 21447370 | D11: 4655343.1 | E11: 2019931.2 | F11: 949706.14 | G11: 2969637.4 | H11: 615522.59
B12: Güemes 2 | C12: 4982999.9 | D12: 2638595.6 | E12: 461056.58 | F12: 57105.53 | G12: 518162.11 | H12: 51993.41
B13: El Solar | C13: 4959712.8 | D13: 3586986.5 | E13: 1619513.2 | F13: 163587.19 | G13: 1783100.4 | H13: 21219.18
B14: Lucero Joyería | C14: 9942712.7 | D14: 6225582.1 | E14: 2080569.8 | F14: 220692.72 | G14: 2301262.5 | H14: 73212.59
... B16: Total general | C16: 1.8419417e+08 | D16: 30852806 | E16: 19620684 | F16: 5885242.5 | G16: 25505927 | H16: 6566329.3
B18: Tienda_Zona | C18: Sueldos | D18: Alquileres | E18: Expensas | F18: Total alquileres + expensas | G18: Otros gastos
B19: Florida | C19: =D3/$C3 -> 0.11827689 | D19: =E3/$C3 -> 0.15119643 | E19: =F3/$C3 -> 0.0097016975 | F19: =G3/$C3 -> 0.16089813 | G19: =H3/$C3 -> 0.038427861
B20: Recoleta | C20: =D4/$C4 -> 0.13216784 | D20: =E4/$C4 -> 0.096244084 | E20: =F4/$C4 -> 0.087278969 | F20: =G4/$C4 -> 0.18352305 | G20: =H4/$C4 -> 0.013327278
B21: Lucero_Zona Centro | C21: =D5/$C5 -> 0.12297991 | D21: =E5/$C5 -> 0.13259137 | E21: =F5/$C5 -> 0.035966825 | F21: =G5/$C5 -> 0.16855819 | G21: =H5/$C5 -> 0.029929624
B22: San Telmo | C22: =D6/$C6 -> 0.10412527 | D22: =E6/$C6 -> 0.083791203 | E22: =F6/$C6 -> 0.014533725 | F22: =G6/$C6 -> 0.098324928 | G22: =H6/$C6 -> 0.068028253
B23: French | C23: =D7/$C7 -> 0.12958821 | D23: =E7/$C7 -> 0.039044768 | E23: =F7/$C7 -> 0.01282305 | F23: =G7/$C7 -> 0.051867818 | G23: =H7/$C7 -> 0.027603164
B24: Lucero_Zona San Telmo | C24: =D8/$C8 -> 0.11314853 | D24: =E8/$C8 -> 0.067934473 | E24: =F8/$C8 -> 0.013927515 | F24: =G8/$C8 -> 0.081861989 | G24: =H8/$C8 -> 0.053702873
B25: Güemes | C25: =D9/$C9 -> 0.53449603 | D25: =E9/$C9 -> 0.17814481 | E25: =F9/$C9 -> 0.10301407 | F25: =G9/$C9 -> 0.28115888 | G25: =H9/$C9 -> 0.08581861
B26: San Telmo 2 | C26: =D10/$C10 -> 0.15252904 | D26: =E10/$C10 -> 0.077112302 | E26: =F10/$C10 -> 0.032341234 | F26: =G10/$C10 -> 0.10945354 | G26: =H10/$C10 -> 0.017087751
B27: Lucero_Güemes+San Telmo 2 | C27: =D11/$C11 -> 0.21705892 | D27: =E11/$C11 -> 0.094180834 | E27: =F11/$C11 -> 0.044280774 | F27: =G11/$C11 -> 0.13846161 | G27: =H11/$C11 -> 0.02869921
B28: Güemes 2 | C28: =D12/$C12 -> 0.5295195 | D28: =E12/$C12 -> 0.092525906 | E28: =F12/$C12 -> 0.01146007 | F28: =G12/$C12 -> 0.10398598 | G28: =H12/$C12 -> 0.010434158
B29: El Solar | C29: =D13/$C13 -> 0.72322463 | D29: =E13/$C13 -> 0.32653366 | E29: =F13/$C13 -> 0.032983198 | F29: =G13/$C13 -> 0.35951686 | G29: =H13/$C13 -> 0.0042783082
B30: Lucero Joyería | C30: =D14/$C14 -> 0.62614522 | D30: =E14/$C14 -> 0.20925574 | E30: =F14/$C14 -> 0.022196429 | F30: =G14/$C14 -> 0.23145217 | G30: =H14/$C14 -> 0.0073634421
... B32: Total general | C32: =D16/$C16 -> 0.16750154 | D32: =E16/$C16 -> 0.10652174 | E32: =F16/$C16 -> 0.031951297 | F32: =G16/$C16 -> 0.13847304 | G32: =H16/$C16 -> 0.035648954

Sheet Diciembre 2025
C1: =1335 -> 1335 | J1: Evolución del porcentaje de los gastos en relación con las ventas desde enero 2025
B2: Tienda_Zona | C2: Venta | D2: Sueldos | E2: Alquileres | F2: Expensas | G2: Total alquileres + expensas | H2: Otros gastos | J2: Tienda_Zona | K2: Venta | L2: % Sueldos | M2: % Alquileres + expensas | N2: % Otros gastos
B3: Florida | C3: 75154430 | D3: 5769355 | E3: 7200000 | F3: 482850.5 | G3: =E3+F3 -> 7682850.5 | H3: 1923824.2 | J3: Florida
B4: Recoleta | C4: 34597889 | D4: 3645925 | E4: 2333872.4 | F4: 1962121.1 | G4: =E4+F4 -> 4295993.5 | H4: 830684.54 | J4: Recoleta
B5: Lucero_Zona Centro | C5: =SUM(C3:C4) -> 1.0975232e+08 | D5: =SUM(D3:D4) -> 9415280 | E5: =SUM(E3:E4) -> 9533872.4 | F5: =SUM(F3:F4) -> 2444971.6 | G5: =SUM(G3:G4) -> 11978844 | H5: =SUM(H3:H4) -> 2754508.8 | J5: Lucero_Zona Centro
B6: San Telmo | C6: 50266585 | D6: 3858890 | E6: 4159281.9 | F6: 592559.63 | G6: =E6+F6 -> 4751841.5 | H6: 291255.47 | J6: San Telmo
B7: French | C7: 25547206 | D7: 3048929 | E7: 850000 | F7: 286765.72 | G7: =E7+F7 -> 1136765.7 | H7: 747180.52 | J7: French
B8: Lucero_Zona San Telmo | C8: =SUM(C6:C7) -> 75813790 | D8: =SUM(D6:D7) -> 6907819 | E8: =SUM(E6:E7) -> 5009281.9 | F8: =SUM(F6:F7) -> 879325.35 | G8: =SUM(G6:G7) -> 5888607.3 | H8: =SUM(H6:H7) -> 1038436 | J8: Lucero_Zona San Telmo
B9: Güemes | C9: 5451413.9 | D9: 2058309 | E9: 645479.21 | F9: 324239.07 | G9: =E9+F9 -> 969718.28 | H9: 407903 | J9: Güemes
B10: San Telmo 2 | C10: 16630870 | D10: 2706334 | E10: 1999268.2 | F10: 592559.63 | G10: =E10+F10 -> 2591827.8 | H10: 7298650.8 | J10: San Telmo 2
B11: Lucero_Güemes+San Telmo 2 | C11: =SUM(C9:C10) -> 22082284 | D11: =SUM(D9:D10) -> 4764643 | E11: =SUM(E9:E10) -> 2644747.4 | F11: =SUM(F9:F10) -> 916798.7 | G11: =SUM(G9:G10) -> 3561546.1 | H11: =SUM(H9:H10) -> 7706553.8 | J11: Lucero_Güemes+San Telmo 2
B12: Güemes 2 | C12: 10969600 | D12: 2967291 | E12: 461056.58 | F12: 49606.42 | G12: =E12+F12 -> 510663 | H12: 365567.13 | J12: Güemes 2
B13: El Solar | C13: 21238500 | D13: 4145644 | E13: 1544265.6 | F13: 155986.42 | G13: =E13+F13 -> 1700252 | H13: 20606.29 | J13: El Solar
B14: Lucero Joyería | C14: =SUM(C12:C13) -> 32208100 | D14: =SUM(D12:D13) -> 7112935 | E14: =SUM(E12:E13) -> 2005322.1 | F14: =SUM(F12:F13) -> 205592.84 | G14: =SUM(G12:G13) -> 2210915 | H14: =SUM(H12:H13) -> 386173.42 | J14: Lucero Joyería
B15: AS San Telmo | C15: 18417509 | D15: 3320623 | E15: 1529517.2 | F15: 1185119.3 | G15: =E15+F15 -> 2714636.5 | H15: 459802.84 | J15: AS San Telmo
B16: Total general | C16: =+C5+C8+C11+C14+C15 -> 2.58274e+08 | D16: =+D5+D8+D11+D14+D15 -> 31521300 | E16: =+E5+E8+E11+E14+E15 -> 20722741 | F16: =+F5+F8+F11+F14+F15 -> 5631807.8 | G16: =+G5+G8+G11+G14+G15 -> 26354549 | H16: =+H5+H8+H11+H14+H15 -> 12345475 | J16: Total general
B18: Tienda_Zona | C18: Sueldos | D18: Alquileres | E18: Expensas | F18: Total alquileres + expensas | G18: Otros gastos
B19: Florida | C19: =D3/$C3 -> 0.076766666 | D19: =E3/$C3 -> 0.095802736 | E19: =F3/$C3 -> 0.0064247776 | F19: =G3/$C3 -> 0.10222751 | G19: =H3/$C3 -> 0.025598281
B20: Recoleta | C20: =D4/$C4 -> 0.10537999 | D20: =E4/$C4 -> 0.067457075 | E20: =F4/$C4 -> 0.056712164 | F20: =G4/$C4 -> 0.12416924 | G20: =H4/$C4 -> 0.024009689 | K20: Proyectado | L20: Real | M20: Desvío
B21: Lucero_Zona Centro | C21: =D5/$C5 -> 0.085786616 | D21: =E5/$C5 -> 0.086867161 | E21: =F5/$C5 -> 0.022277175 | F21: =G5/$C5 -> 0.10914434 | G21: =H5/$C5 -> 0.0250975 | J21: Sueldos | M21: =L21/K21-1 -> #DIV/0!
B22: San Telmo | C22: =D6/$C6 -> 0.076768494 | D22: =E6/$C6 -> 0.082744471 | E22: =F6/$C6 -> 0.011788341 | F22: =G6/$C6 -> 0.094532811 | G22: =H6/$C6 -> 0.0057942164 | J22: Lucero_Zona Centro | M22: =L22/K22-1 -> #DIV/0!
B23: French | C23: =D7/$C7 -> 0.11934491 | D23: =E7/$C7 -> 0.033271741 | E23: =F7/$C7 -> 0.011224935 | F23: =G7/$C7 -> 0.044496676 | G23: =H7/$C7 -> 0.029247055 | J23: Lucero_Zona San Telmo | M23: =L23/K23-1 -> #DIV/0!
B24: Lucero_Zona San Telmo | C24: =D8/$C8 -> 0.0911156 | D24: =E8/$C8 -> 0.066073493 | E24: =F8/$C8 -> 0.011598488 | F24: =G8/$C8 -> 0.077671981 | G24: =H8/$C8 -> 0.013697191 | J24: Lucero_Güemes+San Telmo 2 | M24: =L24/K24-1 -> #DIV/0!
B25: Güemes | C25: =D9/$C9 -> 0.37757342 | D25: =E9/$C9 -> 0.11840583 | E25: =F9/$C9 -> 0.059477977 | F25: =G9/$C9 -> 0.17788381 | G25: =H9/$C9 -> 0.074825176 | J25: AS San Telmo | M25: =L25/K25-1 -> #DIV/0!
B26: San Telmo 2 | C26: =D10/$C10 -> 0.16272955 | D26: =E10/$C10 -> 0.12021429 | E26: =F10/$C10 -> 0.035630104 | F26: =G10/$C10 -> 0.15584439 | G26: =H10/$C10 -> 0.43886163 | J26: El Solar | M26: =L26/K26-1 -> #DIV/0!
B27: Lucero_Güemes+San Telmo 2 | C27: =D11/$C11 -> 0.21576767 | D27: =E11/$C11 -> 0.11976784 | E27: =F11/$C11 -> 0.041517386 | F27: =G11/$C11 -> 0.16128522 | G27: =H11/$C11 -> 0.34899261
B28: Güemes 2 | C28: =D12/$C12 -> 0.27050129 | D28: =E12/$C12 -> 0.042030391 | E28: =F12/$C12 -> 0.0045221722 | F28: =G12/$C12 -> 0.046552563 | G28: =H12/$C12 -> 0.033325475
B29: El Solar | C29: =D13/$C13 -> 0.19519476 | D29: =E13/$C13 -> 0.072710669 | E29: =F13/$C13 -> 0.0073445121 | F29: =G13/$C13 -> 0.080055181 | G29: =H13/$C13 -> 0.00097023283
B30: Lucero Joyería | C30: =D14/$C14 -> 0.22084305 | D30: =E14/$C14 -> 0.062261423 | E30: =F14/$C14 -> 0.0063832651 | F30: =G14/$C14 -> 0.068644688 | G30: =H14/$C14 -> 0.011989947
B31: AS San Telmo | C31: =D15/$C15 -> 0.18029707 | D31: =E15/$C15 -> 0.08304691 | E31: =F15/$C15 -> 0.064347423 | F31: =G15/$C15 -> 0.14739433 | G31: =H15/$C15 -> 0.024965528
B32: Total general | C32: =D16/$C16 -> 0.12204597 | D32: =E16/$C16 -> 0.08023549 | E32: =F16/$C16 -> 0.021805554 | F32: =G16/$C16 -> 0.10204104 | G32: =H16/$C16 -> 0.047799913

Sheet Noviembre 2025_real
C1: =1335 -> 1335 | J1: Evolución del porcentaje de los gastos en relación con las ventas desde enero 2025
B2: Tienda_Zona | C2: Venta | D2: Sueldos | E2: Alquileres | F2: Expensas | G2: Total alquileres + expensas | H2: Otros gastos | J2: Tienda_Zona | K2: Venta | L2: % Sueldos | M2: % Alquileres + expensas | N2: % Otros gastos
B3: Florida | C3: 84288372 | D3: 6586095 | E3: 7050000 | F3: 482850.5 | G3: =E3+F3 -> 7532850.5 | H3: 1732487.7 | J3: Florida
B4: Recoleta | C4: 35080566 | D4: 3710746 | E4: =IFERROR(__xludf.DUMMYFUNCTION("""COMPUTED_VALUE"""),2248205.26) -> 2248205.3 | F4: =IFERROR(__xludf.DUMMYFUNCTION("""COMPUTED_VALUE"""),2081805.58) -> 2081805.6 | G4: =E4+F4 -> 4330010.8 | H4: 801724.66 | J4: Recoleta
B5: Lucero_Zona Centro | C5: =SUM(C3:C4) -> 119368938 | D5: =SUM(D3:D4) -> 10296841 | E5: =SUM(E3:E4) -> 9298205.3 | F5: =SUM(F3:F4) -> 2564656.1 | G5: =SUM(G3:G4) -> 11862861 | H5: =SUM(H3:H4) -> 2534212.4 | J5: Lucero_Zona Centro
B6: San Telmo | C6: 62909140 | D6: 3830165 | E6: 2138745 | F6: 650090.67 | G6: =E6+F6 -> 2788835.7 | H6: 325565.29 | J6: San Telmo
B7: French | C7: 31448390 | D7: 2874528 | E7: 703000 | F7: 246306 | G7: =E7+F7 -> 949306 | H7: 433695.18 | J7: French
B8: Lucero_Zona San Telmo | C8: =SUM(C6:C7) -> 94357530 | D8: =SUM(D6:D7) -> 6704693 | E8: =SUM(E6:E7) -> 2841745 | F8: =SUM(F6:F7) -> 896396.67 | G8: =SUM(G6:G7) -> 3738141.7 | H8: =SUM(H6:H7) -> 759260.47 | J8: Lucero_Zona San Telmo
B9: Güemes | C9: 5000090 | D9: 1669932 | E9: 645479.21 | F9: 352047.74 | G9: =E9+F9 -> 997526.95 | H9: 150044 | J9: Güemes
B10: San Telmo 2 | C10: 24191146 | D10: 2658266 | E10: 1200587.6 | F10: 650090.67 | G10: =E10+F10 -> 1850678.3 | H10: 1291237.8 | J10: San Telmo 2
B11: Lucero_Güemes+San Telmo 2 | C11: =SUM(C9:C10) -> 29191236 | D11: =SUM(D9:D10) -> 4328198 | E11: =SUM(E9:E10) -> 1846066.8 | F11: =SUM(F9:F10) -> 1002138.4 | G11: =SUM(G9:G10) -> 2848205.2 | H11: =SUM(H9:H10) -> 1441281.8 | J11: Lucero_Güemes+San Telmo 2
B12: AS San Telmo | C12: 20563510 | D12: 3468754 | E12: 1425831.8 | F12: 1300181.3 | G12: =E12+F12 -> 2726013.2 | H12: 189763.77 | J12: AS San Telmo
B13: El Solar | C13: 6889990 | D13: 5328412.8 | E13: =IFERROR(__xludf.DUMMYFUNCTION("""COMPUTED_VALUE"""),1544265.55) -> 1544265.6 | F13: 236898.87 | G13: =E13+F13 -> 1781164.4 | H13: 125207.61 | J13: El Solar
B14: AS Güemes | C14: 898200 | D14: 1201341.5 | E14: 267700 | F14: 19514.84 | G14: =E14+F14 -> 287214.84 | H14: 191900 | J14: AS Güemes
B15: Güemes 2 | C15: 1268801 | D15: 994591.3 | E15: 461056.58 | F15: 53860.96 | G15: =E15+F15 -> 514917.54 | H15: 2224.68 | J15: Güemes 2
B16: Total general | C16: =+C5+C8+C11+C12+C13+C14+C15 -> 272538205 | D16: =+D5+D8+D11+D12+D13+D14+D15 -> 32322832 | E16: =+E5+E8+E11+E12+E13+E14+E15 -> 17684871 | F16: =+F5+F8+F11+F12+F13+F14+F15 -> 6073647.2 | G16: =+G5+G8+G11+G12+G13+G14+G15 -> 23758518 | H16: =+H5+H8+H11+H12+H13+H14+H15 -> 5243850.7 | J16: Total general
B18: Tienda_Zona | C18: Sueldos | D18: Alquileres | E18: Expensas | F18: Total alquileres + expensas | G18: Otros gastos
B19: Florida | C19: =D3/$C3 -> 0.078137646 | D19: =E3/$C3 -> 0.08364143 | E19: =F3/$C3 -> 0.0057285541 | F19: =G3/$C3 -> 0.089369985 | G19: =H3/$C3 -> 0.020554291
B20: Recoleta | C20: =D4/$C4 -> 0.10577783 | D20: =E4/$C4 -> 0.064086915 | E20: =F4/$C4 -> 0.059343557 | F20: =G4/$C4 -> 0.12343047 | G20: =H4/$C4 -> 0.022853812 | K20: Proyectado | L20: Real | M20: Desvío
B21: Lucero_Zona Centro | C21: =D5/$C5 -> 0.08626064 | D21: =E5/$C5 -> 0.07789468 | E21: =F5/$C5 -> 0.021485121 | F21: =G5/$C5 -> 0.099379801 | G21: =H5/$C5 -> 0.021230082 | J21: Sueldos | M21: =L21/K21-1 -> #DIV/0!
B22: San Telmo | C22: =D6/$C6 -> 0.060884078 | D22: =E6/$C6 -> 0.033997366 | E22: =F6/$C6 -> 0.010333803 | F22: =G6/$C6 -> 0.044331169 | G22: =H6/$C6 -> 0.0051751668 | J22: Lucero_Zona Centro | M22: =L22/K22-1 -> #DIV/0!
B23: French | C23: =D7/$C7 -> 0.091404616 | D23: =E7/$C7 -> 0.022354086 | E23: =F7/$C7 -> 0.0078320703 | F23: =G7/$C7 -> 0.030186156 | G23: =H7/$C7 -> 0.013790696 | J23: Lucero_Zona San Telmo | M23: =L23/K23-1 -> #DIV/0!
B24: Lucero_Zona San Telmo | C24: =D8/$C8 -> 0.071056258 | D24: =E8/$C8 -> 0.030116781 | E24: =F8/$C8 -> 0.0095000014 | F24: =G8/$C8 -> 0.039616782 | G24: =H8/$C8 -> 0.0080466336 | J24: Lucero_Güemes+San Telmo 2 | M24: =L24/K24-1 -> #DIV/0!
B25: Güemes | C25: =D9/$C9 -> 0.33398039 | D25: =E9/$C9 -> 0.12909352 | E25: =F9/$C9 -> 0.070408281 | F25: =G9/$C9 -> 0.1995018 | G25: =H9/$C9 -> 0.03000826 | J25: AS San Telmo | M25: =L25/K25-1 -> #DIV/0!
B26: San Telmo 2 | C26: =D10/$C10 -> 0.10988591 | D26: =E10/$C10 -> 0.049629216 | E26: =F10/$C10 -> 0.026873083 | F26: =G10/$C10 -> 0.076502298 | G26: =H10/$C10 -> 0.053376463 | J26: El Solar | M26: =L26/K26-1 -> #DIV/0!
B27: Lucero_Güemes+San Telmo 2 | C27: =D11/$C11 -> 0.14827046 | D27: =E11/$C11 -> 0.063240447 | E27: =F11/$C11 -> 0.034330112 | F27: =G11/$C11 -> 0.097570559 | G27: =H11/$C11 -> 0.049373785 | J27: AS Güemes | M27: =L27/K27-1 -> #DIV/0!
B28: AS San Telmo | C28: =D12/$C12 -> 0.16868492 | D28: =E12/$C12 -> 0.06933796 | E28: =F12/$C12 -> 0.063227598 | F28: =G12/$C12 -> 0.13256556 | G28: =H12/$C12 -> 0.0092281799 | J28: Güemes 2 | M28: =L28/K28-1 -> #DIV/0!
B29: El Solar | C29: =D13/$C13 -> 0.77335567 | D29: =E13/$C13 -> 0.22413175 | E29: =F13/$C13 -> 0.03438305 | F29: =G13/$C13 -> 0.2585148 | G29: =H13/$C13 -> 0.018172394
B30: AS Güemes | C30: =D14/$C14 -> 1.3374989 | D30: =E14/$C14 -> 0.29804053 | E30: =F14/$C14 -> 0.021726609 | F30: =G14/$C14 -> 0.31976713 | G30: =H14/$C14 -> 0.21364952
B31: Güemes 2 | C31: =D15/$C15 -> 0.78388282 | D31: =E15/$C15 -> 0.36337974 | E31: =F15/$C15 -> 0.042450282 | F31: =G15/$C15 -> 0.40583002 | G31: =H15/$C15 -> 0.0017533719
B32: Total general | C32: =D16/$C16 -> 0.11859927 | D32: =E16/$C16 -> 0.064889512 | E32: =F16/$C16 -> 0.022285489 | F32: =G16/$C16 -> 0.087175001 | G32: =H16/$C16 -> 0.019240791

Sheet Noviembre 2025_proy
C1: =1335 -> 1335
B2: Tienda_Zona | C2: Venta proyectada | D2: Sueldos | E2: Incentivos por venta | F2: Total gasto de personal | G2: Alquileres | H2: Expensas | I2: Total alquileres + expensas
B3: Florida | E3: =C3*0.014293 -> 0 | F3: =D3+E3 -> 0 | G3: 7300000 | H3: 484460.03 | I3: =G3+H3 -> 7784460
B4: Recoleta | E4: =C4*0.014293 -> 0 | F4: =D4+E4 -> 0 | G4: 2120000 | H4: 2131510.3 | I4: =G4+H4 -> 4251510.3
B5: Lucero_Zona Centro | C5: =SUM(C3:C4) -> 0 | D5: =SUM(D3:D4) -> 0 | E5: =SUM(E3:E4) -> 0 | F5: =SUM(F3:F4) -> 0 | G5: =SUM(G3:G4) -> 9420000 | H5: =SUM(H3:H4) -> 2615970.3 | I5: =SUM(I3:I4) -> 12035970
B6: San Telmo | E6: =C6*0.014293 -> 0 | F6: =D6+E6 -> 0 | G6: 2135537.2 | H6: 565551.33 | I6: =G6+H6 -> 2701088.5
B7: French | E7: =C7*0.014293 -> 0 | F7: =D7+E7 -> 0 | G7: 703000 | H7: 261699.87 | I7: =G7+H7 -> 964699.87
B8: Lucero_Zona San Telmo | C8: =SUM(C6:C7) -> 0 | D8: =SUM(D6:D7) -> 0 | E8: =SUM(E6:E7) -> 0 | F8: =SUM(F6:F7) -> 0 | G8: =SUM(G6:G7) -> 2838537.2 | H8: =SUM(H6:H7) -> 827251.19 | I8: =SUM(I6:I7) -> 3665788.4
B9: Güemes | E9: =C9*0.014293 -> 0 | F9: =D9+E9 -> 0 | G9: 645612 | H9: 373184.7 | I9: =G9+H9 -> 1018796.7
B10: San Telmo 2 | E10: =C10*0.014293 -> 0 | F10: =D10+E10 -> 0 | G10: 1157000 | H10: 565551.33 | I10: =G10+H10 -> 1722551.3
B11: Lucero_Güemes+San Telmo 2 | C11: =SUM(C9:C10) -> 0 | D11: =SUM(D9:D10) -> 0 | E11: =SUM(E9:E10) -> 0 | F11: =SUM(F9:F10) -> 0 | G11: =SUM(G9:G10) -> 1802612 | H11: =SUM(H9:H10) -> 938736.03 | I11: =SUM(I9:I10) -> 2741348
B12: AS San Telmo | E12: =C12*0.014293 -> 0 | F12: =D12+E12 -> 0 | G12: 1361157 | H12: 1131102.7 | I12: =G12+H12 -> 2492259.7
B13: El Solar | E13: =C13*0.014293 -> 0 | F13: =D13+E13 -> 0 | G13: =1400000+140000 -> 1540000 | H13: 156000 | I13: =G13+H13 -> 1696000
B14: Total general | C14: =+C5+C8+C11+C12+C13 -> 0 | D14: =+D5+D8+D11+D12+D13 -> 0 | E14: =+E5+E8+E11+E12+E13 -> 0 | F14: =+F5+F8+F11+F12+F13 -> 0 | G14: =+G5+G8+G11+G12+G13 -> 16962306 | H14: =+H5+H8+H11+H12+H13 -> 5669060.2 | I14: =+I5+I8+I11+I12+I13 -> 22631366
B16: Tienda_Zona | C16: Sueldos | D16: Incentivos por venta | E16: Total gasto de personal | F16: Alquileres | G16: Expensas | H16: Total alquileres + expensas
B17: Florida | C17: =D3/$C3 -> #DIV/0! | D17: =E3/$C3 -> #DIV/0! | E17: =F3/$C3 -> #DIV/0! | F17: =G3/$C3 -> #DIV/0! | G17: =H3/$C3 -> #DIV/0! | H17: =I3/$C3 -> #DIV/0!
B18: Recoleta | C18: =D4/$C4 -> #DIV/0! | D18: =E4/$C4 -> #DIV/0! | E18: =F4/$C4 -> #DIV/0! | F18: =G4/$C4 -> #DIV/0! | G18: =H4/$C4 -> #DIV/0! | H18: =I4/$C4 -> #DIV/0!
B19: Lucero_Zona Centro | C19: =D5/$C5 -> #DIV/0! | D19: =E5/$C5 -> #DIV/0! | E19: =F5/$C5 -> #DIV/0! | F19: =G5/$C5 -> #DIV/0! | G19: =H5/$C5 -> #DIV/0! | H19: =I5/$C5 -> #DIV/0!
B20: San Telmo | C20: =D6/$C6 -> #DIV/0! | D20: =E6/$C6 -> #DIV/0! | E20: =F6/$C6 -> #DIV/0! | F20: =G6/$C6 -> #DIV/0! | G20: =H6/$C6 -> #DIV/0! | H20: =I6/$C6 -> #DIV/0!
B21: French | C21: =D7/$C7 -> #DIV/0! | D21: =E7/$C7 -> #DIV/0! | E21: =F7/$C7 -> #DIV/0! | F21: =G7/$C7 -> #DIV/0! | G21: =H7/$C7 -> #DIV/0! | H21: =I7/$C7 -> #DIV/0!
B22: Lucero_Zona San Telmo | C22: =D8/$C8 -> #DIV/0! | D22: =E8/$C8 -> #DIV/0! | E22: =F8/$C8 -> #DIV/0! | F22: =G8/$C8 -> #DIV/0! | G22: =H8/$C8 -> #DIV/0! | H22: =I8/$C8 -> #DIV/0!
B23: Güemes | C23: =D9/$C9 -> #DIV/0! | D23: =E9/$C9 -> #DIV/0! | E23: =F9/$C9 -> #DIV/0! | F23: =G9/$C9 -> #DIV/0! | G23: =H9/$C9 -> #DIV/0! | H23: =I9/$C9 -> #DIV/0!
B24: San Telmo 2 | C24: =D10/$C10 -> #DIV/0! | D24: =E10/$C10 -> #DIV/0! | E24: =F10/$C10 -> #DIV/0! | F24: =G10/$C10 -> #DIV/0! | G24: =H10/$C10 -> #DIV/0! | H24: =I10/$C10 -> #DIV/0!
B25: Lucero_Güemes+San Telmo 2 | C25: =D11/$C11 -> #DIV/0! | D25: =E11/$C11 -> #DIV/0! | E25: =F11/$C11 -> #DIV/0! | F25: =G11/$C11 -> #DIV/0! | G25: =H11/$C11 -> #DIV/0! | H25: =I11/$C11 -> #DIV/0!
B26: AS San Telmo | C26: =D12/$C12 -> #DIV/0! | D26: =E12/$C12 -> #DIV/0! | E26: =F12/$C12 -> #DIV/0! | F26: =G12/$C12 -> #DIV/0! | G26: =H12/$C12 -> #DIV/0! | H26: =I12/$C12 -> #DIV/0!
B27: El Solar | C27: =D13/$C13 -> #DIV/0! | D27: =E13/$C13 -> #DIV/0! | E27: =F13/$C13 -> #DIV/0! | F27: =G13/$C13 -> #DIV/0! | G27: =H13/$C13 -> #DIV/0! | H27: =I13/$C13 -> #DIV/0!
B28: Total general | C28: =D14/$C14 -> #DIV/0! | D28: =E14/$C14 -> #DIV/0! | E28: =F14/$C14 -> #DIV/0! | F28: =G14/$C14 -> #DIV/0! | G28: =H14/$C14 -> #DIV/0! | H28: =I14/$C14 -> #DIV/0!

Sheet Octubre 2025_proy
C1: =1335 -> 1335
B2: Tienda_Zona | C2: Venta proyectada | D2: Sueldos | E2: Incentivos por venta | F2: Total gasto de personal | G2: Alquileres | H2: Expensas | I2: Total alquileres + expensas
B3: Florida | C3: 68551715 | D3: 5328900 | E3: =C3*0.014293 -> 979809.66 | F3: =D3+E3 -> 6308709.7 | G3: 7000000 | H3: 515040.5 | I3: =G3+H3 -> 7515040.5
B4: Recoleta | C4: 28417188 | D4: 3256550 | E4: =C4*0.014293 -> 406166.87 | F4: =D4+E4 -> 3662716.9 | G4: 1575471 | H4: 2045417 | I4: =G4+H4 -> 3620888
B5: Lucero_Zona Centro | C5: =SUM(C3:C4) -> 96968903 | D5: =SUM(D3:D4) -> 8585450 | E5: =SUM(E3:E4) -> 1385976.5 | F5: =SUM(F3:F4) -> 9971426.5 | G5: =SUM(G3:G4) -> 8575471 | H5: =SUM(H3:H4) -> 2560457.5 | I5: =SUM(I3:I4) -> 11135928
B6: San Telmo | C6: 53365632 | D6: 2979600 | E6: =C6*0.014293 -> 762754.98 | F6: =D6+E6 -> 3742355 | G6: 2205191 | H6: 557887 | I6: =G6+H6 -> 2763078
B7: French | C7: 24216000 | D7: 2540300 | E7: =C7*0.014293 -> 346119.29 | F7: =D7+E7 -> 2886419.3 | G7: 703000 | H7: 231882 | I7: =G7+H7 -> 934882
B8: Lucero_Zona San Telmo | C8: =SUM(C6:C7) -> 77581632 | D8: =SUM(D6:D7) -> 5519900 | E8: =SUM(E6:E7) -> 1108874.3 | F8: =SUM(F6:F7) -> 6628774.3 | G8: =SUM(G6:G7) -> 2908191 | H8: =SUM(H6:H7) -> 789769 | I8: =SUM(I6:I7) -> 3697960
B9: Güemes | C9: 5776908 | D9: 1976850 | E9: =C9*0.014293 -> 82569.346 | F9: =D9+E9 -> 2059419.3 | G9: 644652 | H9: 355773 | I9: =G9+H9 -> 1000425
B10: San Telmo 2 | C10: 15461400 | D10: 2368400 | E10: =C10*0.014293 -> 220989.79 | F10: =D10+E10 -> 2589389.8 | G10: 1064835 | H10: 557887 | I10: =G10+H10 -> 1622722
B11: Lucero_Güemes+San Telmo 2 | C11: =SUM(C9:C10) -> 21238308 | D11: =SUM(D9:D10) -> 4345250 | E11: =SUM(E9:E10) -> 303559.14 | F11: =SUM(F9:F10) -> 4648809.1 | G11: =SUM(G9:G10) -> 1709487 | H11: =SUM(H9:H10) -> 913660 | I11: =SUM(I9:I10) -> 2623147
B12: AS San Telmo | C12: 18012064 | D12: 2674000 | E12: =C12*0.014293 -> 257446.43 | F12: =D12+E12 -> 2931446.4 | G12: 955537 | H12: 1115774 | I12: =G12+H12 -> 2071311
B13: Total general | C13: =+C5+C8+C11+C12 -> 2.1380091e+08 | D13: =+D5+D8+D11+D12 -> 21124600 | E13: =+E5+E8+E11+E12 -> 3055856.4 | F13: =+F5+F8+F11+F12 -> 24180456 | G13: =+G5+G8+G11+G12 -> 14148686 | H13: =+H5+H8+H11+H12 -> 5379660.5 | I13: =+I5+I8+I11+I12 -> 19528346
B15: Tienda_Zona | C15: Sueldos | D15: Incentivos por venta | E15: Total gasto de personal | F15: Alquileres | G15: Expensas | H15: Total alquileres + expensas
B16: Florida | C16: =D3/$C3 -> 0.077735473 | D16: =E3/$C3 -> 0.014293 | E16: =F3/$C3 -> 0.092028473 | F16: =G3/$C3 -> 0.10211269 | G16: =H3/$C3 -> 0.0075131672 | H16: =I3/$C3 -> 0.10962586
B17: Recoleta | C17: =D4/$C4 -> 0.1145979 | D17: =E4/$C4 -> 0.014293 | E17: =F4/$C4 -> 0.1288909 | F17: =G4/$C4 -> 0.055440778 | G17: =H4/$C4 -> 0.071978163 | H17: =I4/$C4 -> 0.12741894
B18: Lucero_Zona Centro | C18: =D5/$C5 -> 0.088538178 | D18: =E5/$C5 -> 0.014293 | E18: =F5/$C5 -> 0.10283118 | F18: =G5/$C5 -> 0.088435269 | G18: =H5/$C5 -> 0.026404934 | H18: =I5/$C5 -> 0.1148402
B19: San Telmo | C19: =D6/$C6 -> 0.055833687 | D19: =E6/$C6 -> 0.014293 | E19: =F6/$C6 -> 0.070126687 | F19: =G6/$C6 -> 0.041322306 | G19: =H6/$C6 -> 0.01045405 | H19: =I6/$C6 -> 0.051776357
B20: French | C20: =D7/$C7 -> 0.10490172 | D20: =E7/$C7 -> 0.014293 | E20: =F7/$C7 -> 0.11919472 | F20: =G7/$C7 -> 0.029030393 | G20: =H7/$C7 -> 0.0095755699 | H20: =I7/$C7 -> 0.038605963
B21: Lucero_Zona San Telmo | C21: =D8/$C8 -> 0.071149573 | D21: =E8/$C8 -> 0.014293 | E21: =F8/$C8 -> 0.085442573 | F21: =G8/$C8 -> 0.037485561 | G21: =H8/$C8 -> 0.010179845 | H21: =I8/$C8 -> 0.047665406
B22: Güemes | C22: =D9/$C9 -> 0.34219863 | D22: =E9/$C9 -> 0.014293 | E22: =F9/$C9 -> 0.35649163 | F22: =G9/$C9 -> 0.11159118 | G22: =H9/$C9 -> 0.061585367 | H22: =I9/$C9 -> 0.17317655
B23: San Telmo 2 | C23: =D10/$C10 -> 0.15318147 | D23: =E10/$C10 -> 0.014293 | E23: =F10/$C10 -> 0.16747447 | F23: =G10/$C10 -> 0.068870542 | G23: =H10/$C10 -> 0.036082567 | H23: =I10/$C10 -> 0.10495311
B24: Lucero_Güemes+San Telmo 2 | C24: =D11/$C11 -> 0.20459492 | D24: =E11/$C11 -> 0.014293 | E24: =F11/$C11 -> 0.21888792 | F24: =G11/$C11 -> 0.080490734 | G24: =H11/$C11 -> 0.043019435 | H24: =I11/$C11 -> 0.12351017
B25: AS San Telmo | C25: =D12/$C12 -> 0.14845606 | D25: =E12/$C12 -> 0.014293 | E25: =F12/$C12 -> 0.16274906 | F25: =G12/$C12 -> 0.053049834 | G25: =H12/$C12 -> 0.061945927 | H25: =I12/$C12 -> 0.11499576
B26: Total general | C26: =D13/$C13 -> 0.098805006 | D26: =E13/$C13 -> 0.014293 | E26: =F13/$C13 -> 0.11309801 | F26: =G13/$C13 -> 0.066176922 | G26: =H13/$C13 -> 0.02516201 | H26: =I13/$C13 -> 0.091338932

Sheet Octubre 2025_real
C1: =1335 -> 1335 | J1: Evolución del porcentaje de los gastos en relación con las ventas desde enero 2025
B2: Tienda_Zona | C2: Venta | D2: Sueldos | E2: Alquileres | F2: Expensas | G2: Total alquileres + expensas | H2: Otros gastos | J2: Tienda_Zona | K2: Venta | L2: % Sueldos | M2: % Alquileres + expensas | N2: % Otros gastos
B3: Florida | C3: 58604767 | D3: 5231714 | E3: 7275000 | F3: 461390.5 | G3: =E3+F3 -> 7736390.5 | H3: 1966770.3 | J3: Florida
B4: Recoleta | C4: 31723946 | D4: 3488427 | E4: 1572090 | F4: 2030009.8 | G4: =E4+F4 -> 3602099.8 | H4: 560026.23 | J4: Recoleta
B5: Lucero_Zona Centro | C5: =SUM(C3:C4) -> 90328713 | D5: =SUM(D3:D4) -> 8720141 | E5: =SUM(E3:E4) -> 8847090 | F5: =SUM(F3:F4) -> 2491400.3 | G5: =SUM(G3:G4) -> 11338490 | H5: =SUM(H3:H4) -> 2526796.5 | J5: Lucero_Zona Centro
B6: San Telmo | C6: 32348520 | D6: 3210558 | E6: 2190647 | F6: 538620.31 | G6: =E6+F6 -> 2729267.3 | H6: 251999.59 | J6: San Telmo
B7: French | C7: 19749649 | D7: 2611013 | E7: 703000 | F7: 249237.97 | G7: =E7+F7 -> 952237.97 | H7: 523330.01 | J7: French
B8: Lucero_Zona San Telmo | C8: =SUM(C6:C7) -> 52098169 | D8: =SUM(D6:D7) -> 5821571 | E8: =SUM(E6:E7) -> 2893647 | F8: =SUM(F6:F7) -> 787858.28 | G8: =SUM(G6:G7) -> 3681505.3 | H8: =SUM(H6:H7) -> 775329.6 | J8: Lucero_Zona San Telmo
B9: Güemes | C9: 5985346 | D9: 2111208 | E9: =599275+46204 -> 645479 | F9: 355414 | G9: =E9+F9 -> 1000893 | H9: 409319 | J9: Güemes
B10: San Telmo 2 | C10: 14527110 | D10: 2640837 | E10: 1058553 | F10: 538620.31 | G10: =E10+F10 -> 1597173.3 | H10: 146799.82 | J10: San Telmo 2
B11: Lucero_Güemes+San Telmo 2 | C11: =SUM(C9:C10) -> 20512456 | D11: =SUM(D9:D10) -> 4752045 | E11: =SUM(E9:E10) -> 1704032 | F11: =SUM(F9:F10) -> 894034.31 | G11: =SUM(G9:G10) -> 2598066.3 | H11: =SUM(H9:H10) -> 556118.82 | J11: Lucero_Güemes+San Telmo 2
B12: AS San Telmo | C12: 19169518 | D12: 3435615 | E12: 957292.11 | F12: 1077240.6 | G12: =E12+F12 -> 2034532.7 | H12: 470452.8 | J12: AS San Telmo
B13: El Solar | C13: 6544524 | D13: 4586090.1 | E13: =1350000*1.1 -> 1485000 | F13: 150000 | G13: =E13+F13 -> 1635000 | H13: 0 | J13: El Solar
B14: Total general | C14: =+C5+C8+C11+C12+C13 -> 1.8865338e+08 | D14: =+D5+D8+D11+D12+D13 -> 27315462 | E14: =+E5+E8+E11+E12+E13 -> 15887061 | F14: =+F5+F8+F11+F12+F13 -> 5400533.5 | G14: =+G5+G8+G11+G12+G13 -> 21287595 | H14: =+H5+H8+H11+H12+H13 -> 4328697.8 | J14: Total general
B16: Tienda_Zona | C16: Sueldos | D16: Alquileres | E16: Expensas | F16: Total alquileres + expensas | G16: Otros gastos
B17: Florida | C17: =D3/$C3 -> 0.089271134 | D17: =E3/$C3 -> 0.12413666 | E17: =F3/$C3 -> 0.0078729176 | F17: =G3/$C3 -> 0.13200958 | G17: =H3/$C3 -> 0.033559903
B18: Recoleta | C18: =D4/$C4 -> 0.10996195 | D18: =E4/$C4 -> 0.049555311 | E18: =F4/$C4 -> 0.063989827 | F18: =G4/$C4 -> 0.11354514 | G18: =H4/$C4 -> 0.017653108 | K18: Proyectado | L18: Real | M18: Desvío
B19: Lucero_Zona Centro | C19: =D5/$C5 -> 0.096537864 | D19: =E5/$C5 -> 0.097943275 | E19: =F5/$C5 -> 0.027581488 | F19: =G5/$C5 -> 0.12552476 | G19: =H5/$C5 -> 0.027973348 | J19: Sueldos | K19: ='Octubre 2025_proy'!F13 -> 24180456 | L19: =D14-D13 -> 22729372 | M19: =L19/K19-1 -> -0.060010628
B20: San Telmo | C20: =D6/$C6 -> 0.099248993 | D20: =E6/$C6 -> 0.067720162 | E20: =F6/$C6 -> 0.01665054 | F20: =G6/$C6 -> 0.084370702 | G20: =H6/$C6 -> 0.0077901428 | J20: Lucero_Zona Centro | K20: ='Octubre 2025_proy'!F5 -> 9971426.5 | L20: =D5 -> 8720141 | M20: =L20/K20-1 -> -0.12548711
B21: French | C21: =D7/$C7 -> 0.13220554 | D21: =E7/$C7 -> 0.035595569 | E21: =F7/$C7 -> 0.012619868 | F21: =G7/$C7 -> 0.048215438 | G21: =H7/$C7 -> 0.026498193 | J21: Lucero_Zona San Telmo | K21: ='Octubre 2025_proy'!F8 -> 6628774.3 | L21: =D8 -> 5821571 | M21: =L21/K21-1 -> -0.12177263
B22: Lucero_Zona San Telmo | C22: =D8/$C8 -> 0.11174233 | D22: =E8/$C8 -> 0.055542202 | E22: =F8/$C8 -> 0.015122571 | F22: =G8/$C8 -> 0.070664773 | G22: =H8/$C8 -> 0.014882089 | J22: Lucero_Güemes+San Telmo 2 | K22: ='Octubre 2025_proy'!F11 -> 4648809.1 | L22: =D11 -> 4752045 | M22: =L22/K22-1 -> 0.022206948
B23: Güemes | C23: =D9/$C9 -> 0.35272948 | D23: =E9/$C9 -> 0.10784322 | E23: =F9/$C9 -> 0.059380694 | F23: =G9/$C9 -> 0.16722392 | G23: =H9/$C9 -> 0.068386857 | J23: AS San Telmo | K23: ='Octubre 2025_proy'!F12 -> 2931446.4 | L23: =D12 -> 3435615 | M23: =L23/K23-1 -> 0.17198628
B24: San Telmo 2 | C24: =D10/$C10 -> 0.18178681 | D24: =E10/$C10 -> 0.072867418 | E24: =F10/$C10 -> 0.037076907 | F24: =G10/$C10 -> 0.10994433 | G24: =H10/$C10 -> 0.010105232
B25: Lucero_Güemes+San Telmo 2 | C25: =D11/$C11 -> 0.23166631 | D25: =E11/$C11 -> 0.083073036 | E25: =F11/$C11 -> 0.043584947 | F25: =G11/$C11 -> 0.12665798 | G25: =H11/$C11 -> 0.027111274
B26: AS San Telmo | C26: =D12/$C12 -> 0.17922282 | D26: =E12/$C12 -> 0.049938246 | E26: =F12/$C12 -> 0.056195498 | F26: =G12/$C12 -> 0.10613374 | G26: =H12/$C12 -> 0.024541713
B27: El Solar | C27: =D13/$C13 -> 0.70075227 | D27: =E13/$C13 -> 0.22690726 | E27: =F13/$C13 -> 0.022919925 | F27: =G13/$C13 -> 0.24982718 | G27: =H13/$C13 -> 0
B28: Total general | C28: =D14/$C14 -> 0.1447918 | D28: =E14/$C14 -> 0.084212968 | E28: =F14/$C14 -> 0.028626752 | F28: =G14/$C14 -> 0.11283972 | G28: =H14/$C14 -> 0.022945244

Sheet Septiembre 2025_real
C1: =1335 -> 1335
B2: Tienda_Zona | C2: Venta real | D2: Sueldos | E2: Alquileres | F2: Expensas | G2: Total alquileres + expensas | H2: Otros gastos
B3: Florida | C3: 62713661 | D3: 5345060 | E3: 7000000 | F3: 300440.5 | G3: =E3+F3 -> 7300440.5 | H3: 1773489.2
B4: Recoleta | C4: 22885150 | D4: 3082266 | E4: 1448355.7 | F4: 1948016.5 | G4: =E4+F4 -> 3396372.2 | H4: 209674.47
B5: Lucero_Zona Centro | C5: =SUM(C3:C4) -> 85598811 | D5: =SUM(D3:D4) -> 8427326 | E5: =SUM(E3:E4) -> 8448355.7 | F5: =SUM(F3:F4) -> 2248457 | G5: =SUM(G3:G4) -> 10696813 | H5: =SUM(H3:H4) -> 1983163.6
B6: San Telmo | C6: 33133540 | D6: 2263663 | E6: 2250334.6 | F6: 531320.8 | G6: =E6+F6 -> 2781655.4 | H6: 200815.63
B7: French | C7: 19997040 | D7: 2444318 | E7: 703000 | F7: 220840 | G7: =E7+F7 -> 923840 | H7: 419343.85
B8: Lucero_Zona San Telmo | C8: =SUM(C6:C7) -> 53130580 | D8: =SUM(D6:D7) -> 4707981 | E8: =SUM(E6:E7) -> 2953334.6 | F8: =SUM(F6:F7) -> 752160.8 | G8: =SUM(G6:G7) -> 3705495.4 | H8: =SUM(H6:H7) -> 620159.48
B9: Güemes | C9: 4814090 | D9: 1976546 | E9: 599275.1 | F9: 338831.14 | G9: =E9+F9 -> 938106.24 | H9: 159124
B10: San Telmo 2 | C10: 12808500 | D10: 2087438 | E10: 900710.7 | F10: 531320.8 | G10: =E10+F10 -> 1432031.5 | H10: 189129.62
B11: Lucero_Güemes+San Telmo 2 | C11: =SUM(C9:C10) -> 17622590 | D11: =SUM(D9:D10) -> 4063984 | E11: =SUM(E9:E10) -> 1499985.8 | F11: =SUM(F9:F10) -> 870151.94 | G11: =SUM(G9:G10) -> 2370137.7 | H11: =SUM(H9:H10) -> 348253.62
B12: AS San Telmo | C12: 12870480 | D12: 2855608 | E12: 1091639.7 | F12: 1062641.6 | G12: =E12+F12 -> 2154281.3 | H12: 2038403.4
B13: Total general | C13: =+C5+C8+C11+C12 -> 1.6922246e+08 | D13: =+D5+D8+D11+D12 -> 20054899 | E13: =+E5+E8+E11+E12 -> 13993316 | F13: =+F5+F8+F11+F12 -> 4933411.3 | G13: =+G5+G8+G11+G12 -> 18926727 | H13: =+H5+H8+H11+H12 -> 4989980.2
B15: Tienda_Zona | C15: Sueldos | D15: Alquileres | E15: Expensas | F15: Total alquileres + expensas | G15: Otros gastos
B16: Florida | C16: =D3/$C3 -> 0.085229596 | D16: =E3/$C3 -> 0.11161842 | E16: =F3/$C3 -> 0.0047906707 | F16: =G3/$C3 -> 0.11640909 | G16: =H3/$C3 -> 0.028279152
B17: Recoleta | C17: =D4/$C4 -> 0.13468411 | D17: =E4/$C4 -> 0.063288015 | E17: =F4/$C4 -> 0.085121422 | F17: =G4/$C4 -> 0.14840944 | G17: =H4/$C4 -> 0.0091620317
B18: Lucero_Zona Centro | C18: =D5/$C5 -> 0.098451438 | D18: =E5/$C5 -> 0.098697115 | E18: =F5/$C5 -> 0.026267386 | F18: =G5/$C5 -> 0.1249645 | G18: =H5/$C5 -> 0.023168121
B19: San Telmo | C19: =D6/$C6 -> 0.068319383 | D19: =E6/$C6 -> 0.067917121 | E19: =F6/$C6 -> 0.016035739 | F19: =G6/$C6 -> 0.08395286 | G19: =H6/$C6 -> 0.0060607961
B20: French | C20: =D7/$C7 -> 0.12223399 | D20: =E7/$C7 -> 0.035155203 | E20: =F7/$C7 -> 0.011043634 | F20: =G7/$C7 -> 0.046198837 | G20: =H7/$C7 -> 0.020970296
B21: Lucero_Zona San Telmo | C21: =D8/$C8 -> 0.088611511 | D21: =E8/$C8 -> 0.055586343 | E21: =F8/$C8 -> 0.014156834 | F21: =G8/$C8 -> 0.069743177 | G21: =H8/$C8 -> 0.011672364
B22: Güemes | C22: =D9/$C9 -> 0.41057521 | D22: =E9/$C9 -> 0.12448357 | E22: =F9/$C9 -> 0.070383217 | F22: =G9/$C9 -> 0.19486678 | G22: =H9/$C9 -> 0.033053807
B23: San Telmo 2 | C23: =D10/$C10 -> 0.16297287 | D23: =E10/$C10 -> 0.070321326 | E23: =F10/$C10 -> 0.041481891 | F23: =G10/$C10 -> 0.11180322 | G23: =H10/$C10 -> 0.014765946
B24: Lucero_Güemes+San Telmo 2 | C24: =D11/$C11 -> 0.23061219 | D24: =E11/$C11 -> 0.085117216 | E24: =F11/$C11 -> 0.049377075 | F24: =G11/$C11 -> 0.13449429 | G24: =H11/$C11 -> 0.019761773
B25: AS San Telmo | C25: =D12/$C12 -> 0.22187269 | D25: =E12/$C12 -> 0.084817326 | E25: =F12/$C12 -> 0.082564255 | F25: =G12/$C12 -> 0.16738158 | G25: =H12/$C12 -> 0.1583782
B26: Total general | C26: =D13/$C13 -> 0.11851204 | D26: =E13/$C13 -> 0.082691835 | E26: =F13/$C13 -> 0.029153407 | F26: =G13/$C13 -> 0.11184524 | G26: =H13/$C13 -> 0.029487694

Sheet Septiembre 2025_proy
C1: =1335 -> 1335
B2: Tienda_Zona | C2: Venta proyectada | D2: Sueldos | E2: Incentivos por venta | F2: Total gasto de personal | G2: Alquileres | H2: Expensas | I2: Total alquileres + expensas
B3: Florida | C3: 49500000 | D3: 4973400 | E3: =C3*0.014293 -> 707503.5 | F3: =D3+E3 -> 5680903.5 | G3: 6875000 | H3: 515040.5 | I3: =G3+H3 -> 7390040.5
B4: Recoleta | C4: 23500000 | D4: 3039300 | E4: =C4*0.014293 -> 335885.5 | F4: =D4+E4 -> 3375185.5 | G4: 1495384.8 | H4: 1912694.2 | I4: =G4+H4 -> 3408079.1
B5: Lucero_Zona Centro | C5: =SUM(C3:C4) -> 73000000 | D5: =SUM(D3:D4) -> 8012700 | E5: =SUM(E3:E4) -> 1043389 | F5: =SUM(F3:F4) -> 9056089 | G5: =SUM(G3:G4) -> 8370384.8 | H5: =SUM(H3:H4) -> 2427734.7 | I5: =SUM(I3:I4) -> 10798120
B6: San Telmo | C6: 36000000 | D6: 2947200 | E6: =C6*0.014293 -> 514548 | F6: =D6+E6 -> 3461748 | G6: 2268093.2 | H6: 573285.05 | I6: =G6+H6 -> 2841378.3
B7: French | C7: 17000000 | D7: 2394600 | E7: =C7*0.014293 -> 242981 | F7: =D7+E7 -> 2637581 | G7: 718564 | H7: 242602.21 | I7: =G7+H7 -> 961166.21
B8: Lucero_Zona San Telmo | C8: =SUM(C6:C7) -> 53000000 | D8: =SUM(D6:D7) -> 5341800 | E8: =SUM(E6:E7) -> 757529 | F8: =SUM(F6:F7) -> 6099329 | G8: =SUM(G6:G7) -> 2986657.2 | H8: =SUM(H6:H7) -> 815887.26 | I8: =SUM(I6:I7) -> 3802544.5
B9: Güemes | C9: 4700000 | D9: 1823580 | E9: =C9*0.014293 -> 67177.1 | F9: =D9+E9 -> 1890757.1 | G9: 599544 | H9: 328003.06 | I9: =G9+H9 -> 927547.06
B10: San Telmo 2 | C10: 11500000 | D10: 2210400 | E10: =C10*0.014293 -> 164369.5 | F10: =D10+E10 -> 2374769.5 | G10: 897405.79 | H10: 573285.05 | I10: =G10+H10 -> 1470690.8
B11: Lucero_Güemes+San Telmo 2 | C11: =SUM(C9:C10) -> 16200000 | D11: =SUM(D9:D10) -> 4033980 | E11: =SUM(E9:E10) -> 231546.6 | F11: =SUM(F9:F10) -> 4265526.6 | G11: =SUM(G9:G10) -> 1496949.8 | H11: =SUM(H9:H10) -> 901288.11 | I11: =SUM(I9:I10) -> 2398237.9
B12: AS San Telmo | C12: 16000000 | D12: 2947200 | E12: =C12*0.014293 -> 228688 | F12: =D12+E12 -> 3175888 | G12: 1085858.2 | H12: 1146570 | I12: =G12+H12 -> 2232428.2
B13: Total general | C13: =+C5+C8+C11+C12 -> 158200000 | D13: =+D5+D8+D11+D12 -> 20335680 | E13: =+E5+E8+E11+E12 -> 2261152.6 | F13: =+F5+F8+F11+F12 -> 22596833 | G13: =+G5+G8+G11+G12 -> 13939850 | H13: =+H5+H8+H11+H12 -> 5291480.1 | I13: =+I5+I8+I11+I12 -> 19231330
B15: Tienda_Zona | C15: Sueldos | D15: Incentivos por venta | E15: Total gasto de personal | F15: Alquileres | G15: Expensas | H15: Total alquileres + expensas
B16: Florida | C16: =D3/$C3 -> 0.10047273 | D16: =E3/$C3 -> 0.014293 | E16: =F3/$C3 -> 0.11476573 | F16: =G3/$C3 -> 0.13888889 | G16: =H3/$C3 -> 0.010404859 | H16: =I3/$C3 -> 0.14929375
B17: Recoleta | C17: =D4/$C4 -> 0.12933191 | D17: =E4/$C4 -> 0.014293 | E17: =F4/$C4 -> 0.14362491 | F17: =G4/$C4 -> 0.063633397 | G17: =H4/$C4 -> 0.081391243 | H17: =I4/$C4 -> 0.14502464
B18: Lucero_Zona Centro | C18: =D5/$C5 -> 0.10976301 | D18: =E5/$C5 -> 0.014293 | E18: =F5/$C5 -> 0.12405601 | F18: =G5/$C5 -> 0.11466281 | G18: =H5/$C5 -> 0.03325664 | H18: =I5/$C5 -> 0.14791945
B19: San Telmo | C19: =D6/$C6 -> 0.081866667 | D19: =E6/$C6 -> 0.014293 | E19: =F6/$C6 -> 0.096159667 | F19: =G6/$C6 -> 0.06300259 | G19: =H6/$C6 -> 0.015924585 | H19: =I6/$C6 -> 0.078927174
B20: French | C20: =D7/$C7 -> 0.14085882 | D20: =E7/$C7 -> 0.014293 | E20: =F7/$C7 -> 0.15515182 | F20: =G7/$C7 -> 0.042268471 | G20: =H7/$C7 -> 0.014270718 | H20: =I7/$C7 -> 0.056539189
B21: Lucero_Zona San Telmo | C21: =D8/$C8 -> 0.10078868 | D21: =E8/$C8 -> 0.014293 | E21: =F8/$C8 -> 0.11508168 | F21: =G8/$C8 -> 0.056352023 | G21: =H8/$C8 -> 0.015394099 | H21: =I8/$C8 -> 0.071746122
B22: Güemes | C22: =D9/$C9 -> 0.38799574 | D22: =E9/$C9 -> 0.014293 | E22: =F9/$C9 -> 0.40228874 | F22: =G9/$C9 -> 0.12756255 | G22: =H9/$C9 -> 0.069787885 | H22: =I9/$C9 -> 0.19735044
B23: San Telmo 2 | C23: =D10/$C10 -> 0.1922087 | D23: =E10/$C10 -> 0.014293 | E23: =F10/$C10 -> 0.2065017 | F23: =G10/$C10 -> 0.078035286 | G23: =H10/$C10 -> 0.049850874 | H23: =I10/$C10 -> 0.12788616
B24: Lucero_Güemes+San Telmo 2 | C24: =D11/$C11 -> 0.24901111 | D24: =E11/$C11 -> 0.014293 | E24: =F11/$C11 -> 0.26330411 | F24: =G11/$C11 -> 0.092404308 | G24: =H11/$C11 -> 0.055635069 | H24: =I11/$C11 -> 0.14803938
B25: AS San Telmo | C25: =D12/$C12 -> 0.1842 | D25: =E12/$C12 -> 0.014293 | E25: =F12/$C12 -> 0.198493 | F25: =G12/$C12 -> 0.067866136 | G25: =H12/$C12 -> 0.071660626 | H25: =I12/$C12 -> 0.13952676
B26: Total general | C26: =D13/$C13 -> 0.12854412 | D26: =E13/$C13 -> 0.014293 | E26: =F13/$C13 -> 0.14283712 | F26: =G13/$C13 -> 0.08811536 | G26: =H13/$C13 -> 0.033448041 | H26: =I13/$C13 -> 0.1215634

Sheet Agosto 2025-real
C1: =1335 -> 1335 | J1: Evolución del porcentaje de los gastos en relación con las ventas desde enero 2025
B2: Tienda_Zona | C2: Venta | D2: Sueldos | E2: Alquileres | F2: Expensas | G2: Total alquileres + expensas | H2: Otros gastos | J2: Tienda_Zona | K2: Venta | L2: Sueldos | M2: Alquileres + expensas | N2: Otros gastos
B3: Florida | C3: 45735238 | D3: 5359007 | E3: 6550000 | F3: 407740.5 | G3: =E3+F3 -> 6957740.5 | H3: 1845033.1 | J3: Florida
B4: Recoleta | C4: 21770316 | D4: 3174723 | E4: 1299988.6 | F4: 1901854.1 | G4: =E4+F4 -> 3201842.7 | H4: 509583.35 | J4: Recoleta
B5: Güemes | C5: 4168817.5 | D5: 1914315.8 | E5: 599275.1 | F5: 328003.06 | G5: =E5+F5 -> 927278.16 | H5: 315055 | J5: Güemes
B6: Lucero_Zona Centro | C6: =SUM(C3:C5) -> 71674372 | D6: =SUM(D3:D5) -> 10448046 | E6: =SUM(E3:E5) -> 8449263.7 | F6: =SUM(F3:F5) -> 2637597.7 | G6: =SUM(G3:G5) -> 11086861 | H6: =SUM(H3:H5) -> 2669671.4 | J6: Lucero_Zona Centro
B7: San Telmo | C7: 34037280 | D7: 3084694.7 | E7: 1741513.4 | F7: 573285.05 | G7: =E7+F7 -> 2314798.5 | H7: 276404.91 | J7: San Telmo
B8: French | C8: 16141623 | D8: 2609720.2 | E8: 667200 | F8: 242602.21 | G8: =E8+F8 -> 909802.21 | H8: 462502.76 | J8: French
B9: San Telmo 2 | C9: 10898600 | D9: 2415229.8 | E9: 887700 | F9: 573285.05 | G9: =E9+F9 -> 1460985.1 | H9: 444315.8 | J9: San Telmo 2
B10: Lucero_Zona San Telmo | C10: =SUM(C7:C9) -> 61077503 | D10: =SUM(D7:D9) -> 8109644.7 | E10: =SUM(E7:E9) -> 3296413.4 | F10: =SUM(F7:F9) -> 1389172.3 | G10: =SUM(G7:G9) -> 4685585.8 | H10: =SUM(H7:H9) -> 1183223.5 | J10: Lucero_Zona San Telmo
B11: AS San Telmo | C11: 14676490 | D11: 3434064.9 | E11: 1569765 | F11: 1146570 | G11: =E11+F11 -> 2716335 | H11: 2896000 | J11: AS San Telmo
